Workbook

Sheet SalesRaw
A1: id | B1: item_id | C1: dept_id | D1: cat_id | E1: store_id | F1: state_id | G1: d_1 | H1: d_2 | I1: d_3 | J1: d_4 | K1: d_5 | L1: d_6 | M1: d_7 | N1: d_8 | O1: d_9 | P1: d_10 | Q1: d_11 | R1: d_12 | S1: d_13 | T1: d_14 | U1: d_15 | V1: d_16 | W1: d_17 | X1: d_18 | Y1: d_19 | Z1: d_20 | AA1: d_21 | AB1: d_22 | AC1: d_23 | AD1: d_24 | AE1: d_25 | AF1: d_26 | AG1: d_27 | AH1: d_28 | AI1: d_29 | AJ1: d_30 | AK1: d_31 | AL1: d_32 | AM1: d_33 | AN1: d_34 | AO1: d_35 | AP1: d_36 | AQ1: d_37 | AR1: d_38 | AS1: d_39 | AT1: d_40 | AU1: d_41 | AV1: d_42 | AW1: d_43 | AX1: d_44 | AY1: d_45 | AZ1: d_46 | BA1: d_47 | BB1: d_48 | BC1: d_49 | BD1: d_50 | BE1: d_51 | BF1: d_52 | BG1: d_53 | BH1: d_54 | BI1: d_55 | BJ1: d_56 | BK1: d_57 | BL1: d_58 | BM1: d_59 | BN1: d_60 | BO1: d_61 | BP1: d_62 | BQ1: d_63 | BR1: d_64 | BS1: d_65 | BT1: d_66 | BU1: d_67 | BV1: d_68 | BW1: d_69 | BX1: d_70 | BY1: d_71 | BZ1: d_72 | CA1: d_73 | CB1: d_74 | CC1: d_75 | CD1: d_76 | CE1: d_77 | CF1: d_78 | CG1: d_79 | CH1: d_80 | CI1: d_81 | CJ1: d_82 | CK1: d_83 | CL1: d_84 | CM1: d_85 | CN1: d_86 | CO1: d_87 | CP1: d_88 | CQ1: d_89 | CR1: d_90 | CS1: d_91 | CT1: d_92 | CU1: d_93 | CV1: d_94 | CW1: d_95 | CX1: d_96 | CY1: d_97 | CZ1: d_98 | DA1: d_99 | DB1: d_100 | DC1: d_101 | DD1: d_102 | DE1: d_103 | DF1: d_104 | DG1: d_105 | DH1: d_106 | DI1: d_107 | DJ1: d_108 | DK1: d_109 | DL1: d_110 | DM1: d_111 | DN1: d_112 | DO1: d_113 | DP1: d_114 | DQ1: d_115 | DR1: d_116 | DS1: d_117 | DT1: d_118 | DU1: d_119 | DV1: d_120 | DW1: d_121 | DX1: d_122 | DY1: d_123 | DZ1: d_124 | EA1: d_125 | EB1: d_126 | EC1: d_127 | ED1: d_128 | EE1: d_129 | EF1: d_130 | EG1: d_131 | EH1: d_132 | EI1: d_133 | EJ1: d_134 | EK1: d_135 | EL1: d_136 | EM1: d_137 | EN1: d_138 | EO1: d_139 | EP1: d_140 | EQ1: d_141 | ER1: d_142 | ES1: d_143 | ET1: d_144 | EU1: d_145 | EV1: d_146 | EW1: d_147 | EX1: d_148 | EY1: d_149 | EZ1: d_150 | FA1: d_151 | FB1: d_152 | FC1: d_153 | FD1: d_154 | FE1: d_155 | FF1: d_156 | FG1: d_157 | FH1: d_158 | FI1: d_159 | FJ1: d_160 | FK1: d_161 | FL1: d_162 | FM1: d_163 | FN1: d_164 | FO1: d_165 | FP1: d_166 | FQ1: d_167 | FR1: d_168 | FS1: d_169 | FT1: d_170 | FU1: d_171 | FV1: d_172 | FW1: d_173 | FX1: d_174 | FY1: d_175 | FZ1: d_176 | GA1: d_177 | GB1: d_178 | GC1: d_179 | GD1: d_180 | GE1: d_181 | GF1: d_182 | GG1: d_183 | GH1: d_184 | GI1: d_185 | GJ1: d_186 | GK1: d_187 | GL1: d_188 | GM1: d_189 | GN1: d_190 | GO1: d_191 | GP1: d_192 | GQ1: d_193 | GR1: d_194 | GS1: d_195 | GT1: d_196 | GU1: d_197 | GV1: d_198 | GW1: d_199 | GX1: d_200 | GY1: d_201 | GZ1: d_202 | HA1: d_203 | HB1: d_204 | HC1: d_205 | HD1: d_206 | HE1: d_207 | HF1: d_208 | HG1: d_209 | HH1: d_210 | HI1: d_211 | HJ1: d_212 | HK1: d_213 | HL1: d_214 | HM1: d_215 | HN1: d_216 | HO1: d_217 | HP1: d_218 | HQ1: d_219 | HR1: d_220 | HS1: d_221 | HT1: d_222 | HU1: d_223 | HV1: d_224 | HW1: d_225 | HX1: d_226 | HY1: d_227 | HZ1: d_228 | IA1: d_229 | IB1: d_230 | IC1: d_231 | ID1: d_232 | IE1: d_233 | IF1: d_234 | IG1: d_235 | IH1: d_236 | II1: d_237 | IJ1: d_238 | IK1: d_239 | IL1: d_240 | IM1: d_241 | IN1: d_242 | IO1: d_243 | IP1: d_244 | IQ1: d_245 | IR1: d_246 | IS1: d_247 | IT1: d_248 | IU1: d_249 | IV1: d_250 | IW1: d_251 | IX1: d_252 | IY1: d_253 | IZ1: d_254 | JA1: d_255 | JB1: d_256 | JC1: d_257 | JD1: d_258 | JE1: d_259 | JF1: d_260 | JG1: d_261 | JH1: d_262 | JI1: d_263 | JJ1: d_264 | JK1: d_265 | JL1: d_266 | JM1: d_267 | JN1: d_268 | JO1: d_269 | JP1: d_270 | JQ1: d_271 | JR1: d_272 | JS1: d_273 | JT1: d_274 | JU1: d_275 | JV1: d_276 | JW1: d_277 | JX1: d_278 | JY1: d_279 | JZ1: d_280 | KA1: d_281 | KB1: d_282 | KC1: d_283 | KD1: d_284 | KE1: d_285 | KF1: d_286 | KG1: d_287 | KH1: d_288 | KI1: d_289 | KJ1: d_290 | KK1: d_291 | KL1: d_292 | KM1: d_293 | KN1: d_294 | KO1: d_295 | KP1: d_296 | KQ1: d_297 | KR1: d_298 | KS1: d_299 | KT1: d_300 | KU1: d_301 | KV1: d_302 | KW1: d_303 | KX1: d_304 | KY1: d_305 | KZ1: d_306 | LA1: d_307 | LB1: d_308 | LC1: d_309 | LD1: d_310 | LE1: d_311 | LF1: d_312 | LG1: d_313 | LH1: d_314 | LI1: d_315 | LJ1: d_316 | LK1: d_317 | LL1: d_318 | LM1: d_319 | LN1: d_320 | LO1: d_321 | LP1: d_322 | LQ1: d_323 | LR1: d_324 | LS1: d_325 | LT1: d_326 | LU1: d_327 | LV1: d_328 | LW1: d_329 | LX1: d_330 | LY1: d_331 | LZ1: d_332 | MA1: d_333 | MB1: d_334 | MC1: d_335 | MD1: d_336 | ME1: d_337 | MF1: d_338 | MG1: d_339 | MH1: d_340 | MI1: d_341 | MJ1: d_342 | MK1: d_343 | ML1: d_344 | MM1: d_345 | MN1: d_346 | MO1: d_347 | MP1: d_348 | MQ1: d_349 | MR1: d_350 | MS1: d_351 | MT1: d_352 | MU1: d_353 | MV1: d_354 | MW1: d_355 | MX1: d_356 | MY1: d_357 | MZ1: d_358 | NA1: d_359 | NB1: d_360 | NC1: d_361 | ND1: d_362 | NE1: d_363 | NF1: d_364 | NG1: d_365 | NH1: d_366 | NI1: d_367 | NJ1: d_368 | NK1: d_369 | NL1: d_370 | NM1: d_371 | NN1: d_372 | NO1: d_373 | NP1: d_374 | NQ1: d_375 | NR1: d_376 | NS1: d_377 | NT1: d_378 | NU1: d_379 | NV1: d_380 | NW1: d_381 | NX1: d_382 | NY1: d_383 | NZ1: d_384 | OA1: d_385 | OB1: d_386 | OC1: d_387 | OD1: d_388 | OE1: d_389 | OF1: d_390 | OG1: d_391 | OH1: d_392 | OI1: d_393 | OJ1: d_394 | OK1: d_395 | OL1: d_396 | OM1: d_397 | ON1: d_398 | OO1: d_399 | OP1: d_400 | OQ1: d_401 | OR1: d_402 | OS1: d_403 | OT1: d_404 | OU1: d_405 | OV1: d_406 | OW1: d_407 | OX1: d_408 | OY1: d_409 | OZ1: d_410 | PA1: d_411 | PB1: d_412 | PC1: d_413 | PD1: d_414 | PE1: d_415 | PF1: d_416 | PG1: d_417 | PH1: d_418 | PI1: d_419 | PJ1: d_420 | PK1: d_421 | PL1: d_422 | PM1: d_423 | PN1: d_424 | PO1: d_425 | PP1: d_426 | PQ1: d_427 | PR1: d_428 | PS1: d_429 | PT1: d_430 | PU1: d_431 | PV1: d_432 | PW1: d_433 | PX1: d_434 | PY1: d_435 | PZ1: d_436 | QA1: d_437 | QB1: d_438 | QC1: d_439 | QD1: d_440 | QE1: d_441 | QF1: d_442 | QG1: d_443 | QH1: d_444 | QI1: d_445 | QJ1: d_446 | QK1: d_447 | QL1: d_448 | QM1: d_449 | QN1: d_450 | QO1: d_451 | QP1: d_452 | QQ1: d_453 | QR1: d_454 | QS1: d_455 | QT1: d_456 | QU1: d_457 | QV1: d_458 | QW1: d_459 | QX1: d_460 | QY1: d_461 | QZ1: d_462 | RA1: d_463 | RB1: d_464 | RC1: d_465 | RD1: d_466 | RE1: d_467 | RF1: d_468 | RG1: d_469 | RH1: d_470 | RI1: d_471 | RJ1: d_472 | RK1: d_473 | RL1: d_474 | RM1: d_475 | RN1: d_476 | RO1: d_477 | RP1: d_478 | RQ1: d_479 | RR1: d_480 | RS1: d_481 | RT1: d_482 | RU1: d_483 | RV1: d_484 | RW1: d_485 | RX1: d_486 | RY1: d_487 | RZ1: d_488 | SA1: d_489 | SB1: d_490 | SC1: d_491 | SD1: d_492 | SE1: d_493 | SF1: d_494 | SG1: d_495 | SH1: d_496 | SI1: d_497 | SJ1: d_498 | SK1: d_499 | SL1: d_500 | SM1: d_501 | SN1: d_502 | SO1: d_503 | SP1: d_504 | SQ1: d_505 | SR1: d_506 | SS1: d_507 | ST1: d_508 | SU1: d_509 | SV1: d_510 | SW1: d_511 | SX1: d_512 | SY1: d_513 | SZ1: d_514 | TA1: d_515 | TB1: d_516 | TC1: d_517 | TD1: d_518 | TE1: d_519 | TF1: d_520 | TG1: d_521 | TH1: d_522 | TI1: d_523 | TJ1: d_524 | TK1: d_525 | TL1: d_526 | TM1: d_527 | TN1: d_528 | TO1: d_529 | TP1: d_530 | TQ1: d_531 | TR1: d_532 | TS1: d_533 | TT1: d_534 | TU1: d_535 | TV1: d_536 | TW1: d_537 | TX1: d_538 | TY1: d_539 | TZ1: d_540 | UA1: d_541 | UB1: d_542 | UC1: d_543 | UD1: d_544 | UE1: d_545 | UF1: d_546 | UG1: d_547 | UH1: d_548 | UI1: d_549 | UJ1: d_550 | UK1: d_551 | UL1: d_552 | UM1: d_553 | UN1: d_554 | UO1: d_555 | UP1: d_556 | UQ1: d_557 | UR1: d_558 | US1: d_559 | UT1: d_560 | UU1: d_561 | UV1: d_562 | UW1: d_563 | UX1: d_564 | UY1: d_565 | UZ1: d_566 | VA1: d_567 | VB1: d_568 | VC1: d_569 | VD1: d_570 | VE1: d_571 | VF1: d_572 | VG1: d_573 | VH1: d_574 | VI1: d_575 | VJ1: d_576 | VK1: d_577 | VL1: d_578 | VM1: d_579 | VN1: d_580 | VO1: d_581 | VP1: d_582 | VQ1: d_583 | VR1: d_584 | VS1: d_585 | VT1: d_586 | VU1: d_587 | VV1: d_588 | VW1: d_589 | VX1: d_590 | VY1: d_591 | VZ1: d_592 | WA1: d_593 | WB1: d_594 | WC1: d_595 | WD1: d_596 | WE1: d_597 | WF1: d_598 | WG1: d_599 | WH1: d_600 | WI1: d_601 | WJ1: d_602 | WK1: d_603 | WL1: d_604 | WM1: d_605 | WN1: d_606 | WO1: d_607 | WP1: d_608 | WQ1: d_609 | WR1: d_610 | WS1: d_611 | WT1: d_612 | WU1: d_613 | WV1: d_614 | WW1: d_615 | WX1: d_616 | WY1: d_617 | WZ1: d_618 | XA1: d_619 | XB1: d_620 | XC1: d_621 | XD1: d_622 | XE1: d_623 | XF1: d_624 | XG1: d_625 | XH1: d_626 | XI1: d_627 | XJ1: d_628 | XK1: d_629 | XL1: d_630 | XM1: d_631 | XN1: d_632 | XO1: d_633 | XP1: d_634 | XQ1: d_635 | XR1: d_636 | XS1: d_637 | XT1: d_638 | XU1: d_639 | XV1: d_640 | XW1: d_641 | XX1: d_642 | XY1: d_643 | XZ1: d_644 | YA1: d_645 | YB1: d_646 | YC1: d_647 | YD1: d_648 | YE1: d_649 | YF1: d_650 | YG1: d_651 | YH1: d_652 | YI1: d_653 | YJ1: d_654 | YK1: d_655 | YL1: d_656 | YM1: d_657 | YN1: d_658 | YO1: d_659 | YP1: d_660 | YQ1: d_661 | YR1: d_662 | YS1: d_663 | YT1: d_664 | YU1: d_665 | YV1: d_666 | YW1: d_667 | YX1: d_668 | YY1: d_669 | YZ1: d_670 | ZA1: d_671 | ZB1: d_672 | ZC1: d_673 | ZD1: d_674 | ZE1: d_675 | ZF1: d_676 | ZG1: d_677 | ZH1: d_678 | ZI1: d_679 | ZJ1: d_680 | ZK1: d_681 | ZL1: d_682 | ZM1: d_683 | ZN1: d_684 | ZO1: d_685 | ZP1: d_686 | ZQ1: d_687 | ZR1: d_688 | ZS1: d_689 | ZT1: d_690 | ZU1: d_691 | ZV1: d_692 | ZW1: d_693 | ZX1: d_694 | ZY1: d_695 | ZZ1: d_696 | AAA1: d_697 | AAB1: d_698 | AAC1: d_699 | AAD1: d_700 | AAE1: d_701 | AAF1: d_702 | AAG1: d_703 | AAH1: d_704 | AAI1: d_705 | AAJ1: d_706 | AAK1: d_707 | AAL1: d_708 | AAM1: d_709 | AAN1: d_710 | AAO1: d_711 | AAP1: d_712 | AAQ1: d_713 | AAR1: d_714 | AAS1: d_715 | AAT1: d_716 | AAU1: d_717 | AAV1: d_718 | AAW1: d_719 | AAX1: d_720 | AAY1: d_721 | AAZ1: d_722 | ABA1: d_723 | ABB1: d_724 | ABC1: d_725 | ABD1: d_726 | ABE1: d_727 | ABF1: d_728 | ABG1: d_729 | ABH1: d_730 | ABI1: d_731 | ABJ1: d_732 | ABK1: d_733 | ABL1: d_734 | ABM1: d_735 | ABN1: d_736 | ABO1: d_737 | ABP1: d_738 | ABQ1: d_739 | ABR1: d_740 | ABS1: d_741 | ABT1: d_742 | ABU1: d_743 | ABV1: d_744 | ABW1: d_745 | ABX1: d_746 | ABY1: d_747 | ABZ1: d_748 | ACA1: d_749 | ACB1: d_750 | ACC1: d_751 | ACD1: d_752 | ACE1: d_753 | ACF1: d_754 | ACG1: d_755 | ACH1: d_756 | ACI1: d_757 | ACJ1: d_758 | ACK1: d_759 | ACL1: d_760 | ACM1: d_761 | ACN1: d_762 | ACO1: d_763 | ACP1: d_764 | ACQ1: d_765 | ACR1: d_766 | ACS1: d_767 | ACT1: d_768 | ACU1: d_769 | ACV1: d_770 | ACW1: d_771 | ACX1: d_772 | ACY1: d_773 | ACZ1: d_774 | ADA1: d_775 | ADB1: d_776 | ADC1: d_777 | ADD1: d_778 | ADE1: d_779 | ADF1: d_780 | ADG1: d_781 | ADH1: d_782 | ADI1: d_783 | ADJ1: d_784 | ADK1: d_785 | ADL1: d_786 | ADM1: d_787 | ADN1: d_788 | ADO1: d_789 | ADP1: d_790 | ADQ1: d_791 | ADR1: d_792 | ADS1: d_793 | ADT1: d_794 | ADU1: d_795 | ADV1: d_796 | ADW1: d_797 | ADX1: d_798 | ADY1: d_799 | ADZ1: d_800 | AEA1: d_801 | AEB1: d_802 | AEC1: d_803 | AED1: d_804 | AEE1: d_805 | AEF1: d_806 | AEG1: d_807 | AEH1: d_808 | AEI1: d_809 | AEJ1: d_810 | AEK1: d_811 | AEL1: d_812 | AEM1: d_813 | AEN1: d_814 | AEO1: d_815 | AEP1: d_816 | AEQ1: d_817 | AER1: d_818 | AES1: d_819 | AET1: d_820 | AEU1: d_821 | AEV1: d_822 | AEW1: d_823 | AEX1: d_824 | AEY1: d_825 | AEZ1: d_826 | AFA1: d_827 | AFB1: d_828 | AFC1: d_829 | AFD1: d_830 | AFE1: d_831 | AFF1: d_832 | AFG1: d_833 | AFH1: d_834 | AFI1: d_835 | AFJ1: d_836 | AFK1: d_837 | AFL1: d_838 | AFM1: d_839 | AFN1: d_840 | AFO1: d_841 | AFP1: d_842 | AFQ1: d_843 | AFR1: d_844 | AFS1: d_845 | AFT1: d_846 | AFU1: d_847 | AFV1: d_848 | AFW1: d_849 | AFX1: d_850 | AFY1: d_851 | AFZ1: d_852 | AGA1: d_853 | AGB1: d_854 | AGC1: d_855 | AGD1: d_856 | AGE1: d_857 | AGF1: d_858 | AGG1: d_859 | AGH1: d_860 | AGI1: d_861 | AGJ1: d_862 | AGK1: d_863 | AGL1: d_864 | AGM1: d_865 | AGN1: d_866 | AGO1: d_867 | AGP1: d_868 | AGQ1: d_869 | AGR1: d_870 | AGS1: d_871 | AGT1: d_872 | AGU1: d_873 | AGV1: d_874 | AGW1: d_875 | AGX1: d_876 | AGY1: d_877 | AGZ1: d_878 | AHA1: d_879 | AHB1: d_880 | AHC1: d_881 | AHD1: d_882 | AHE1: d_883 | AHF1: d_884 | AHG1: d_885 | AHH1: d_886 | AHI1: d_887 | AHJ1: d_888 | AHK1: d_889 | AHL1: d_890 | AHM1: d_891 | AHN1: d_892 | AHO1: d_893 | AHP1: d_894 | AHQ1: d_895 | AHR1: d_896 | AHS1: d_897 | AHT1: d_898 | AHU1: d_899 | AHV1: d_900 | AHW1: d_901 | AHX1: d_902 | AHY1: d_903 | AHZ1: d_904 | AIA1: d_905 | AIB1: d_906 | AIC1: d_907 | AID1: d_908 | AIE1: d_909 | AIF1: d_910 | AIG1: d_911 | AIH1: d_912 | AII1: d_913 | AIJ1: d_914 | AIK1: d_915 | AIL1: d_916 | AIM1: d_917 | AIN1: d_918 | AIO1: d_919 | AIP1: d_920 | AIQ1: d_921 | AIR1: d_922 | AIS1: d_923 | AIT1: d_924 | AIU1: d_925 | AIV1: d_926 | AIW1: d_927 | AIX1: d_928 | AIY1: d_929 | AIZ1: d_930 | AJA1: d_931 | AJB1: d_932 | AJC1: d_933 | AJD1: d_934 | AJE1: d_935 | AJF1: d_936 | AJG1: d_937 | AJH1: d_938 | AJI1: d_939 | AJJ1: d_940 | AJK1: d_941 | AJL1: d_942 | AJM1: d_943 | AJN1: d_944 | AJO1: d_945 | AJP1: d_946 | AJQ1: d_947 | AJR1: d_948 | AJS1: d_949 | AJT1: d_950 | AJU1: d_951 | AJV1: d_952 | AJW1: d_953 | AJX1: d_954 | AJY1: d_955 | AJZ1: d_956 | AKA1: d_957 | AKB1: d_958 | AKC1: d_959 | AKD1: d_960 | AKE1: d_961 | AKF1: d_962 | AKG1: d_963 | AKH1: d_964 | AKI1: d_965 | AKJ1: d_966 | AKK1: d_967 | AKL1: d_968 | AKM1: d_969 | AKN1: d_970 | AKO1: d_971 | AKP1: d_972 | AKQ1: d_973 | AKR1: d_974 | AKS1: d_975 | AKT1: d_976 | AKU1: d_977 | AKV1: d_978 | AKW1: d_979 | AKX1: d_980 | AKY1: d_981 | AKZ1: d_982 | ALA1: d_983 | ALB1: d_984 | ALC1: d_985 | ALD1: d_986 | ALE1: d_987 | ALF1: d_988 | ALG1: d_989 | ALH1: d_990 | ALI1: d_991 | ALJ1: d_992 | ALK1: d_993 | ALL1: d_994 | ALM1: d_995 | ALN1: d_996 | ALO1: d_997 | ALP1: d_998 | ALQ1: d_999 | ALR1: d_1000 | ALS1: d_1001 | ALT1: d_1002 | ALU1: d_1003 | ALV1: d_1004 | ALW1: d_1005 | ALX1: d_1006 | ALY1: d_1007 | ALZ1: d_1008 | AMA1: d_1009 | AMB1: d_1010 | AMC1: d_1011 | AMD1: d_1012 | AME1: d_1013 | AMF1: d_1014 | AMG1: d_1015 | AMH1: d_1016 | AMI1: d_1017 | AMJ1: d_1018 | AMK1: d_1019 | AML1: d_1020 | AMM1: d_1021 | AMN1: d_1022 | AMO1: d_1023 | AMP1: d_1024 | AMQ1: d_1025 | AMR1: d_1026 | AMS1: d_1027 | AMT1: d_1028 | AMU1: d_1029 | AMV1: d_1030 | AMW1: d_1031 | AMX1: d_1032 | AMY1: d_1033 | AMZ1: d_1034 | ANA1: d_1035 | ANB1: d_1036 | ANC1: d_1037 | AND1: d_1038 | ANE1: d_1039 | ANF1: d_1040 | ANG1: d_1041 | ANH1: d_1042 | ANI1: d_1043 | ANJ1: d_1044 | ANK1: d_1045 | ANL1: d_1046 | ANM1: d_1047 | ANN1: d_1048 | ANO1: d_1049 | ANP1: d_1050 | ANQ1: d_1051 | ANR1: d_1052 | ANS1: d_1053 | ANT1: d_1054 | ANU1: d_1055 | ANV1: d_1056 | ANW1: d_1057 | ANX1: d_1058 | ANY1: d_1059 | ANZ1: d_1060 | AOA1: d_1061 | AOB1: d_1062 | AOC1: d_1063 | AOD1: d_1064 | AOE1: d_1065 | AOF1: d_1066 | AOG1: d_1067 | AOH1: d_1068 | AOI1: d_1069 | AOJ1: d_1070 | AOK1: d_1071 | AOL1: d_1072 | AOM1: d_1073 | AON1: d_1074 | AOO1: d_1075 | AOP1: d_1076 | AOQ1: d_1077 | AOR1: d_1078 | AOS1: d_1079 | AOT1: d_1080 | AOU1: d_1081 | AOV1: d_1082 | AOW1: d_1083 | AOX1: d_1084 | AOY1: d_1085 | AOZ1: d_1086 | APA1: d_1087 | APB1: d_1088 | APC1: d_1089 | APD1: d_1090 | APE1: d_1091 | APF1: d_1092 | APG1: d_1093 | APH1: d_1094 | API1: d_1095 | APJ1: d_1096 | APK1: d_1097 | APL1: d_1098 | APM1: d_1099 | APN1: d_1100 | APO1: d_1101 | APP1: d_1102 | APQ1: d_1103 | APR1: d_1104 | APS1: d_1105 | APT1: d_1106 | APU1: d_1107 | APV1: d_1108 | APW1: d_1109 | APX1: d_1110 | APY1: d_1111 | APZ1: d_1112 | AQA1: d_1113 | AQB1: d_1114 | AQC1: d_1115 | AQD1: d_1116 | AQE1: d_1117 | AQF1: d_1118 | AQG1: d_1119 | AQH1: d_1120 | AQI1: d_1121 | AQJ1: d_1122 | AQK1: d_1123 | AQL1: d_1124 | AQM1: d_1125 | AQN1: d_1126 | AQO1: d_1127 | AQP1: d_1128 | AQQ1: d_1129 | AQR1: d_1130 | AQS1: d_1131 | AQT1: d_1132 | AQU1: d_1133 | AQV1: d_1134 | AQW1: d_1135 | AQX1: d_1136 | AQY1: d_1137 | AQZ1: d_1138 | ARA1: d_1139 | ARB1: d_1140 | ARC1: d_1141 | ARD1: d_1142 | ARE1: d_1143 | ARF1: d_1144 | ARG1: d_1145 | ARH1: d_1146 | ARI1: d_1147 | ARJ1: d_1148 | ARK1: d_1149 | ARL1: d_1150 | ARM1: d_1151 | ARN1: d_1152 | ARO1: d_1153 | ARP1: d_1154 | ARQ1: d_1155 | ARR1: d_1156 | ARS1: d_1157 | ART1: d_1158 | ARU1: d_1159 | ARV1: d_1160 | ARW1: d_1161 | ARX1: d_1162 | ARY1: d_1163 | ARZ1: d_1164 | ASA1: d_1165 | ASB1: d_1166 | ASC1: d_1167 | ASD1: d_1168 | ASE1: d_1169 | ASF1: d_1170 | ASG1: d_1171 | ASH1: d_1172 | ASI1: d_1173 | ASJ1: d_1174 | ASK1: d_1175 | ASL1: d_1176 | ASM1: d_1177 | ASN1: d_1178 | ASO1: d_1179 | ASP1: d_1180 | ASQ1: d_1181 | ASR1: d_1182 | ASS1: d_1183 | AST1: d_1184 | ASU1: d_1185 | ASV1: d_1186 | ASW1: d_1187 | ASX1: d_1188 | ASY1: d_1189 | ASZ1: d_1190 | ATA1: d_1191 | ATB1: d_1192 | ATC1: d_1193 | ATD1: d_1194 | ATE1: d_1195 | ATF1: d_1196 | ATG1: d_1197 | ATH1: d_1198 | ATI1: d_1199 | ATJ1: d_1200 | ATK1: d_1201 | ATL1: d_1202 | ATM1: d_1203 | ATN1: d_1204 | ATO1: d_1205 | ATP1: d_1206 | ATQ1: d_1207 | ATR1: d_1208 | ATS1: d_1209 | ATT1: d_1210 | ATU1: d_1211 | ATV1: d_1212 | ATW1: d_1213 | ATX1: d_1214 | ATY1: d_1215 | ATZ1: d_1216 | AUA1: d_1217 | AUB1: d_1218 | AUC1: d_1219 | AUD1: d_1220 | AUE1: d_1221 | AUF1: d_1222 | AUG1: d_1223 | AUH1: d_1224 | AUI1: d_1225 | AUJ1: d_1226 | AUK1: d_1227 | AUL1: d_1228 | AUM1: d_1229 | AUN1: d_1230 | AUO1: d_1231 | AUP1: d_1232 | AUQ1: d_1233 | AUR1: d_1234 | AUS1: d_1235 | AUT1: d_1236 | AUU1: d_1237 | AUV1: d_1238 | AUW1: d_1239 | AUX1: d_1240 | AUY1: d_1241 | AUZ1: d_1242 | AVA1: d_1243 | AVB1: d_1244 | AVC1: d_1245 | AVD1: d_1246 | AVE1: d_1247 | AVF1: d_1248 | AVG1: d_1249 | AVH1: d_1250 | AVI1: d_1251 | AVJ1: d_1252 | AVK1: d_1253 | AVL1: d_1254 | AVM1: d_1255 | AVN1: d_1256 | AVO1: d_1257 | AVP1: d_1258 | AVQ1: d_1259 | AVR1: d_1260 | AVS1: d_1261 | AVT1: d_1262 | AVU1: d_1263 | AVV1: d_1264 | AVW1: d_1265 | AVX1: d_1266 | AVY1: d_1267 | AVZ1: d_1268 | AWA1: d_1269 | AWB1: d_1270 | AWC1: d_1271 | AWD1: d_1272 | AWE1: d_1273 | AWF1: d_1274 | AWG1: d_1275 | AWH1: d_1276 | AWI1: d_1277 | AWJ1: d_1278 | AWK1: d_1279 | AWL1: d_1280 | AWM1: d_1281 | AWN1: d_1282 | AWO1: d_1283 | AWP1: d_1284 | AWQ1: d_1285 | AWR1: d_1286 | AWS1: d_1287 | AWT1: d_1288 | AWU1: d_1289 | AWV1: d_1290 | AWW1: d_1291 | AWX1: d_1292 | AWY1: d_1293 | AWZ1: d_1294 | AXA1: d_1295 | AXB1: d_1296 | AXC1: d_1297 | AXD1: d_1298 | AXE1: d_1299 | AXF1: d_1300 | AXG1: d_1301 | AXH1: d_1302 | AXI1: d_1303 | AXJ1: d_1304 | AXK1: d_1305 | AXL1: d_1306 | AXM1: d_1307 | AXN1: d_1308 | AXO1: d_1309 | AXP1: d_1310 | AXQ1: d_1311 | AXR1: d_1312 | AXS1: d_1313 | AXT1: d_1314 | AXU1: d_1315 | AXV1: d_1316 | AXW1: d_1317 | AXX1: d_1318 | AXY1: d_1319 | AXZ1: d_1320 | AYA1: d_1321 | AYB1: d_1322 | AYC1: d_1323 | AYD1: d_1324 | AYE1: d_1325 | AYF1: d_1326 | AYG1: d_1327 | AYH1: d_1328 | AYI1: d_1329 | AYJ1: d_1330 | AYK1: d_1331 | AYL1: d_1332 | AYM1: d_1333 | AYN1: d_1334 | AYO1: d_1335 | AYP1: d_1336 | AYQ1: d_1337 | AYR1: d_1338 | AYS1: d_1339 | AYT1: d_1340 | AYU1: d_1341 | AYV1: d_1342 | AYW1: d_1343 | AYX1: d_1344 | AYY1: d_1345 | AYZ1: d_1346 | AZA1: d_1347 | AZB1: d_1348 | AZC1: d_1349 | AZD1: d_1350 | AZE1: d_1351 | AZF1: d_1352 | AZG1: d_1353 | AZH1: d_1354 | AZI1: d_1355 | AZJ1: d_1356 | AZK1: d_1357 | AZL1: d_1358 | AZM1: d_1359 | AZN1: d_1360 | AZO1: d_1361 | AZP1: d_1362 | AZQ1: d_1363 | AZR1: d_1364 | AZS1: d_1365 | AZT1: d_1366 | AZU1: d_1367 | AZV1: d_1368 | AZW1: d_1369 | AZX1: d_1370 | AZY1: d_1371 | AZZ1: d_1372 | BAA1: d_1373 | BAB1: d_1374 | BAC1: d_1375 | BAD1: d_1376 | BAE1: d_1377 | BAF1: d_1378 | BAG1: d_1379 | BAH1: d_1380 | BAI1: d_1381 | BAJ1: d_1382 | BAK1: d_1383 | BAL1: d_1384 | BAM1: d_1385 | BAN1: d_1386 | BAO1: d_1387 | BAP1: d_1388 | BAQ1: d_1389 | BAR1: d_1390 | BAS1: d_1391 | BAT1: d_1392 | BAU1: d_1393 | BAV1: d_1394 | BAW1: d_1395 | BAX1: d_1396 | BAY1: d_1397 | BAZ1: d_1398 | BBA1: d_1399 | BBB1: d_1400 | BBC1: d_1401 | BBD1: d_1402 | BBE1: d_1403 | BBF1: d_1404 | BBG1: d_1405 | BBH1: d_1406 | BBI1: d_1407 | BBJ1: d_1408 | BBK1: d_1409 | BBL1: d_1410 | BBM1: d_1411 | BBN1: d_1412 | BBO1: d_1413 | BBP1: d_1414 | BBQ1: d_1415 | BBR1: d_1416 | BBS1: d_1417 | BBT1: d_1418 | BBU1: d_1419 | BBV1: d_1420 | BBW1: d_1421 | BBX1: d_1422 | BBY1: d_1423 | BBZ1: d_1424 | BCA1: d_1425 | BCB1: d_1426 | BCC1: d_1427 | BCD1: d_1428 | BCE1: d_1429 | BCF1: d_1430 | BCG1: d_1431 | BCH1: d_1432 | BCI1: d_1433 | BCJ1: d_1434 | BCK1: d_1435 | BCL1: d_1436 | BCM1: d_1437 | BCN1: d_1438 | BCO1: d_1439 | BCP1: d_1440 | BCQ1: d_1441 | BCR1: d_1442 | BCS1: d_1443 | BCT1: d_1444 | BCU1: d_1445 | BCV1: d_1446 | BCW1: d_1447 | BCX1: d_1448 | BCY1: d_1449 | BCZ1: d_1450 | BDA1: d_1451 | BDB1: d_1452 | BDC1: d_1453 | BDD1: d_1454 | BDE1: d_1455 | BDF1: d_1456 | BDG1: d_1457 | BDH1: d_1458 | BDI1: d_1459 | BDJ1: d_1460 | BDK1: d_1461 | BDL1: d_1462 | BDM1: d_1463 | BDN1: d_1464 | BDO1: d_1465 | BDP1: d_1466 | BDQ1: d_1467 | BDR1: d_1468 | BDS1: d_1469 | BDT1: d_1470 | BDU1: d_1471 | BDV1: d_1472 | BDW1: d_1473 | BDX1: d_1474 | BDY1: d_1475 | BDZ1: d_1476 | BEA1: d_1477 | BEB1: d_1478 | BEC1: d_1479 | BED1: d_1480 | BEE1: d_1481 | BEF1: d_1482 | BEG1: d_1483 | BEH1: d_1484 | BEI1: d_1485 | BEJ1: d_1486 | BEK1: d_1487 | BEL1: d_1488 | BEM1: d_1489 | BEN1: d_1490 | BEO1: d_1491 | BEP1: d_1492 | BEQ1: d_1493 | BER1: d_1494 | BES1: d_1495 | BET1: d_1496 | BEU1: d_1497 | BEV1: d_1498 | BEW1: d_1499 | BEX1: d_1500 | BEY1: d_1501 | BEZ1: d_1502 | BFA1: d_1503 | BFB1: d_1504 | BFC1: d_1505 | BFD1: d_1506 | BFE1: d_1507 | BFF1: d_1508 | BFG1: d_1509 | BFH1: d_1510 | BFI1: d_1511 | BFJ1: d_1512 | BFK1: d_1513 | BFL1: d_1514 | BFM1: d_1515 | BFN1: d_1516 | BFO1: d_1517 | BFP1: d_1518 | BFQ1: d_1519 | BFR1: d_1520 | BFS1: d_1521 | BFT1: d_1522 | BFU1: d_1523 | BFV1: d_1524 | BFW1: d_1525 | BFX1: d_1526 | BFY1: d_1527 | BFZ1: d_1528 | BGA1: d_1529 | BGB1: d_1530 | BGC1: d_1531 | BGD1: d_1532 | BGE1: d_1533 | BGF1: d_1534 | BGG1: d_1535 | BGH1: d_1536 | BGI1: d_1537 | BGJ1: d_1538 | BGK1: d_1539 | BGL1: d_1540 | BGM1: d_1541 | BGN1: d_1542 | BGO1: d_1543 | BGP1: d_1544 | BGQ1: d_1545 | BGR1: d_1546 | BGS1: d_1547 | BGT1: d_1548 | BGU1: d_1549 | BGV1: d_1550 | BGW1: d_1551 | BGX1: d_1552 | BGY1: d_1553 | BGZ1: d_1554 | BHA1: d_1555 | BHB1: d_1556 | BHC1: d_1557 | BHD1: d_1558 | BHE1: d_1559 | BHF1: d_1560 | BHG1: d_1561 | BHH1: d_1562 | BHI1: d_1563 | BHJ1: d_1564 | BHK1: d_1565 | BHL1: d_1566 | BHM1: d_1567 | BHN1: d_1568 | BHO1: d_1569 | BHP1: d_1570 | BHQ1: d_1571 | BHR1: d_1572 | BHS1: d_1573 | BHT1: d_1574 | BHU1: d_1575 | BHV1: d_1576 | BHW1: d_1577 | BHX1: d_1578 | BHY1: d_1579 | BHZ1: d_1580 | BIA1: d_1581 | BIB1: d_1582 | BIC1: d_1583 | BID1: d_1584 | BIE1: d_1585 | BIF1: d_1586 | BIG1: d_1587 | BIH1: d_1588 | BII1: d_1589 | BIJ1: d_1590 | BIK1: d_1591 | BIL1: d_1592 | BIM1: d_1593 | BIN1: d_1594 | BIO1: d_1595 | BIP1: d_1596 | BIQ1: d_1597 | BIR1: d_1598 | BIS1: d_1599 | BIT1: d_1600 | BIU1: d_1601 | BIV1: d_1602 | BIW1: d_1603 | BIX1: d_1604 | BIY1: d_1605 | BIZ1: d_1606 | BJA1: d_1607 | BJB1: d_1608 | BJC1: d_1609 | BJD1: d_1610 | BJE1: d_1611 | BJF1: d_1612 | BJG1: d_1613 | BJH1: d_1614 | BJI1: d_1615 | BJJ1: d_1616 | BJK1: d_1617 | BJL1: d_1618 | BJM1: d_1619 | BJN1: d_1620 | BJO1: d_1621 | BJP1: d_1622 | BJQ1: d_1623 | BJR1: d_1624 | BJS1: d_1625 | BJT1: d_1626 | BJU1: d_1627 | BJV1: d_1628 | BJW1: d_1629 | BJX1: d_1630 | BJY1: d_1631 | BJZ1: d_1632 | BKA1: d_1633 | BKB1: d_1634 | BKC1: d_1635 | BKD1: d_1636 | BKE1: d_1637 | BKF1: d_1638 | BKG1: d_1639 | BKH1: d_1640 | BKI1: d_1641 | BKJ1: d_1642 | BKK1: d_1643 | BKL1: d_1644 | BKM1: d_1645 | BKN1: d_1646 | BKO1: d_1647 | BKP1: d_1648 | BKQ1: d_1649 | BKR1: d_1650 | BKS1: d_1651 | BKT1: d_1652 | BKU1: d_1653 | BKV1: d_1654 | BKW1: d_1655 | BKX1: d_1656 | BKY1: d_1657 | BKZ1: d_1658 | BLA1: d_1659 | BLB1: d_1660 | BLC1: d_1661 | BLD1: d_1662 | BLE1: d_1663 | BLF1: d_1664 | BLG1: d_1665 | BLH1: d_1666 | BLI1: d_1667 | BLJ1: d_1668 | BLK1: d_1669 | BLL1: d_1670 | BLM1: d_1671 | BLN1: d_1672 | BLO1: d_1673 | BLP1: d_1674 | BLQ1: d_1675 | BLR1: d_1676 | BLS1: d_1677 | BLT1: d_1678 | BLU1: d_1679 | BLV1: d_1680 | BLW1: d_1681 | BLX1: d_1682 | BLY1: d_1683 | BLZ1: d_1684 | BMA1: d_1685 | BMB1: d_1686 | BMC1: d_1687 | BMD1: d_1688 | BME1: d_1689 | BMF1: d_1690 | BMG1: d_1691 | BMH1: d_1692 | BMI1: d_1693 | BMJ1: d_1694 | BMK1: d_1695 | BML1: d_1696 | BMM1: d_1697 | BMN1: d_1698 | BMO1: d_1699 | BMP1: d_1700 | BMQ1: d_1701 | BMR1: d_1702 | BMS1: d_1703 | BMT1: d_1704 | BMU1: d_1705 | BMV1: d_1706 | BMW1: d_1707 | BMX1: d_1708 | BMY1: d_1709 | BMZ1: d_1710 | BNA1: d_1711 | BNB1: d_1712 | BNC1: d_1713 | BND1: d_1714 | BNE1: d_1715 | BNF1: d_1716 | BNG1: d_1717 | BNH1: d_1718 | BNI1: d_1719 | BNJ1: d_1720 | BNK1: d_1721 | BNL1: d_1722 | BNM1: d_1723 | BNN1: d_1724 | BNO1: d_1725 | BNP1: d_1726 | BNQ1: d_1727 | BNR1: d_1728 | BNS1: d_1729 | BNT1: d_1730 | BNU1: d_1731 | BNV1: d_1732 | BNW1: d_1733 | BNX1: d_1734 | BNY1: d_1735 | BNZ1: d_1736 | BOA1: d_1737 | BOB1: d_1738 | BOC1: d_1739 | BOD1: d_1740 | BOE1: d_1741 | BOF1: d_1742 | BOG1: d_1743 | BOH1: d_1744 | BOI1: d_1745 | BOJ1: d_1746 | BOK1: d_1747 | BOL1: d_1748 | BOM1: d_1749 | BON1: d_1750 | BOO1: d_1751 | BOP1: d_1752 | BOQ1: d_1753 | BOR1: d_1754 | BOS1: d_1755 | BOT1: d_1756 | BOU1: d_1757 | BOV1: d_1758 | BOW1: d_1759 | BOX1: d_1760 | BOY1: d_1761 | BOZ1: d_1762 | BPA1: d_1763 | BPB1: d_1764 | BPC1: d_1765 | BPD1: d_1766 | BPE1: d_1767 | BPF1: d_1768 | BPG1: d_1769 | BPH1: d_1770 | BPI1: d_1771 | BPJ1: d_1772 | BPK1: d_1773 | BPL1: d_1774 | BPM1: d_1775 | BPN1: d_1776 | BPO1: d_1777 | BPP1: d_1778 | BPQ1: d_1779 | BPR1: d_1780 | BPS1: d_1781 | BPT1: d_1782 | BPU1: d_1783 | BPV1: d_1784 | BPW1: d_1785 | BPX1: d_1786 | BPY1: d_1787 | BPZ1: d_1788 | BQA1: d_1789 | BQB1: d_1790 | BQC1: d_1791 | BQD1: d_1792 | BQE1: d_1793 | BQF1: d_1794 | BQG1: d_1795 | BQH1: d_1796 | BQI1: d_1797 | BQJ1: d_1798 | BQK1: d_1799 | BQL1: d_1800 | BQM1: d_1801 | BQN1: d_1802 | BQO1: d_1803 | BQP1: d_1804 | BQQ1: d_1805 | BQR1: d_1806 | BQS1: d_1807 | BQT1: d_1808 | BQU1: d_1809 | BQV1: d_1810 | BQW1: d_1811 | BQX1: d_1812 | BQY1: d_1813 | BQZ1: d_1814 | BRA1: d_1815 | BRB1: d_1816 | BRC1: d_1817 | BRD1: d_1818 | BRE1: d_1819 | BRF1: d_1820 | BRG1: d_1821 | BRH1: d_1822 | BRI1: d_1823 | BRJ1: d_1824 | BRK1: d_1825 | BRL1: d_1826 | BRM1: d_1827 | BRN1: d_1828 | BRO1: d_1829 | BRP1: d_1830 | BRQ1: d_1831 | BRR1: d_1832 | BRS1: d_1833 | BRT1: d_1834 | BRU1: d_1835 | BRV1: d_1836 | BRW1: d_1837 | BRX1: d_1838 | BRY1: d_1839 | BRZ1: d_1840 | BSA1: d_1841 | BSB1: d_1842 | BSC1: d_1843 | BSD1: d_1844 | BSE1: d_1845 | BSF1: d_1846 | BSG1: d_1847 | BSH1: d_1848 | BSI1: d_1849 | BSJ1: d_1850 | BSK1: d_1851 | BSL1: d_1852 | BSM1: d_1853 | BSN1: d_1854 | BSO1: d_1855 | BSP1: d_1856 | BSQ1: d_1857 | BSR1: d_1858 | BSS1: d_1859 | BST1: d_1860 | BSU1: d_1861 | BSV1: d_1862 | BSW1: d_1863 | BSX1: d_1864 | BSY1: d_1865 | BSZ1: d_1866 | BTA1: d_1867 | BTB1: d_1868 | BTC1: d_1869 | BTD1: d_1870 | BTE1: d_1871 | BTF1: d_1872 | BTG1: d_1873 | BTH1: d_1874 | BTI1: d_1875 | BTJ1: d_1876 | BTK1: d_1877 | BTL1: d_1878 | BTM1: d_1879 | BTN1: d_1880 | BTO1: d_1881 | BTP1: d_1882 | BTQ1: d_1883 | BTR1: d_1884 | BTS1: d_1885 | BTT1: d_1886 | BTU1: d_1887 | BTV1: d_1888 | BTW1: d_1889 | BTX1: d_1890 | BTY1: d_1891 | BTZ1: d_1892 | BUA1: d_1893 | BUB1: d_1894 | BUC1: d_1895 | BUD1: d_1896 | BUE1: d_1897 | BUF1: d_1898 | BUG1: d_1899 | BUH1: d_1900 | BUI1: d_1901 | BUJ1: d_1902 | BUK1: d_1903 | BUL1: d_1904 | BUM1: d_1905 | BUN1: d_1906 | BUO1: d_1907 | BUP1: d_1908 | BUQ1: d_1909 | BUR1: d_1910 | BUS1: d_1911 | BUT1: d_1912 | BUU1: d_1913
A2: FOODS_1_001_CA_1_validation | B2: FOODS_1_001 | C2: FOODS_1 | D2: FOODS | E2: CA_1 | F2: CA | G2: 3 | H2: 0 | I2: 0 | J2: 1 | K2: 4 | L2: 2 | M2: 0 | N2: 2 | O2: 0 | P2: 0 | Q2: 0 | R2: 0 | S2: 3 | T2: 1 | U2: 3 | V2: 0 | W2: 2 | X2: 1 | Y2: 2 | Z2: 0 | AA2: 2 | AB2: 1 | AC2: 2 | AD2: 0 | AE2: 2 | AF2: 2 | AG2: 2 | AH2: 4 | AI2: 2 | AJ2: 2 | AK2: 0 | AL2: 2 | AM2: 1 | AN2: 7 | AO2: 1 | AP2: 2 | AQ2: 3 | AR2: 0 | AS2: 1 | AT2: 2 | AU2: 3 | AV2: 0 | AW2: 1 | AX2: 5 | AY2: 0 | AZ2: 0 | BA2: 1 | BB2: 0 | BC2: 0 | BD2: 1 | BE2: 1 | BF2: 1 | BG2: 1 | BH2: 1 | BI2: 0 | BJ2: 1 | BK2: 2 | BL2: 2 | BM2: 0 | BN2: 1 | BO2: 0 | BP2: 0 | BQ2: 0 | BR2: 0 | BS2: 0 | BT2: 4 | BU2: 0 | BV2: 1 | BW2: 0 | BX2: 1 | BY2: 0 | BZ2: 2 | CA2: 2 | CB2: 1 | CC2: 1 | CD2: 0 | CE2: 2 | CF2: 1 | CG2: 2 | CH2: 0 | CI2: 2 | CJ2: 0 | CK2: 0 | CL2: 0 | CM2: 1 | CN2: 0 | CO2: 0 | CP2: 0 | CQ2: 0 | CR2: 0 | CS2: 0 | CT2: 3 | CU2: 2 | CV2: 7 | CW2: 1 | CX2: 0 | CY2: 0 | CZ2: 9 | DA2: 0 | DB2: 0 | DC2: 0 | DD2: 1 | DE2: 2 | DF2: 0 | DG2: 1 | DH2: 3 | DI2: 1 | DJ2: 3 | DK2: 0 | DL2: 0 | DM2: 1 | DN2: 1 | DO2: 1 | DP2: 3 | DQ2: 0 | DR2: 1 | DS2: 2 | DT2: 0 | DU2: 6 | DV2: 3 | DW2: 1 | DX2: 0 | DY2: 1 | DZ2: 0 | EA2: 2 | EB2: 0 | EC2: 0 | ED2: 0 | EE2: 0 | EF2: 0 | EG2: 1 | EH2: 4 | EI2: 0 | EJ2: 0 | EK2: 3 | EL2: 0 | EM2: 1 | EN2: 1 | EO2: 0 | EP2: 2 | EQ2: 3 | ER2: 2 | ES2: 3 | ET2: 1 | EU2: 1 | EV2: 0 | EW2: 2 | EX2: 1 | EY2: 0 | EZ2: 1 | FA2: 0 | FB2: 0 | FC2: 0 | FD2: 0 | FE2: 3 | FF2: 0 | FG2: 1 | FH2: 0 | FI2: 1 | FJ2: 0 | FK2: 1 | FL2: 2 | FM2: 0 | FN2: 0 | FO2: 4 | FP2: 0 | FQ2: 1 | FR2: 1 | FS2: 1 | FT2: 1 | FU2: 1 | FV2: 1 | FW2: 1 | FX2: 2 | FY2: 0 | FZ2: 2 | GA2: 0 | GB2: 0 | GC2: 0 | GD2: 1 | GE2: 0 | GF2: 2 | GG2: 0 | GH2: 1 | GI2: 0 | GJ2: 0 | GK2: 1 | GL2: 1 | GM2: 0 | GN2: 0 | GO2: 0 | GP2: 0 | GQ2: 0 | GR2: 0 | GS2: 0 | GT2: 0 | GU2: 0 | GV2: 0 | GW2: 0 | GX2: 0 | GY2: 0 | GZ2: 0 | HA2: 0 | HB2: 0 | HC2: 0 | HD2: 0 | HE2: 0 | HF2: 0 | HG2: 0 | HH2: 0 | HI2: 0 | HJ2: 0 | HK2: 0 | HL2: 0 | HM2: 0 | HN2: 0 | HO2: 0 | HP2: 0 | HQ2: 0 | HR2: 0 | HS2: 0 | HT2: 0 | HU2: 0 | HV2: 0 | HW2: 0 | HX2: 0 | HY2: 0 | HZ2: 0 | IA2: 0 | IB2: 0 | IC2: 0 | ID2: 0 | IE2: 0 | IF2: 0 | IG2: 0 | IH2: 0 | II2: 0 | IJ2: 0 | IK2: 0 | IL2: 0 | IM2: 0 | IN2: 0 | IO2: 0 | IP2: 0 | IQ2: 0 | IR2: 0 | IS2: 0 | IT2: 0 | IU2: 0 | IV2: 0 | IW2: 0 | IX2: 0 | IY2: 0 | IZ2: 0 | JA2: 0 | JB2: 0 | JC2: 0 | JD2: 0 | JE2: 0 | JF2: 0 | JG2: 0 | JH2: 0 | JI2: 0 | JJ2: 0 | JK2: 0 | JL2: 0 | JM2: 0 | JN2: 0 | JO2: 0 | JP2: 0 | JQ2: 0 | JR2: 0 | JS2: 0 | JT2: 0 | JU2: 0 | JV2: 0 | JW2: 0 | JX2: 3 | JY2: 1 | JZ2: 4 | KA2: 2 | KB2: 1 | KC2: 0 | KD2: 2 | KE2: 1 | KF2: 0 | KG2: 1 | KH2: 0 | KI2: 6 | KJ2: 1 | KK2: 0 | KL2: 0 | KM2: 0 | KN2: 1 | KO2: 3 | KP2: 4 | KQ2: 0 | KR2: 0 | KS2: 1 | KT2: 0 | KU2: 2 | KV2: 0 | KW2: 0 | KX2: 1 | KY2: 0 | KZ2: 8 | LA2: 3 | LB2: 1 | LC2: 1 | LD2: 5 | LE2: 3 | LF2: 2 | LG2: 0 | LH2: 1 | LI2: 0 | LJ2: 0 | LK2: 2 | LL2: 0 | LM2: 1 | LN2: 0 | LO2: 1 | LP2: 2 | LQ2: 2 | LR2: 6 | LS2: 2 | LT2: 3 | LU2: 5 | LV2: 3 | LW2: 5 | LX2: 1 | LY2: 0 | LZ2: 1 | MA2: 1 | MB2: 1 | MC2: 0 | MD2: 0 | ME2: 2 | MF2: 2 | MG2: 0 | MH2: 0 | MI2: 1 | MJ2: 1 | MK2: 0 | ML2: 1 | MM2: 0 | MN2: 0 | MO2: 0 | MP2: 2 | MQ2: 0 | MR2: 1 | MS2: 0 | MT2: 1 | MU2: 1 | MV2: 1 | MW2: 0 | MX2: 0 | MY2: 4 | MZ2: 1 | NA2: 1 | NB2: 0 | NC2: 0 | ND2: 0 | NE2: 0 | NF2: 0 | NG2: 2 | NH2: 4 | NI2: 0 | NJ2: 1 | NK2: 0 | NL2: 0 | NM2: 0 | NN2: 0 | NO2: 2 | NP2: 0 | NQ2: 0 | NR2: 1 | NS2: 2 | NT2: 0 | NU2: 1 | NV2: 3 | NW2: 0 | NX2: 0 | NY2: 0 | NZ2: 2 | OA2: 0 | OB2: 0 | OC2: 0 | OD2: 0 | OE2: 1 | OF2: 1 | OG2: 0 | OH2: 4 | OI2: 0 | OJ2: 3 | OK2: 1 | OL2: 0 | OM2: 1 | ON2: 1 | OO2: 2 | OP2: 3 | OQ2: 0 | OR2: 0 | OS2: 1 | OT2: 0 | OU2: 0 | OV2: 2 | OW2: 2 | OX2: 3 | OY2: 1 | OZ2: 0 | PA2: 1 | PB2: 1 | PC2: 0 | PD2: 1 | PE2: 0 | PF2: 0 | PG2: 1 | PH2: 0 | PI2: 1 | PJ2: 2 | PK2: 2 | PL2: 2 | PM2: 7 | PN2: 1 | PO2: 0 | PP2: 1 | PQ2: 3 | PR2: 0 | PS2: 3 | PT2: 0 | PU2: 2 | PV2: 0 | PW2: 1 | PX2: 4 | PY2: 2 | PZ2: 2 | QA2: 0 | QB2: 0 | QC2: 0 | QD2: 0 | QE2: 2 | QF2: 2 | QG2: 3 | QH2: 0 | QI2: 1 | QJ2: 0 | QK2: 1 | QL2: 0 | QM2: 4 | QN2: 0 | QO2: 0 | QP2: 1 | QQ2: 0 | QR2: 0 | QS2: 1 | QT2: 0 | QU2: 2 | QV2: 1 | QW2: 2 | QX2: 1 | QY2: 0 | QZ2: 2 | RA2: 1 | RB2: 0 | RC2: 2 | RD2: 0 | RE2: 1 | RF2: 1 | RG2: 0 | RH2: 1 | RI2: 3 | RJ2: 2 | RK2: 0 | RL2: 0 | RM2: 0 | RN2: 0 | RO2: 0 | RP2: 1 | RQ2: 0 | RR2: 1 | RS2: 2 | RT2: 1 | RU2: 2 | RV2: 1 | RW2: 0 | RX2: 0 | RY2: 2 | RZ2: 1 | SA2: 4 | SB2: 0 | SC2: 1 | SD2: 1 | SE2: 0 | SF2: 0 | SG2: 0 | SH2: 0 | SI2: 0 | SJ2: 3 | SK2: 2 | SL2: 2 | SM2: 1 | SN2: 1 | SO2: 2 | SP2: 0 | SQ2: 1 | SR2: 4 | SS2: 2 | ST2: 0 | SU2: 0 | SV2: 1 | SW2: 1 | SX2: 0 | SY2: 0 | SZ2: 0 | TA2: 1 | TB2: 1 | TC2: 0 | TD2: 0 | TE2: 1 | TF2: 1 | TG2: 0 | TH2: 0 | TI2: 1 | TJ2: 1 | TK2: 0 | TL2: 1 | TM2: 1 | TN2: 0 | TO2: 2 | TP2: 0 | TQ2: 1 | TR2: 0 | TS2: 0 | TT2: 1 | TU2: 0 | TV2: 2 | TW2: 4 | TX2: 0 | TY2: 2 | TZ2: 2 | UA2: 0 | UB2: 0 | UC2: 1 | UD2: 2 | UE2: 2 | UF2: 0 | UG2: 2 | UH2: 1 | UI2: 1 | UJ2: 1 | UK2: 2 | UL2: 0 | UM2: 0 | UN2: 4 | UO2: 1 | UP2: 0 | UQ2: 0 | UR2: 2 | US2: 1 | UT2: 13 | UU2: 1 | UV2: 0 | UW2: 0 | UX2: 5 | UY2: 0 | UZ2: 1 | VA2: 4 | VB2: 4 | VC2: 2 | VD2: 6 | VE2: 0 | VF2: 0 | VG2: 0 | VH2: 0 | VI2: 15 | VJ2: 3 | VK2: 0 | VL2: 1 | VM2: 0 | VN2: 1 | VO2: 0 | VP2: 1 | VQ2: 1 | VR2: 2 | VS2: 2 | VT2: 1 | VU2: 1 | VV2: 1 | VW2: 1 | VX2: 2 | VY2: 2 | VZ2: 2 | WA2: 0 | WB2: 2 | WC2: 0 | WD2: 1 | WE2: 5 | WF2: 1 | WG2: 0 | WH2: 1 | WI2: 0 | WJ2: 1 | WK2: 2 | WL2: 0 | WM2: 0 | WN2: 2 | WO2: 0 | WP2: 0 | WQ2: 2 | WR2: 0 | WS2: 6 | WT2: 2 | WU2: 3 | WV2: 1 | WW2: 2 | WX2: 0 | WY2: 2 | WZ2: 0 | XA2: 0 | XB2: 0 | XC2: 2 | XD2: 0 | XE2: 0 | XF2: 3 | XG2: 1 | XH2: 1 | XI2: 0 | XJ2: 0 | XK2: 1 | XL2: 1 | XM2: 1 | XN2: 0 | XO2: 0 | XP2: 0 | XQ2: 3 | XR2: 1 | XS2: 1 | XT2: 1 | XU2: 0 | XV2: 0 | XW2: 1 | XX2: 2 | XY2: 2 | XZ2: 5 | YA2: 2 | YB2: 0 | YC2: 0 | YD2: 0 | YE2: 2 | YF2: 1 | YG2: 0 | YH2: 0 | YI2: 0 | YJ2: 1 | YK2: 2 | YL2: 0 | YM2: 2 | YN2: 0 | YO2: 0 | YP2: 1 | YQ2: 0 | YR2: 0 | YS2: 0 | YT2: 0 | YU2: 0 | YV2: 3 | YW2: 0 | YX2: 5 | YY2: 2 | YZ2: 2 | ZA2: 0 | ZB2: 1 | ZC2: 0 | ZD2: 2 | ZE2: 0 | ZF2: 1 | ZG2: 5 | ZH2: 0 | ZI2: 1 | ZJ2: 0 | ZK2: 2 | ZL2: 0 | ZM2: 3 | ZN2: 0 | ZO2: 2 | ZP2: 2 | ZQ2: 0 | ZR2: 1 | ZS2: 0 | ZT2: 2 | ZU2: 0 | ZV2: 4 | ZW2: 4 | ZX2: 1 | ZY2: 1 | ZZ2: 0 | AAA2: 0 | AAB2: 1 | AAC2: 0 | AAD2: 0 | AAE2: 1 | AAF2: 2 | AAG2: 1 | AAH2: 0 | AAI2: 2 | AAJ2: 1 | AAK2: 1 | AAL2: 1 | AAM2: 0 | AAN2: 0 | AAO2: 0 | AAP2: 2 | AAQ2: 1 | AAR2: 3 | AAS2: 2 | AAT2: 1 | AAU2: 0 | AAV2: 0 | AAW2: 0 | AAX2: 0 | AAY2: 0 | AAZ2: 0 | ABA2: 2 | ABB2: 0 | ABC2: 2 | ABD2: 0 | ABE2: 0 | ABF2: 0 | ABG2: 1 | ABH2: 0 | ABI2: 0 | ABJ2: 0 | ABK2: 0 | ABL2: 0 | ABM2: 1 | ABN2: 2 | ABO2: 0 | ABP2: 2 | ABQ2: 1 | ABR2: 1 | ABS2: 0 | ABT2: 3 | ABU2: 3 | ABV2: 1 | ABW2: 1 | ABX2: 0 | ABY2: 1 | ABZ2: 0 | ACA2: 1 | ACB2: 1 | ACC2: 2 | ACD2: 0 | ACE2: 0 | ACF2: 0 | ACG2: 3 | ACH2: 0 | ACI2: 1 | ACJ2: 0 | ACK2: 0 | ACL2: 2 | ACM2: 0 | ACN2: 1 | ACO2: 1 | ACP2: 2 | ACQ2: 2 | ACR2: 0 | ACS2: 0 | ACT2: 0 | ACU2: 0 | ACV2: 0 | ACW2: 0 | ACX2: 2 | ACY2: 0 | ACZ2: 0 | ADA2: 0 | ADB2: 1 | ADC2: 2 | ADD2: 0 | ADE2: 0 | ADF2: 1 | ADG2: 0 | ADH2: 1 | ADI2: 2 | ADJ2: 2 | ADK2: 0 | ADL2: 0 | ADM2: 0 | ADN2: 1 | ADO2: 1 | ADP2: 1 | ADQ2: 0 | ADR2: 1 | ADS2: 1 | ADT2: 1 | ADU2: 0 | ADV2: 0 | ADW2: 1 | ADX2: 0 | ADY2: 0 | ADZ2: 0 | AEA2: 2 | AEB2: 0 | AEC2: 1 | AED2: 1 | AEE2: 1 | AEF2: 1 | AEG2: 1 | AEH2: 0 | AEI2: 0 | AEJ2: 0 | AEK2: 0 | AEL2: 0 | AEM2: 0 | AEN2: 0 | AEO2: 1 | AEP2: 0 | AEQ2: 0 | AER2: 0 | AES2: 1 | AET2: 0 | AEU2: 0 | AEV2: 0 | AEW2: 1 | AEX2: 2 | AEY2: 0 | AEZ2: 0 | AFA2: 0 | AFB2: 0 | AFC2: 0 | AFD2: 0 | AFE2: 2 | AFF2: 2 | AFG2: 1 | AFH2: 1 | AFI2: 0 | AFJ2: 1 | AFK2: 1 | AFL2: 3 | AFM2: 0 | AFN2: 1 | AFO2: 2 | AFP2: 0 | AFQ2: 0 | AFR2: 0 | AFS2: 0 | AFT2: 1 | AFU2: 0 | AFV2: 1 | AFW2: 0 | AFX2: 0 | AFY2: 2 | AFZ2: 2 | AGA2: 0 | AGB2: 1 | AGC2: 0 | AGD2: 0 | AGE2: 2 | AGF2: 0 | AGG2: 0 | AGH2: 0 | AGI2: 4 | AGJ2: 1 | AGK2: 0 | AGL2: 0 | AGM2: 0 | AGN2: 1 | AGO2: 1 | AGP2: 1 | AGQ2: 1 | AGR2: 1 | AGS2: 1 | AGT2: 0 | AGU2: 0 | AGV2: 0 | AGW2: 0 | AGX2: 2 | AGY2: 1 | AGZ2: 1 | AHA2: 0 | AHB2: 0 | AHC2: 0 | AHD2: 10 | AHE2: 0 | AHF2: 0 | AHG2: 1 | AHH2: 0 | AHI2: 0 | AHJ2: 0 | AHK2: 1 | AHL2: 1 | AHM2: 0 | AHN2: 9 | AHO2: 2 | AHP2: 0 | AHQ2: 0 | AHR2: 1 | AHS2: 2 | AHT2: 0 | AHU2: 1 | AHV2: 3 | AHW2: 0 | AHX2: 0 | AHY2: 0 | AHZ2: 1 | AIA2: 2 | AIB2: 0 | AIC2: 1 | AID2: 2 | AIE2: 0 | AIF2: 0 | AIG2: 1 | AIH2: 1 | AII2: 0 | AIJ2: 0 | AIK2: 0 | AIL2: 1 | AIM2: 1 | AIN2: 0 | AIO2: 0 | AIP2: 0 | AIQ2: 0 | AIR2: 1 | AIS2: 0 | AIT2: 1 | AIU2: 0 | AIV2: 0 | AIW2: 0 | AIX2: 0 | AIY2: 3 | AIZ2: 1 | AJA2: 0 | AJB2: 0 | AJC2: 1 | AJD2: 1 | AJE2: 0 | AJF2: 0 | AJG2: 0 | AJH2: 0 | AJI2: 0 | AJJ2: 0 | AJK2: 1 | AJL2: 0 | AJM2: 0 | AJN2: 0 | AJO2: 1 | AJP2: 0 | AJQ2: 0 | AJR2: 0 | AJS2: 0 | AJT2: 0 | AJU2: 0 | AJV2: 1 | AJW2: 0 | AJX2: 0 | AJY2: 0 | AJZ2: 2 | AKA2: 0 | AKB2: 0 | AKC2: 2 | AKD2: 1 | AKE2: 2 | AKF2: 2 | AKG2: 0 | AKH2: 0 | AKI2: 0 | AKJ2: 0 | AKK2: 1 | AKL2: 1 | AKM2: 0 | AKN2: 3 | AKO2: 1 | AKP2: 1 | AKQ2: 0 | AKR2: 0 | AKS2: 0 | AKT2: 0 | AKU2: 0 | AKV2: 0 | AKW2: 0 | AKX2: 1 | AKY2: 0 | AKZ2: 0 | ALA2: 0 | ALB2: 0 | ALC2: 0 | ALD2: 2 | ALE2: 0 | ALF2: 4 | ALG2: 2 | ALH2: 0 | ALI2: 0 | ALJ2: 1 | ALK2: 0 | ALL2: 2 | ALM2: 0 | ALN2: 0 | ALO2: 0 | ALP2: 1 | ALQ2: 0 | ALR2: 1 | ALS2: 0 | ALT2: 1 | ALU2: 0 | ALV2: 0 | ALW2: 0 | ALX2: 0 | ALY2: 1 | ALZ2: 0 | AMA2: 0 | AMB2: 0 | AMC2: 0 | AMD2: 0 | AME2: 0 | AMF2: 0 | AMG2: 0 | AMH2: 0 | AMI2: 0 | AMJ2: 0 | AMK2: 0 | AML2: 0 | AMM2: 0 | AMN2: 0 | AMO2: 0 | AMP2: 0 | AMQ2: 0 | AMR2: 0 | AMS2: 0 | AMT2: 0 | AMU2: 0 | AMV2: 0 | AMW2: 0 | AMX2: 0 | AMY2: 0 | AMZ2: 0 | ANA2: 0 | ANB2: 0 | ANC2: 0 | AND2: 0 | ANE2: 0 | ANF2: 0 | ANG2: 0 | ANH2: 0 | ANI2: 0 | ANJ2: 0 | ANK2: 0 | ANL2: 0 | ANM2: 0 | ANN2: 0 | ANO2: 0 | ANP2: 0 | ANQ2: 0 | ANR2: 0 | ANS2: 0 | ANT2: 0 | ANU2: 0 | ANV2: 0 | ANW2: 0 | ANX2: 0 | ANY2: 0 | ANZ2: 0 | AOA2: 0 | AOB2: 0 | AOC2: 0 | AOD2: 0 | AOE2: 0 | AOF2: 0 | AOG2: 0 | AOH2: 0 | AOI2: 0 | AOJ2: 0 | AOK2: 0 | AOL2: 0 | AOM2: 0 | AON2: 0 | AOO2: 0 | AOP2: 0 | AOQ2: 0 | AOR2: 0 | AOS2: 0 | AOT2: 0 | AOU2: 0 | AOV2: 0 | AOW2: 0 | AOX2: 0 | AOY2: 0 | AOZ2: 0 | APA2: 0 | APB2: 0 | APC2: 0 | APD2: 0 | APE2: 0 | APF2: 0 | APG2: 0 | APH2: 0 | API2: 0 | APJ2: 0 | APK2: 0 | APL2: 0 | APM2: 0 | APN2: 0 | APO2: 0 | APP2: 0 | APQ2: 0 | APR2: 0 | APS2: 0 | APT2: 2 | APU2: 2 | APV2: 0 | APW2: 0 | APX2: 4 | APY2: 0 | APZ2: 0 | AQA2: 1 | AQB2: 0 | AQC2: 2 | AQD2: 1 | AQE2: 0 | AQF2: 0 | AQG2: 0 | AQH2: 0 | AQI2: 2 | AQJ2: 0 | AQK2: 0 | AQL2: 3 | AQM2: 0 | AQN2: 1 | AQO2: 0 | AQP2: 4 | AQQ2: 0 | AQR2: 6 | AQS2: 0 | AQT2: 0 | AQU2: 0 | AQV2: 0 | AQW2: 0 | AQX2: 0 | AQY2: 0 | AQZ2: 0 | ARA2: 0 | ARB2: 1 | ARC2: 0 | ARD2: 2 | ARE2: 1 | ARF2: 0 | ARG2: 0 | ARH2: 0 | ARI2: 0 | ARJ2: 1 | ARK2: 1 | ARL2: 1 | ARM2: 0 | ARN2: 0 | ARO2: 1 | ARP2: 0 | ARQ2: 2 | ARR2: 1 | ARS2: 0 | ART2: 0 | ARU2: 0 | ARV2: 1 | ARW2: 1 | ARX2: 0 | ARY2: 3 | ARZ2: 0 | ASA2: 0 | ASB2: 2 | ASC2: 0 | ASD2: 0 | ASE2: 1 | ASF2: 0 | ASG2: 3 | ASH2: 0 | ASI2: 1 | ASJ2: 6 | ASK2: 2 | ASL2: 0 | ASM2: 3 | ASN2: 1 | ASO2: 2 | ASP2: 0 | ASQ2: 0 | ASR2: 0 | ASS2: 1 | AST2: 0 | ASU2: 0 | ASV2: 1 | ASW2: 1 | ASX2: 1 | ASY2: 1 | ASZ2: 3 | ATA2: 1 | ATB2: 1 | ATC2: 0 | ATD2: 0 | ATE2: 2 | ATF2: 0 | ATG2: 1 | ATH2: 2 | ATI2: 0 | ATJ2: 1 | ATK2: 2 | ATL2: 0 | ATM2: 0 | ATN2: 0 | ATO2: 2 | ATP2: 2 | ATQ2: 3 | ATR2: 1 | ATS2: 0 | ATT2: 1 | ATU2: 0 | ATV2: 0 | ATW2: 0 | ATX2: 0 | ATY2: 0 | ATZ2: 0 | AUA2: 5 | AUB2: 1 | AUC2: 0 | AUD2: 1 | AUE2: 1 | AUF2: 0 | AUG2: 0 | AUH2: 0 | AUI2: 2 | AUJ2: 2 | AUK2: 1 | AUL2: 0 | AUM2: 0 | AUN2: 0 | AUO2: 0 | AUP2: 1 | AUQ2: 2 | AUR2: 4 | AUS2: 1 | AUT2: 1 | AUU2: 1 | AUV2: 0 | AUW2: 1 | AUX2: 0 | AUY2: 1 | AUZ2: 2 | AVA2: 0 | AVB2: 1 | AVC2: 1 | AVD2: 2 | AVE2: 1 | AVF2: 0 | AVG2: 1 | AVH2: 0 | AVI2: 0 | AVJ2: 0 | AVK2: 0 | AVL2: 0 | AVM2: 0 | AVN2: 1 | AVO2: 0 | AVP2: 1 | AVQ2: 0 | AVR2: 0 | AVS2: 0 | AVT2: 1 | AVU2: 0 | AVV2: 0 | AVW2: 1 | AVX2: 0 | AVY2: 3 | AVZ2: 0 | AWA2: 1 | AWB2: 1 | AWC2: 0 | AWD2: 1 | AWE2: 2 | AWF2: 0 | AWG2: 1 | AWH2: 1 | AWI2: 0 | AWJ2: 0 | AWK2: 1 | AWL2: 0 | AWM2: 0 | AWN2: 2 | AWO2: 0 | AWP2: 0 | AWQ2: 0 | AWR2: 3 | AWS2: 0 | AWT2: 1 | AWU2: 2 | AWV2: 2 | AWW2: 2 | AWX2: 0 | AWY2: 2 | AWZ2: 0 | AXA2: 0 | AXB2: 0 | AXC2: 0 | AXD2: 2 | AXE2: 0 | AXF2: 0 | AXG2: 0 | AXH2: 1 | AXI2: 1 | AXJ2: 0 | AXK2: 1 | AXL2: 0 | AXM2: 3 | AXN2: 0 | AXO2: 1 | AXP2: 4 | AXQ2: 1 | AXR2: 0 | AXS2: 3 | AXT2: 0 | AXU2: 3 | AXV2: 1 | AXW2: 2 | AXX2: 1 | AXY2: 1 | AXZ2: 2 | AYA2: 0 | AYB2: 0 | AYC2: 0 | AYD2: 3 | AYE2: 0 | AYF2: 0 | AYG2: 0 | AYH2: 1 | AYI2: 0 | AYJ2: 1 | AYK2: 0 | AYL2: 0 | AYM2: 0 | AYN2: 0 | AYO2: 0 | AYP2: 0 | AYQ2: 0 | AYR2: 2 | AYS2: 1 | AYT2: 0 | AYU2: 0 | AYV2: 1 | AYW2: 1 | AYX2: 2 | AYY2: 1 | AYZ2: 1 | AZA2: 3 | AZB2: 1 | AZC2: 2 | AZD2: 0 | AZE2: 0 | AZF2: 0 | AZG2: 0 | AZH2: 1 | AZI2: 1 | AZJ2: 0 | AZK2: 0 | AZL2: 0 | AZM2: 0 | AZN2: 5 | AZO2: 0 | AZP2: 0 | AZQ2: 1 | AZR2: 0 | AZS2: 0 | AZT2: 1 | AZU2: 0 | AZV2: 4 | AZW2: 2 | AZX2: 0 | AZY2: 0 | AZZ2: 0 | BAA2: 0 | BAB2: 1 | BAC2: 0 | BAD2: 0 | BAE2: 0 | BAF2: 1 | BAG2: 3 | BAH2: 0 | BAI2: 1 | BAJ2: 0 | BAK2: 1 | BAL2: 2 | BAM2: 0 | BAN2: 0 | BAO2: 0 | BAP2: 2 | BAQ2: 1 | BAR2: 1 | BAS2: 0 | BAT2: 0 | BAU2: 0 | BAV2: 0 | BAW2: 2 | BAX2: 0 | BAY2: 0 | BAZ2: 0 | BBA2: 0 | BBB2: 0 | BBC2: 0 | BBD2: 0 | BBE2: 0 | BBF2: 0 | BBG2: 0 | BBH2: 0 | BBI2: 2 | BBJ2: 3 | BBK2: 0 | BBL2: 1 | BBM2: 0 | BBN2: 2 | BBO2: 2 | BBP2: 1 | BBQ2: 2 | BBR2: 2 | BBS2: 1 | BBT2: 1 | BBU2: 0 | BBV2: 1 | BBW2: 1 | BBX2: 1 | BBY2: 1 | BBZ2: 2 | BCA2: 1 | BCB2: 4 | BCC2: 0 | BCD2: 0 | BCE2: 1 | BCF2: 0 | BCG2: 0 | BCH2: 6 | BCI2: 0 | BCJ2: 1 | BCK2: 0 | BCL2: 1 | BCM2: 0 | BCN2: 1 | BCO2: 0 | BCP2: 0 | BCQ2: 2 | BCR2: 0 | BCS2: 2 | BCT2: 5 | BCU2: 1 | BCV2: 0 | BCW2: 0 | BCX2: 0 | BCY2: 0 | BCZ2: 0 | BDA2: 0 | BDB2: 0 | BDC2: 1 | BDD2: 0 | BDE2: 0 | BDF2: 1 | BDG2: 3 | BDH2: 0 | BDI2: 0 | BDJ2: 0 | BDK2: 0 | BDL2: 1 | BDM2: 0 | BDN2: 3 | BDO2: 0 | BDP2: 0 | BDQ2: 0 | BDR2: 0 | BDS2: 0 | BDT2: 0 | BDU2: 0 | BDV2: 2 | BDW2: 1 | BDX2: 1 | BDY2: 1 | BDZ2: 0 | BEA2: 4 | BEB2: 2 | BEC2: 1 | BED2: 1 | BEE2: 1 | BEF2: 0 | BEG2: 0 | BEH2: 0 | BEI2: 1 | BEJ2: 0 | BEK2: 0 | BEL2: 0 | BEM2: 1 | BEN2: 0 | BEO2: 0 | BEP2: 1 | BEQ2: 0 | BER2: 0 | BES2: 0 | BET2: 1 | BEU2: 7 | BEV2: 1 | BEW2: 0 | BEX2: 1 | BEY2: 0 | BEZ2: 1 | BFA2: 0 | BFB2: 1 | BFC2: 2 | BFD2: 1 | BFE2: 1 | BFF2: 2 | BFG2: 0 | BFH2: 0 | BFI2: 0 | BFJ2: 0 | BFK2: 0 | BFL2: 1 | BFM2: 0 | BFN2: 0 | BFO2: 0 | BFP2: 0 | BFQ2: 0 | BFR2: 0 | BFS2: 0 | BFT2: 0 | BFU2: 0 | BFV2: 0 | BFW2: 1 | BFX2: 0 | BFY2: 2 | BFZ2: 2 | BGA2: 0 | BGB2: 0 | BGC2: 1 | BGD2: 0 | BGE2: 0 | BGF2: 1 | BGG2: 2 | BGH2: 1 | BGI2: 1 | BGJ2: 0 | BGK2: 2 | BGL2: 0 | BGM2: 0 | BGN2: 1 | BGO2: 0 | BGP2: 0 | BGQ2: 0 | BGR2: 1 | BGS2: 0 | BGT2: 4 | BGU2: 0 | BGV2: 1 | BGW2: 0 | BGX2: 0 | BGY2: 0 | BGZ2: 1 | BHA2: 2 | BHB2: 0 | BHC2: 2 | BHD2: 0 | BHE2: 1 | BHF2: 0 | BHG2: 0 | BHH2: 2 | BHI2: 0 | BHJ2: 0 | BHK2: 1 | BHL2: 0 | BHM2: 0 | BHN2: 0 | BHO2: 0 | BHP2: 2 | BHQ2: 0 | BHR2: 0 | BHS2: 0 | BHT2: 1 | BHU2: 2 | BHV2: 0 | BHW2: 0 | BHX2: 0 | BHY2: 0 | BHZ2: 1 | BIA2: 0 | BIB2: 0 | BIC2: 0 | BID2: 2 | BIE2: 4 | BIF2: 0 | BIG2: 4 | BIH2: 1 | BII2: 0 | BIJ2: 1 | BIK2: 1 | BIL2: 0 | BIM2: 0 | BIN2: 0 | BIO2: 2 | BIP2: 0 | BIQ2: 0 | BIR2: 2 | BIS2: 1 | BIT2: 0 | BIU2: 0 | BIV2: 0 | BIW2: 1 | BIX2: 0 | BIY2: 1 | BIZ2: 0 | BJA2: 0 | BJB2: 0 | BJC2: 0 | BJD2: 0 | BJE2: 1 | BJF2: 0 | BJG2: 0 | BJH2: 0 | BJI2: 1 | BJJ2: 1 | BJK2: 0 | BJL2: 0 | BJM2: 0 | BJN2: 1 | BJO2: 0 | BJP2: 0 | BJQ2: 1 | BJR2: 0 | BJS2: 0 | BJT2: 3 | BJU2: 1 | BJV2: 0 | BJW2: 0 | BJX2: 1 | BJY2: 0 | BJZ2: 2 | BKA2: 3 | BKB2: 0 | BKC2: 0 | BKD2: 0 | BKE2: 0 | BKF2: 1 | BKG2: 0 | BKH2: 0 | BKI2: 0 | BKJ2: 1 | BKK2: 0 | BKL2: 0 | BKM2: 1 | BKN2: 0 | BKO2: 0 | BKP2: 0 | BKQ2: 0 | BKR2: 0 | BKS2: 0 | BKT2: 1 | BKU2: 0 | BKV2: 3 | BKW2: 1 | BKX2: 2 | BKY2: 0 | BKZ2: 0 | BLA2: 0 | BLB2: 0 | BLC2: 0 | BLD2: 0 | BLE2: 4 | BLF2: 0 | BLG2: 1 | BLH2: 1 | BLI2: 0 | BLJ2: 1 | BLK2: 0 | BLL2: 0 | BLM2: 1 | BLN2: 0 | BLO2: 2 | BLP2: 0 | BLQ2: 0 | BLR2: 0 | BLS2: 0 | BLT2: 1 | BLU2: 0 | BLV2: 0 | BLW2: 0 | BLX2: 0 | BLY2: 0 | BLZ2: 0 | BMA2: 1 | BMB2: 0 | BMC2: 4 | BMD2: 0 | BME2: 0 | BMF2: 0 | BMG2: 0 | BMH2: 0 | BMI2: 1 | BMJ2: 2 | BMK2: 3 | BML2: 0 | BMM2: 0 | BMN2: 0 | BMO2: 0 | BMP2: 2 | BMQ2: 1 | BMR2: 0 | BMS2: 0 | BMT2: 0 | BMU2: 0 | BMV2: 0 | BMW2: 0 | BMX2: 0 | BMY2: 0 | BMZ2: 4 | BNA2: 0 | BNB2: 1 | BNC2: 0 | BND2: 0 | BNE2: 0 | BNF2: 1 | BNG2: 4 | BNH2: 1 | BNI2: 0 | BNJ2: 0 | BNK2: 0 | BNL2: 1 | BNM2: 0 | BNN2: 1 | BNO2: 0 | BNP2: 0 | BNQ2: 2 | BNR2: 0 | BNS2: 0 | BNT2: 0 | BNU2: 1 | BNV2: 0 | BNW2: 0 | BNX2: 0 | BNY2: 1 | BNZ2: 1 | BOA2: 0 | BOB2: 1 | BOC2: 1 | BOD2: 1 | BOE2: 0 | BOF2: 0 | BOG2: 0 | BOH2: 1 | BOI2: 0 | BOJ2: 0 | BOK2: 2 | BOL2: 0 | BOM2: 1 | BON2: 0 | BOO2: 1 | BOP2: 0 | BOQ2: 1 | BOR2: 1 | BOS2: 6 | BOT2: 0 | BOU2: 0 | BOV2: 1 | BOW2: 1 | BOX2: 1 | BOY2: 1 | BOZ2: 0 | BPA2: 2 | BPB2: 1 | BPC2: 0 | BPD2: 1 | BPE2: 0 | BPF2: 0 | BPG2: 1 | BPH2: 0 | BPI2: 3 | BPJ2: 0 | BPK2: 0 | BPL2: 2 | BPM2: 4 | BPN2: 1 | BPO2: 1 | BPP2: 1 | BPQ2: 0 | BPR2: 4 | BPS2: 0 | BPT2: 1 | BPU2: 0 | BPV2: 0 | BPW2: 0 | BPX2: 2 | BPY2: 0 | BPZ2: 0 | BQA2: 1 | BQB2: 2 | BQC2: 0 | BQD2: 0 | BQE2: 1 | BQF2: 0 | BQG2: 0 | BQH2: 0 | BQI2: 0 | BQJ2: 2 | BQK2: 0 | BQL2: 0 | BQM2: 0 | BQN2: 1 | BQO2: 0 | BQP2: 0 | BQQ2: 0 | BQR2: 3 | BQS2: 0 | BQT2: 0 | BQU2: 0 | BQV2: 0 | BQW2: 2 | BQX2: 0 | BQY2: 0 | BQZ2: 0 | BRA2: 1 | BRB2: 0 | BRC2: 0 | BRD2: 0 | BRE2: 1 | BRF2: 0 | BRG2: 0 | BRH2: 0 | BRI2: 0 | BRJ2: 1 | BRK2: 1 | BRL2: 2 | BRM2: 1 | BRN2: 0 | BRO2: 2 | BRP2: 0 | BRQ2: 2 | BRR2: 0 | BRS2: 3 | BRT2: 1 | BRU2: 2 | BRV2: 0 | BRW2: 2 | BRX2: 0 | BRY2: 0 | BRZ2: 2 | BSA2: 0 | BSB2: 0 | BSC2: 2 | BSD2: 1 | BSE2: 0 | BSF2: 1 | BSG2: 0 | BSH2: 1 | BSI2: 2 | BSJ2: 0 | BSK2: 0 | BSL2: 1 | BSM2: 0 | BSN2: 0 | BSO2: 0 | BSP2: 0 | BSQ2: 0 | BSR2: 1 | BSS2: 0 | BST2: 1 | BSU2: 0 | BSV2: 0 | BSW2: 2 | BSX2: 0 | BSY2: 0 | BSZ2: 0 | BTA2: 0 | BTB2: 1 | BTC2: 1 | BTD2: 1 | BTE2: 1 | BTF2: 3 | BTG2: 0 | BTH2: 0 | BTI2: 2 | BTJ2: 1 | BTK2: 2 | BTL2: 2 | BTM2: 0 | BTN2: 2 | BTO2: 2 | BTP2: 0 | BTQ2: 1 | BTR2: 1 | BTS2: 0 | BTT2: 2 | BTU2: 1 | BTV2: 1 | BTW2: 0 | BTX2: 4 | BTY2: 0 | BTZ2: 0 | BUA2: 4 | BUB2: 1 | BUC2: 3 | BUD2: 0 | BUE2: 1 | BUF2: 0 | BUG2: 2 | BUH2: 2 | BUI2: 0 | BUJ2: 1 | BUK2: 1 | BUL2: 0 | BUM2: 2 | BUN2: 0 | BUO2: 4 | BUP2: 1 | BUQ2: 1 | BUR2: 0 | BUS2: 1 | BUT2: 1 | BUU2: 0
