Workbook

Sheet raw_sales
A1: item_id | B1: store_id | C1: d_1 | D1: d_2 | E1: d_3 | F1: d_4 | G1: d_5 | H1: d_6 | I1: d_7 | J1: d_8 | K1: d_9 | L1: d_10 | M1: d_11 | N1: d_12 | O1: d_13 | P1: d_14 | Q1: d_15 | R1: d_16 | S1: d_17 | T1: d_18 | U1: d_19 | V1: d_20 | W1: d_21 | X1: d_22 | Y1: d_23 | Z1: d_24 | AA1: d_25 | AB1: d_26 | AC1: d_27 | AD1: d_28 | AE1: d_29 | AF1: d_30 | AG1: d_31 | AH1: d_32 | AI1: d_33 | AJ1: d_34 | AK1: d_35 | AL1: d_36 | AM1: d_37 | AN1: d_38 | AO1: d_39 | AP1: d_40 | AQ1: d_41 | AR1: d_42 | AS1: d_43 | AT1: d_44 | AU1: d_45 | AV1: d_46 | AW1: d_47 | AX1: d_48 | AY1: d_49 | AZ1: d_50 | BA1: d_51 | BB1: d_52 | BC1: d_53 | BD1: d_54 | BE1: d_55 | BF1: d_56 | BG1: d_57 | BH1: d_58 | BI1: d_59 | BJ1: d_60 | BK1: d_61 | BL1: d_62 | BM1: d_63 | BN1: d_64 | BO1: d_65 | BP1: d_66 | BQ1: d_67 | BR1: d_68 | BS1: d_69 | BT1: d_70 | BU1: d_71 | BV1: d_72 | BW1: d_73 | BX1: d_74 | BY1: d_75 | BZ1: d_76 | CA1: d_77 | CB1: d_78 | CC1: d_79 | CD1: d_80 | CE1: d_81 | CF1: d_82 | CG1: d_83 | CH1: d_84 | CI1: d_85 | CJ1: d_86 | CK1: d_87 | CL1: d_88 | CM1: d_89 | CN1: d_90 | CO1: d_91 | CP1: d_92 | CQ1: d_93 | CR1: d_94 | CS1: d_95 | CT1: d_96 | CU1: d_97 | CV1: d_98 | CW1: d_99 | CX1: d_100 | CY1: d_101 | CZ1: d_102 | DA1: d_103 | DB1: d_104 | DC1: d_105 | DD1: d_106 | DE1: d_107 | DF1: d_108 | DG1: d_109 | DH1: d_110 | DI1: d_111 | DJ1: d_112 | DK1: d_113 | DL1: d_114 | DM1: d_115 | DN1: d_116 | DO1: d_117 | DP1: d_118 | DQ1: d_119 | DR1: d_120 | DS1: d_121 | DT1: d_122 | DU1: d_123 | DV1: d_124 | DW1: d_125 | DX1: d_126 | DY1: d_127 | DZ1: d_128 | EA1: d_129 | EB1: d_130 | EC1: d_131 | ED1: d_132 | EE1: d_133 | EF1: d_134 | EG1: d_135 | EH1: d_136 | EI1: d_137 | EJ1: d_138 | EK1: d_139 | EL1: d_140 | EM1: d_141 | EN1: d_142 | EO1: d_143 | EP1: d_144 | EQ1: d_145 | ER1: d_146 | ES1: d_147 | ET1: d_148 | EU1: d_149 | EV1: d_150 | EW1: d_151 | EX1: d_152 | EY1: d_153 | EZ1: d_154 | FA1: d_155 | FB1: d_156 | FC1: d_157 | FD1: d_158 | FE1: d_159 | FF1: d_160 | FG1: d_161 | FH1: d_162 | FI1: d_163 | FJ1: d_164 | FK1: d_165 | FL1: d_166 | FM1: d_167 | FN1: d_168 | FO1: d_169 | FP1: d_170 | FQ1: d_171 | FR1: d_172 | FS1: d_173 | FT1: d_174 | FU1: d_175 | FV1: d_176 | FW1: d_177 | FX1: d_178 | FY1: d_179 | FZ1: d_180 | GA1: d_181 | GB1: d_182 | GC1: d_183 | GD1: d_184 | GE1: d_185 | GF1: d_186 | GG1: d_187 | GH1: d_188 | GI1: d_189 | GJ1: d_190 | GK1: d_191 | GL1: d_192 | GM1: d_193 | GN1: d_194 | GO1: d_195 | GP1: d_196 | GQ1: d_197 | GR1: d_198 | GS1: d_199 | GT1: d_200 | GU1: d_201 | GV1: d_202 | GW1: d_203 | GX1: d_204 | GY1: d_205 | GZ1: d_206 | HA1: d_207 | HB1: d_208 | HC1: d_209 | HD1: d_210 | HE1: d_211 | HF1: d_212 | HG1: d_213 | HH1: d_214 | HI1: d_215 | HJ1: d_216 | HK1: d_217 | HL1: d_218 | HM1: d_219 | HN1: d_220 | HO1: d_221 | HP1: d_222 | HQ1: d_223 | HR1: d_224 | HS1: d_225 | HT1: d_226 | HU1: d_227 | HV1: d_228 | HW1: d_229 | HX1: d_230 | HY1: d_231 | HZ1: d_232 | IA1: d_233 | IB1: d_234 | IC1: d_235 | ID1: d_236 | IE1: d_237 | IF1: d_238 | IG1: d_239 | IH1: d_240 | II1: d_241 | IJ1: d_242 | IK1: d_243 | IL1: d_244 | IM1: d_245 | IN1: d_246 | IO1: d_247 | IP1: d_248 | IQ1: d_249 | IR1: d_250 | IS1: d_251 | IT1: d_252 | IU1: d_253 | IV1: d_254 | IW1: d_255 | IX1: d_256 | IY1: d_257 | IZ1: d_258 | JA1: d_259 | JB1: d_260 | JC1: d_261 | JD1: d_262 | JE1: d_263 | JF1: d_264 | JG1: d_265 | JH1: d_266 | JI1: d_267 | JJ1: d_268 | JK1: d_269 | JL1: d_270 | JM1: d_271 | JN1: d_272 | JO1: d_273 | JP1: d_274 | JQ1: d_275 | JR1: d_276 | JS1: d_277 | JT1: d_278 | JU1: d_279 | JV1: d_280 | JW1: d_281 | JX1: d_282 | JY1: d_283 | JZ1: d_284 | KA1: d_285 | KB1: d_286 | KC1: d_287 | KD1: d_288 | KE1: d_289 | KF1: d_290 | KG1: d_291 | KH1: d_292 | KI1: d_293 | KJ1: d_294 | KK1: d_295 | KL1: d_296 | KM1: d_297 | KN1: d_298 | KO1: d_299 | KP1: d_300 | KQ1: d_301 | KR1: d_302 | KS1: d_303 | KT1: d_304 | KU1: d_305 | KV1: d_306 | KW1: d_307 | KX1: d_308 | KY1: d_309 | KZ1: d_310 | LA1: d_311 | LB1: d_312 | LC1: d_313 | LD1: d_314 | LE1: d_315 | LF1: d_316 | LG1: d_317 | LH1: d_318 | LI1: d_319 | LJ1: d_320 | LK1: d_321 | LL1: d_322 | LM1: d_323 | LN1: d_324 | LO1: d_325 | LP1: d_326 | LQ1: d_327 | LR1: d_328 | LS1: d_329 | LT1: d_330 | LU1: d_331 | LV1: d_332 | LW1: d_333 | LX1: d_334 | LY1: d_335 | LZ1: d_336 | MA1: d_337 | MB1: d_338 | MC1: d_339 | MD1: d_340 | ME1: d_341 | MF1: d_342 | MG1: d_343 | MH1: d_344 | MI1: d_345 | MJ1: d_346 | MK1: d_347 | ML1: d_348 | MM1: d_349 | MN1: d_350 | MO1: d_351 | MP1: d_352 | MQ1: d_353 | MR1: d_354 | MS1: d_355 | MT1: d_356 | MU1: d_357 | MV1: d_358 | MW1: d_359 | MX1: d_360 | MY1: d_361 | MZ1: d_362 | NA1: d_363 | NB1: d_364 | NC1: d_365 | ND1: Total
A2: FOODS_1_218 | B2: CA_1 | C2: 10 | D2: 3 | E2: 4 | F2: 0 | G2: 0 | H2: 0 | I2: 1 | J2: 4 | K2: 2 | L2: 0 | M2: 0 | N2: 4 | O2: 0 | P2: 2 | Q2: 0 | R2: 0 | S2: 1 | T2: 3 | U2: 2 | V2: 0 | W2: 0 | X2: 0 | Y2: 0 | Z2: 0 | AA2: 0 | AB2: 0 | AC2: 0 | AD2: 0 | AE2: 0 | AF2: 0 | AG2: 0 | AH2: 26 | AI2: 14 | AJ2: 24 | AK2: 16 | AL2: 18 | AM2: 15 | AN2: 6 | AO2: 2 | AP2: 3 | AQ2: 2 | AR2: 2 | AS2: 6 | AT2: 4 | AU2: 2 | AV2: 3 | AW2: 0 | AX2: 0 | AY2: 12 | AZ2: 2 | BA2: 2 | BB2: 0 | BC2: 2 | BD2: 0 | BE2: 0 | BF2: 0 | BG2: 1 | BH2: 0 | BI2: 0 | BJ2: 0 | BK2: 0 | BL2: 0 | BM2: 0 | BN2: 0 | BO2: 0 | BP2: 0 | BQ2: 0 | BR2: 0 | BS2: 0 | BT2: 0 | BU2: 0 | BV2: 0 | BW2: 0 | BX2: 0 | BY2: 0 | BZ2: 0 | CA2: 0 | CB2: 0 | CC2: 0 | CD2: 0 | CE2: 0 | CF2: 0 | CG2: 0 | CH2: 0 | CI2: 0 | CJ2: 0 | CK2: 0 | CL2: 0 | CM2: 0 | CN2: 0 | CO2: 0 | CP2: 0 | CQ2: 0 | CR2: 0 | CS2: 23 | CT2: 6 | CU2: 10 | CV2: 10 | CW2: 7 | CX2: 8 | CY2: 19 | CZ2: 4 | DA2: 1 | DB2: 7 | DC2: 4 | DD2: 8 | DE2: 2 | DF2: 4 | DG2: 0 | DH2: 3 | DI2: 0 | DJ2: 5 | DK2: 3 | DL2: 2 | DM2: 0 | DN2: 1 | DO2: 0 | DP2: 0 | DQ2: 0 | DR2: 0 | DS2: 0 | DT2: 4 | DU2: 6 | DV2: 4 | DW2: 10 | DX2: 20 | DY2: 19 | DZ2: 12 | EA2: 7 | EB2: 2 | EC2: 1 | ED2: 0 | EE2: 0 | EF2: 6 | EG2: 8 | EH2: 7 | EI2: 7 | EJ2: 4 | EK2: 3 | EL2: 6 | EM2: 9 | EN2: 10 | EO2: 5 | EP2: 17 | EQ2: 15 | ER2: 21 | ES2: 22 | ET2: 21 | EU2: 18 | EV2: 24 | EW2: 8 | EX2: 14 | EY2: 13 | EZ2: 16 | FA2: 17 | FB2: 11 | FC2: 9 | FD2: 17 | FE2: 10 | FF2: 12 | FG2: 11 | FH2: 14 | FI2: 27 | FJ2: 4 | FK2: 11 | FL2: 10 | FM2: 17 | FN2: 6 | FO2: 33 | FP2: 14 | FQ2: 5 | FR2: 15 | FS2: 8 | FT2: 8 | FU2: 5 | FV2: 15 | FW2: 9 | FX2: 2 | FY2: 13 | FZ2: 15 | GA2: 16 | GB2: 7 | GC2: 10 | GD2: 0 | GE2: 0 | GF2: 0 | GG2: 0 | GH2: 0 | GI2: 0 | GJ2: 0 | GK2: 25 | GL2: 10 | GM2: 8 | GN2: 8 | GO2: 8 | GP2: 13 | GQ2: 13 | GR2: 3 | GS2: 3 | GT2: 7 | GU2: 10 | GV2: 11 | GW2: 12 | GX2: 12 | GY2: 18 | GZ2: 4 | HA2: 4 | HB2: 7 | HC2: 7 | HD2: 8 | HE2: 17 | HF2: 26 | HG2: 2 | HH2: 12 | HI2: 8 | HJ2: 6 | HK2: 4 | HL2: 6 | HM2: 4 | HN2: 9 | HO2: 17 | HP2: 11 | HQ2: 17 | HR2: 9 | HS2: 20 | HT2: 13 | HU2: 7 | HV2: 14 | HW2: 16 | HX2: 17 | HY2: 3 | HZ2: 20 | IA2: 14 | IB2: 5 | IC2: 7 | ID2: 1 | IE2: 2 | IF2: 7 | IG2: 18 | IH2: 16 | II2: 12 | IJ2: 2 | IK2: 4 | IL2: 18 | IM2: 23 | IN2: 59 | IO2: 30 | IP2: 27 | IQ2: 17 | IR2: 11 | IS2: 4 | IT2: 11 | IU2: 10 | IV2: 8 | IW2: 4 | IX2: 12 | IY2: 6 | IZ2: 11 | JA2: 27 | JB2: 31 | JC2: 17 | JD2: 20 | JE2: 7 | JF2: 7 | JG2: 7 | JH2: 5 | JI2: 18 | JJ2: 17 | JK2: 1 | JL2: 2 | JM2: 4 | JN2: 2 | JO2: 1 | JP2: 1 | JQ2: 3 | JR2: 0 | JS2: 8 | JT2: 2 | JU2: 6 | JV2: 4 | JW2: 4 | JX2: 4 | JY2: 4 | JZ2: 1 | KA2: 0 | KB2: 5 | KC2: 2 | KD2: 3 | KE2: 0 | KF2: 2 | KG2: 2 | KH2: 0 | KI2: 1 | KJ2: 3 | KK2: 2 | KL2: 2 | KM2: 0 | KN2: 0 | KO2: 3 | KP2: 0 | KQ2: 1 | KR2: 27 | KS2: 25 | KT2: 13 | KU2: 20 | KV2: 4 | KW2: 10 | KX2: 11 | KY2: 5 | KZ2: 9 | LA2: 8 | LB2: 5 | LC2: 5 | LD2: 3 | LE2: 20 | LF2: 14 | LG2: 36 | LH2: 6 | LI2: 6 | LJ2: 4 | LK2: 1 | LL2: 4 | LM2: 7 | LN2: 2 | LO2: 2 | LP2: 27 | LQ2: 35 | LR2: 26 | LS2: 13 | LT2: 12 | LU2: 0 | LV2: 2 | LW2: 6 | LX2: 1 | LY2: 4 | LZ2: 1 | MA2: 54 | MB2: 33 | MC2: 41 | MD2: 38 | ME2: 25 | MF2: 13 | MG2: 13 | MH2: 18 | MI2: 18 | MJ2: 20 | MK2: 14 | ML2: 23 | MM2: 19 | MN2: 26 | MO2: 68 | MP2: 28 | MQ2: 25 | MR2: 14 | MS2: 24 | MT2: 14 | MU2: 23 | MV2: 27 | MW2: 41 | MX2: 19 | MY2: 19 | MZ2: 24 | NA2: 35 | NB2: 37 | NC2: 55 | ND2: =SUM(C2:NC2) -> 3214
A3: FOODS_1_085 | B3: CA_1 | C3: 10 | D3: 15 | E3: 13 | F3: 5 | G3: 11 | H3: 5 | I3: 7 | J3: 21 | K3: 6 | L3: 6 | M3: 5 | N3: 6 | O3: 14 | P3: 13 | Q3: 35 | R3: 25 | S3: 19 | T3: 4 | U3: 8 | V3: 10 | W3: 6 | X3: 25 | Y3: 24 | Z3: 7 | AA3: 10 | AB3: 6 | AC3: 14 | AD3: 27 | AE3: 24 | AF3: 8 | AG3: 3 | AH3: 4 | AI3: 3 | AJ3: 6 | AK3: 1 | AL3: 1 | AM3: 1 | AN3: 0 | AO3: 31 | AP3: 25 | AQ3: 19 | AR3: 27 | AS3: 34 | AT3: 32 | AU3: 12 | AV3: 20 | AW3: 14 | AX3: 8 | AY3: 33 | AZ3: 41 | BA3: 14 | BB3: 18 | BC3: 15 | BD3: 7 | BE3: 15 | BF3: 18 | BG3: 20 | BH3: 20 | BI3: 10 | BJ3: 10 | BK3: 3 | BL3: 6 | BM3: 17 | BN3: 20 | BO3: 11 | BP3: 15 | BQ3: 9 | BR3: 4 | BS3: 13 | BT3: 7 | BU3: 16 | BV3: 18 | BW3: 12 | BX3: 8 | BY3: 8 | BZ3: 12 | CA3: 15 | CB3: 21 | CC3: 17 | CD3: 5 | CE3: 9 | CF3: 18 | CG3: 13 | CH3: 30 | CI3: 46 | CJ3: 15 | CK3: 11 | CL3: 8 | CM3: 8 | CN3: 10 | CO3: 16 | CP3: 17 | CQ3: 14 | CR3: 14 | CS3: 16 | CT3: 14 | CU3: 32 | CV3: 22 | CW3: 21 | CX3: 31 | CY3: 8 | CZ3: 6 | DA3: 12 | DB3: 13 | DC3: 12 | DD3: 9 | DE3: 18 | DF3: 5 | DG3: 7 | DH3: 8 | DI3: 5 | DJ3: 13 | DK3: 15 | DL3: 10 | DM3: 10 | DN3: 8 | DO3: 7 | DP3: 5 | DQ3: 8 | DR3: 10 | DS3: 6 | DT3: 2 | DU3: 6 | DV3: 11 | DW3: 6 | DX3: 8 | DY3: 0 | DZ3: 0 | EA3: 0 | EB3: 0 | EC3: 1 | ED3: 5 | EE3: 8 | EF3: 14 | EG3: 18 | EH3: 17 | EI3: 10 | EJ3: 22 | EK3: 20 | EL3: 28 | EM3: 14 | EN3: 8 | EO3: 8 | EP3: 12 | EQ3: 17 | ER3: 10 | ES3: 20 | ET3: 25 | EU3: 19 | EV3: 13 | EW3: 16 | EX3: 16 | EY3: 14 | EZ3: 15 | FA3: 21 | FB3: 36 | FC3: 10 | FD3: 9 | FE3: 15 | FF3: 17 | FG3: 10 | FH3: 25 | FI3: 20 | FJ3: 7 | FK3: 9 | FL3: 12 | FM3: 21 | FN3: 20 | FO3: 25 | FP3: 14 | FQ3: 10 | FR3: 14 | FS3: 14 | FT3: 8 | FU3: 15 | FV3: 27 | FW3: 15 | FX3: 17 | FY3: 17 | FZ3: 16 | GA3: 11 | GB3: 12 | GC3: 20 | GD3: 0 | GE3: 0 | GF3: 0 | GG3: 0 | GH3: 0 | GI3: 0 | GJ3: 0 | GK3: 25 | GL3: 12 | GM3: 9 | GN3: 13 | GO3: 20 | GP3: 8 | GQ3: 19 | GR3: 16 | GS3: 15 | GT3: 8 | GU3: 7 | GV3: 5 | GW3: 4 | GX3: 14 | GY3: 9 | GZ3: 9 | HA3: 2 | HB3: 12 | HC3: 7 | HD3: 7 | HE3: 19 | HF3: 12 | HG3: 15 | HH3: 12 | HI3: 5 | HJ3: 4 | HK3: 6 | HL3: 15 | HM3: 6 | HN3: 10 | HO3: 6 | HP3: 5 | HQ3: 3 | HR3: 8 | HS3: 11 | HT3: 12 | HU3: 3 | HV3: 3 | HW3: 6 | HX3: 10 | HY3: 1 | HZ3: 7 | IA3: 22 | IB3: 5 | IC3: 8 | ID3: 4 | IE3: 3 | IF3: 3 | IG3: 14 | IH3: 5 | II3: 9 | IJ3: 0 | IK3: 7 | IL3: 13 | IM3: 29 | IN3: 46 | IO3: 22 | IP3: 20 | IQ3: 16 | IR3: 15 | IS3: 17 | IT3: 14 | IU3: 20 | IV3: 13 | IW3: 3 | IX3: 19 | IY3: 11 | IZ3: 2 | JA3: 20 | JB3: 11 | JC3: 15 | JD3: 11 | JE3: 20 | JF3: 7 | JG3: 6 | JH3: 7 | JI3: 14 | JJ3: 14 | JK3: 3 | JL3: 2 | JM3: 10 | JN3: 2 | JO3: 0 | JP3: 14 | JQ3: 11 | JR3: 1 | JS3: 13 | JT3: 20 | JU3: 3 | JV3: 6 | JW3: 6 | JX3: 7 | JY3: 13 | JZ3: 7 | KA3: 4 | KB3: 12 | KC3: 12 | KD3: 4 | KE3: 4 | KF3: 6 | KG3: 5 | KH3: 1 | KI3: 2 | KJ3: 1 | KK3: 0 | KL3: 1 | KM3: 1 | KN3: 0 | KO3: 1 | KP3: 1 | KQ3: 18 | KR3: 28 | KS3: 20 | KT3: 20 | KU3: 10 | KV3: 10 | KW3: 6 | KX3: 10 | KY3: 4 | KZ3: 5 | LA3: 11 | LB3: 4 | LC3: 7 | LD3: 3 | LE3: 11 | LF3: 10 | LG3: 3 | LH3: 4 | LI3: 2 | LJ3: 8 | LK3: 3 | LL3: 4 | LM3: 6 | LN3: 7 | LO3: 3 | LP3: 25 | LQ3: 20 | LR3: 18 | LS3: 9 | LT3: 5 | LU3: 0 | LV3: 3 | LW3: 6 | LX3: 2 | LY3: 1 | LZ3: 2 | MA3: 21 | MB3: 18 | MC3: 10 | MD3: 12 | ME3: 7 | MF3: 3 | MG3: 11 | MH3: 13 | MI3: 14 | MJ3: 13 | MK3: 6 | ML3: 14 | MM3: 8 | MN3: 24 | MO3: 38 | MP3: 28 | MQ3: 20 | MR3: 19 | MS3: 23 | MT3: 31 | MU3: 15 | MV3: 34 | MW3: 14 | MX3: 13 | MY3: 12 | MZ3: 12 | NA3: 17 | NB3: 18 | NC3: 38 | ND3: =SUM(C3:NC3) -> 4350
A4: FOODS_1_018 | B4: CA_1 | C4: 17 | D4: 3 | E4: 8 | F4: 2 | G4: 5 | H4: 0 | I4: 1 | J4: 5 | K4: 12 | L4: 4 | M4: 7 | N4: 9 | O4: 2 | P4: 5 | Q4: 11 | R4: 6 | S4: 3 | T4: 3 | U4: 3 | V4: 2 | W4: 14 | X4: 19 | Y4: 12 | Z4: 8 | AA4: 2 | AB4: 3 | AC4: 3 | AD4: 4 | AE4: 5 | AF4: 2 | AG4: 5 | AH4: 6 | AI4: 5 | AJ4: 0 | AK4: 1 | AL4: 13 | AM4: 2 | AN4: 0 | AO4: 0 | AP4: 2 | AQ4: 0 | AR4: 0 | AS4: 4 | AT4: 3 | AU4: 3 | AV4: 13 | AW4: 19 | AX4: 15 | AY4: 15 | AZ4: 25 | BA4: 18 | BB4: 12 | BC4: 7 | BD4: 1 | BE4: 3 | BF4: 12 | BG4: 8 | BH4: 1 | BI4: 2 | BJ4: 2 | BK4: 1 | BL4: 2 | BM4: 6 | BN4: 6 | BO4: 1 | BP4: 2 | BQ4: 1 | BR4: 2 | BS4: 0 | BT4: 2 | BU4: 2 | BV4: 0 | BW4: 1 | BX4: 0 | BY4: 0 | BZ4: 0 | CA4: 0 | CB4: 0 | CC4: 6 | CD4: 2 | CE4: 4 | CF4: 4 | CG4: 4 | CH4: 4 | CI4: 3 | CJ4: 2 | CK4: 1 | CL4: 2 | CM4: 3 | CN4: 3 | CO4: 8 | CP4: 6 | CQ4: 6 | CR4: 9 | CS4: 8 | CT4: 1 | CU4: 2 | CV4: 7 | CW4: 1 | CX4: 3 | CY4: 3 | CZ4: 1 | DA4: 0 | DB4: 0 | DC4: 9 | DD4: 10 | DE4: 5 | DF4: 8 | DG4: 0 | DH4: 4 | DI4: 7 | DJ4: 6 | DK4: 11 | DL4: 8 | DM4: 5 | DN4: 7 | DO4: 3 | DP4: 5 | DQ4: 1 | DR4: 7 | DS4: 10 | DT4: 7 | DU4: 5 | DV4: 2 | DW4: 3 | DX4: 1 | DY4: 2 | DZ4: 15 | EA4: 3 | EB4: 2 | EC4: 0 | ED4: 0 | EE4: 0 | EF4: 7 | EG4: 3 | EH4: 7 | EI4: 7 | EJ4: 6 | EK4: 4 | EL4: 3 | EM4: 12 | EN4: 8 | EO4: 5 | EP4: 5 | EQ4: 7 | ER4: 9 | ES4: 2 | ET4: 9 | EU4: 12 | EV4: 17 | EW4: 5 | EX4: 11 | EY4: 7 | EZ4: 4 | FA4: 4 | FB4: 9 | FC4: 1 | FD4: 5 | FE4: 3 | FF4: 4 | FG4: 5 | FH4: 3 | FI4: 2 | FJ4: 3 | FK4: 0 | FL4: 9 | FM4: 9 | FN4: 11 | FO4: 8 | FP4: 17 | FQ4: 8 | FR4: 4 | FS4: 14 | FT4: 10 | FU4: 9 | FV4: 22 | FW4: 14 | FX4: 7 | FY4: 2 | FZ4: 3 | GA4: 3 | GB4: 3 | GC4: 13 | GD4: 0 | GE4: 0 | GF4: 0 | GG4: 0 | GH4: 0 | GI4: 0 | GJ4: 0 | GK4: 9 | GL4: 8 | GM4: 3 | GN4: 2 | GO4: 2 | GP4: 19 | GQ4: 23 | GR4: 13 | GS4: 7 | GT4: 3 | GU4: 13 | GV4: 2 | GW4: 9 | GX4: 15 | GY4: 4 | GZ4: 3 | HA4: 8 | HB4: 6 | HC4: 3 | HD4: 8 | HE4: 7 | HF4: 5 | HG4: 16 | HH4: 6 | HI4: 5 | HJ4: 3 | HK4: 13 | HL4: 15 | HM4: 8 | HN4: 10 | HO4: 1 | HP4: 2 | HQ4: 2 | HR4: 4 | HS4: 9 | HT4: 8 | HU4: 8 | HV4: 2 | HW4: 4 | HX4: 1 | HY4: 1 | HZ4: 0 | IA4: 2 | IB4: 2 | IC4: 0 | ID4: 0 | IE4: 0 | IF4: 3 | IG4: 2 | IH4: 2 | II4: 2 | IJ4: 0 | IK4: 0 | IL4: 1 | IM4: 2 | IN4: 1 | IO4: 4 | IP4: 9 | IQ4: 0 | IR4: 2 | IS4: 2 | IT4: 2 | IU4: 3 | IV4: 0 | IW4: 17 | IX4: 7 | IY4: 7 | IZ4: 3 | JA4: 6 | JB4: 3 | JC4: 8 | JD4: 9 | JE4: 24 | JF4: 26 | JG4: 11 | JH4: 20 | JI4: 18 | JJ4: 19 | JK4: 1 | JL4: 2 | JM4: 4 | JN4: 3 | JO4: 0 | JP4: 5 | JQ4: 12 | JR4: 2 | JS4: 1 | JT4: 2 | JU4: 6 | JV4: 8 | JW4: 10 | JX4: 15 | JY4: 9 | JZ4: 5 | KA4: 3 | KB4: 7 | KC4: 17 | KD4: 15 | KE4: 4 | KF4: 9 | KG4: 11 | KH4: 7 | KI4: 6 | KJ4: 9 | KK4: 13 | KL4: 17 | KM4: 9 | KN4: 5 | KO4: 5 | KP4: 6 | KQ4: 26 | KR4: 12 | KS4: 5 | KT4: 6 | KU4: 3 | KV4: 12 | KW4: 8 | KX4: 7 | KY4: 23 | KZ4: 10 | LA4: 7 | LB4: 2 | LC4: 6 | LD4: 3 | LE4: 7 | LF4: 15 | LG4: 5 | LH4: 33 | LI4: 10 | LJ4: 15 | LK4: 6 | LL4: 8 | LM4: 12 | LN4: 18 | LO4: 6 | LP4: 5 | LQ4: 2 | LR4: 8 | LS4: 8 | LT4: 16 | LU4: 0 | LV4: 12 | LW4: 21 | LX4: 23 | LY4: 3 | LZ4: 13 | MA4: 14 | MB4: 9 | MC4: 13 | MD4: 16 | ME4: 8 | MF4: 4 | MG4: 13 | MH4: 10 | MI4: 15 | MJ4: 4 | MK4: 9 | ML4: 9 | MM4: 7 | MN4: 10 | MO4: 8 | MP4: 6 | MQ4: 6 | MR4: 7 | MS4: 6 | MT4: 9 | MU4: 6 | MV4: 6 | MW4: 2 | MX4: 0 | MY4: 2 | MZ4: 4 | NA4: 2 | NB4: 12 | NC4: 9 | ND4: =SUM(C4:NC4) -> 2334

Sheet transformed_sales
A1: item_id | B1: store_id | C1: day_id | D1: unit_sold | E1: date | F1: weekday | G1: month | H1: year | I1: event_name | J1: event_type | K1: snap_CA
A2: FOODS_1_218 | B2: CA_1 | C2: d_1 | D2: 10 | E2: =_xlfn.XLOOKUP(Sheet1[[#This Row],[day_id]],calendar!A2,calendar!B2) -> 40572 | F2: =_xlfn.XLOOKUP(Sheet1[[#This Row],[day_id]],calendar!A2,calendar!C2) -> Saturday | G2: =_xlfn.XLOOKUP(Sheet1[[#This Row],[day_id]],calendar!A2,calendar!E2) -> 1 | H2: =_xlfn.XLOOKUP(Sheet1[[#This Row],[day_id]],calendar!A2,calendar!F2) -> 2011 | I2: =_xlfn.XLOOKUP(Sheet1[[#This Row],[day_id]],calendar!A2,calendar!J2) -> No Event | J2: =_xlfn.XLOOKUP(Sheet1[[#This Row],[day_id]],calendar!A2,calendar!K2) -> No Event Type | K2: =_xlfn.XLOOKUP(Sheet1[[#This Row],[day_id]],calendar!A2,calendar!I2) -> 0
A3: FOODS_1_218 | B3: CA_1 | C3: d_2 | D3: 3 | E3: =_xlfn.XLOOKUP(Sheet1[[#This Row],[day_id]],calendar!A3,calendar!B3) -> 40573 | F3: =_xlfn.XLOOKUP(Sheet1[[#This Row],[day_id]],calendar!A3,calendar!C3) -> Sunday | G3: =_xlfn.XLOOKUP(Sheet1[[#This Row],[day_id]],calendar!A3,calendar!E3) -> 1 | H3: =_xlfn.XLOOKUP(Sheet1[[#This Row],[day_id]],calendar!A3,calendar!F3) -> 2011 | I3: =_xlfn.XLOOKUP(Sheet1[[#This Row],[day_id]],calendar!A3,calendar!J3) -> No Event | J3: =_xlfn.XLOOKUP(Sheet1[[#This Row],[day_id]],calendar!A3,calendar!K3) -> No Event Type | K3: =_xlfn.XLOOKUP(Sheet1[[#This Row],[day_id]],calendar!A3,calendar!I3) -> 0
A4: FOODS_1_218 | B4: CA_1 | C4: d_3 | D4: 4 | E4: =_xlfn.XLOOKUP(Sheet1[[#This Row],[day_id]],calendar!A4,calendar!B4) -> 40574 | F4: =_xlfn.XLOOKUP(Sheet1[[#This Row],[day_id]],calendar!A4,calendar!C4) -> Monday | G4: =_xlfn.XLOOKUP(Sheet1[[#This Row],[day_id]],calendar!A4,calendar!E4) -> 1 | H4: =_xlfn.XLOOKUP(Sheet1[[#This Row],[day_id]],calendar!A4,calendar!F4) -> 2011 | I4: =_xlfn.XLOOKUP(Sheet1[[#This Row],[day_id]],calendar!A4,calendar!J4) -> No Event | J4: =_xlfn.XLOOKUP(Sheet1[[#This Row],[day_id]],calendar!A4,calendar!K4) -> No Event Type | K4: =_xlfn.XLOOKUP(Sheet1[[#This Row],[day_id]],calendar!A4,calendar!I4) -> 0
A5: FOODS_1_218 | B5: CA_1 | C5: d_4 | D5: 0 | E5: =_xlfn.XLOOKUP(Sheet1[[#This Row],[day_id]],calendar!A5,calendar!B5) -> 40575 | F5: =_xlfn.XLOOKUP(Sheet1[[#This Row],[day_id]],calendar!A5,calendar!C5) -> Tuesday | G5: =_xlfn.XLOOKUP(Sheet1[[#This Row],[day_id]],calendar!A5,calendar!E5) -> 2 | H5: =_xlfn.XLOOKUP(Sheet1[[#This Row],[day_id]],calendar!A5,calendar!F5) -> 2011 | I5: =_xlfn.XLOOKUP(Sheet1[[#This Row],[day_id]],calendar!A5,calendar!J5) -> No Event | J5: =_xlfn.XLOOKUP(Sheet1[[#This Row],[day_id]],calendar!A5,calendar!K5) -> No Event Type | K5: =_xlfn.XLOOKUP(Sheet1[[#This Row],[day_id]],calendar!A5,calendar!I5) -> 1
A6: FOODS_1_218 | B6: CA_1 | C6: d_5 | D6: 0 | E6: =_xlfn.XLOOKUP(Sheet1[[#This Row],[day_id]],calendar!A6,calendar!B6) -> 40576 | F6: =_xlfn.XLOOKUP(Sheet1[[#This Row],[day_id]],calendar!A6,calendar!C6) -> Wednesday | G6: =_xlfn.XLOOKUP(Sheet1[[#This Row],[day_id]],calendar!A6,calendar!E6) -> 2 | H6: =_xlfn.XLOOKUP(Sheet1[[#This Row],[day_id]],calendar!A6,calendar!F6) -> 2011 | I6: =_xlfn.XLOOKUP(Sheet1[[#This Row],[day_id]],calendar!A6,calendar!J6) -> No Event | J6: =_xlfn.XLOOKUP(Sheet1[[#This Row],[day_id]],calendar!A6,calendar!K6) -> No Event Type | K6: =_xlfn.XLOOKUP(Sheet1[[#This Row],[day_id]],calendar!A6,calendar!I6) -> 1
A7: FOODS_1_218 | B7: CA_1 | C7: d_6 | D7: 0 | E7: =_xlfn.XLOOKUP(Sheet1[[#This Row],[day_id]],calendar!A7,calendar!B7) -> 40577 | F7: =_xlfn.XLOOKUP(Sheet1[[#This Row],[day_id]],calendar!A7,calendar!C7) -> Thursday | G7: =_xlfn.XLOOKUP(Sheet1[[#This Row],[day_id]],calendar!A7,calendar!E7) -> 2 | H7: =_xlfn.XLOOKUP(Sheet1[[#This Row],[day_id]],calendar!A7,calendar!F7) -> 2011 | I7: =_xlfn.XLOOKUP(Sheet1[[#This Row],[day_id]],calendar!A7,calendar!J7) -> No Event | J7: =_xlfn.XLOOKUP(Sheet1[[#This Row],[day_id]],calendar!A7,calendar!K7) -> No Event Type | K7: =_xlfn.XLOOKUP(Sheet1[[#This Row],[day_id]],calendar!A7,calendar!I7) -> 1
A8: FOODS_1_218 | B8: CA_1 | C8: d_7 | D8: 1 | E8: =_xlfn.XLOOKUP(Sheet1[[#This Row],[day_id]],calendar!A8,calendar!B8) -> 40578 | F8: =_xlfn.XLOOKUP(Sheet1[[#This Row],[day_id]],calendar!A8,calendar!C8) -> Friday | G8: =_xlfn.XLOOKUP(Sheet1[[#This Row],[day_id]],calendar!A8,calendar!E8) -> 2 | H8: =_xlfn.XLOOKUP(Sheet1[[#This Row],[day_id]],calendar!A8,calendar!F8) -> 2011 | I8: =_xlfn.XLOOKUP(Sheet1[[#This Row],[day_id]],calendar!A8,calendar!J8) -> No Event | J8: =_xlfn.XLOOKUP(Sheet1[[#This Row],[day_id]],calendar!A8,calendar!K8) -> No Event Type | K8: =_xlfn.XLOOKUP(Sheet1[[#This Row],[day_id]],calendar!A8,calendar!I8) -> 1
A9: FOODS_1_218 | B9: CA_1 | C9: d_8 | D9: 4 | E9: =_xlfn.XLOOKUP(Sheet1[[#This Row],[day_id]],calendar!A9,calendar!B9) -> 40579 | F9: =_xlfn.XLOOKUP(Sheet1[[#This Row],[day_id]],calendar!A9,calendar!C9) -> Saturday | G9: =_xlfn.XLOOKUP(Sheet1[[#This Row],[day_id]],calendar!A9,calendar!E9) -> 2 | H9: =_xlfn.XLOOKUP(Sheet1[[#This Row],[day_id]],calendar!A9,calendar!F9) -> 2011 | I9: =_xlfn.XLOOKUP(Sheet1[[#This Row],[day_id]],calendar!A9,calendar!J9) -> No Event | J9: =_xlfn.XLOOKUP(Sheet1[[#This Row],[day_id]],calendar!A9,calendar!K9) -> No Event Type | K9: =_xlfn.XLOOKUP(Sheet1[[#This Row],[day_id]],calendar!A9,calendar!I9) -> 1
A10: FOODS_1_218 | B10: CA_1 | C10: d_9 | D10: 2 | E10: =_xlfn.XLOOKUP(Sheet1[[#This Row],[day_id]],calendar!A10,calendar!B10) -> 40580 | F10: =_xlfn.XLOOKUP(Sheet1[[#This Row],[day_id]],calendar!A10,calendar!C10) -> Sunday | G10: =_xlfn.XLOOKUP(Sheet1[[#This Row],[day_id]],calendar!A10,calendar!E10) -> 2 | H10: =_xlfn.XLOOKUP(Sheet1[[#This Row],[day_id]],calendar!A10,calendar!F10) -> 2011 | I10: =_xlfn.XLOOKUP(Sheet1[[#This Row],[day_id]],calendar!A10,calendar!J10) -> SuperBowl | J10: =_xlfn.XLOOKUP(Sheet1[[#This Row],[day_id]],calendar!A10,calendar!K10) -> Sporting | K10: =_xlfn.XLOOKUP(Sheet1[[#This Row],[day_id]],calendar!A10,calendar!I10) -> 1
A11: FOODS_1_218 | B11: CA_1 | C11: d_10 | D11: 0 | E11: =_xlfn.XLOOKUP(Sheet1[[#This Row],[day_id]],calendar!A11,calendar!B11) -> 40581 | F11: =_xlfn.XLOOKUP(Sheet1[[#This Row],[day_id]],calendar!A11,calendar!C11) -> Monday | G11: =_xlfn.XLOOKUP(Sheet1[[#This Row],[day_id]],calendar!A11,calendar!E11) -> 2 | H11: =_xlfn.XLOOKUP(Sheet1[[#This Row],[day_id]],calendar!A11,calendar!F11) -> 2011 | I11: =_xlfn.XLOOKUP(Sheet1[[#This Row],[day_id]],calendar!A11,calendar!J11) -> No Event | J11: =_xlfn.XLOOKUP(Sheet1[[#This Row],[day_id]],calendar!A11,calendar!K11) -> No Event Type | K11: =_xlfn.XLOOKUP(Sheet1[[#This Row],[day_id]],calendar!A11,calendar!I11) -> 1
A12: FOODS_1_218 | B12: CA_1 | C12: d_11 | D12: 0 | E12: =_xlfn.XLOOKUP(Sheet1[[#This Row],[day_id]],calendar!A12,calendar!B12) -> 40582 | F12: =_xlfn.XLOOKUP(Sheet1[[#This Row],[day_id]],calendar!A12,calendar!C12) -> Tuesday | G12: =_xlfn.XLOOKUP(Sheet1[[#This Row],[day_id]],calendar!A12,calendar!E12) -> 2 | H12: =_xlfn.XLOOKUP(Sheet1[[#This Row],[day_id]],calendar!A12,calendar!F12) -> 2011 | I12: =_xlfn.XLOOKUP(Sheet1[[#This Row],[day_id]],calendar!A12,calendar!J12) -> No Event | J12: =_xlfn.XLOOKUP(Sheet1[[#This Row],[day_id]],calendar!A12,calendar!K12) -> No Event Type | K12: =_xlfn.XLOOKUP(Sheet1[[#This Row],[day_id]],calendar!A12,calendar!I12) -> 1
A13: FOODS_1_218 | B13: CA_1 | C13: d_12 | D13: 4 | E13: =_xlfn.XLOOKUP(Sheet1[[#This Row],[day_id]],calendar!A13,calendar!B13) -> 40583 | F13: =_xlfn.XLOOKUP(Sheet1[[#This Row],[day_id]],calendar!A13,calendar!C13) -> Wednesday | G13: =_xlfn.XLOOKUP(Sheet1[[#This Row],[day_id]],calendar!A13,calendar!E13) -> 2 | H13: =_xlfn.XLOOKUP(Sheet1[[#This Row],[day_id]],calendar!A13,calendar!F13) -> 2011 | I13: =_xlfn.XLOOKUP(Sheet1[[#This Row],[day_id]],calendar!A13,calendar!J13) -> No Event | J13: =_xlfn.XLOOKUP(Sheet1[[#This Row],[day_id]],calendar!A13,calendar!K13) -> No Event Type | K13: =_xlfn.XLOOKUP(Sheet1[[#This Row],[day_id]],calendar!A13,calendar!I13) -> 1
... A366: FOODS_1_218 | B366: CA_1 | C366: d_365 | D366: 55 | E366: =_xlfn.XLOOKUP(Sheet1[[#This Row],[day_id]],calendar!A366,calendar!B366) -> 40936 | F366: =_xlfn.XLOOKUP(Sheet1[[#This Row],[day_id]],calendar!A366,calendar!C366) -> Saturday | G366: =_xlfn.XLOOKUP(Sheet1[[#This Row],[day_id]],calendar!A366,calendar!E366) -> 1 | H366: =_xlfn.XLOOKUP(Sheet1[[#This Row],[day_id]],calendar!A366,calendar!F366) -> 2012 | I366: =_xlfn.XLOOKUP(Sheet1[[#This Row],[day_id]],calendar!A366,calendar!J366) -> No Event | J366: =_xlfn.XLOOKUP(Sheet1[[#This Row],[day_id]],calendar!A366,calendar!K366) -> No Event Type | K366: =_xlfn.XLOOKUP(Sheet1[[#This Row],[day_id]],calendar!A366,calendar!I366) -> 0
A367: FOODS_1_085 | B367: CA_1 | C367: d_1 | D367: 10 | E367: =_xlfn.XLOOKUP(Sheet1[[#This Row],[day_id]],calendar!A2,calendar!B2) -> 40572 | F367: =_xlfn.XLOOKUP(Sheet1[[#This Row],[day_id]],calendar!A2,calendar!C2) -> Saturday | G367: =_xlfn.XLOOKUP(Sheet1[[#This Row],[day_id]],calendar!A2,calendar!E2) -> 1 | H367: =_xlfn.XLOOKUP(Sheet1[[#This Row],[day_id]],calendar!A2,calendar!F2) -> 2011 | I367: =_xlfn.XLOOKUP(Sheet1[[#This Row],[day_id]],calendar!A2,calendar!J2) -> No Event | J367: =_xlfn.XLOOKUP(Sheet1[[#This Row],[day_id]],calendar!A2,calendar!K2) -> No Event Type | K367: =_xlfn.XLOOKUP(Sheet1[[#This Row],[day_id]],calendar!A2,calendar!I2) -> 0
A368: FOODS_1_085 | B368: CA_1 | C368: d_2 | D368: 15 | E368: =_xlfn.XLOOKUP(Sheet1[[#This Row],[day_id]],calendar!A3,calendar!B3) -> 40573 | F368: =_xlfn.XLOOKUP(Sheet1[[#This Row],[day_id]],calendar!A3,calendar!C3) -> Sunday | G368: =_xlfn.XLOOKUP(Sheet1[[#This Row],[day_id]],calendar!A3,calendar!E3) -> 1 | H368: =_xlfn.XLOOKUP(Sheet1[[#This Row],[day_id]],calendar!A3,calendar!F3) -> 2011 | I368: =_xlfn.XLOOKUP(Sheet1[[#This Row],[day_id]],calendar!A3,calendar!J3) -> No Event | J368: =_xlfn.XLOOKUP(Sheet1[[#This Row],[day_id]],calendar!A3,calendar!K3) -> No Event Type | K368: =_xlfn.XLOOKUP(Sheet1[[#This Row],[day_id]],calendar!A3,calendar!I3) -> 0
A369: FOODS_1_085 | B369: CA_1 | C369: d_3 | D369: 13 | E369: =_xlfn.XLOOKUP(Sheet1[[#This Row],[day_id]],calendar!A4,calendar!B4) -> 40574 | F369: =_xlfn.XLOOKUP(Sheet1[[#This Row],[day_id]],calendar!A4,calendar!C4) -> Monday | G369: =_xlfn.XLOOKUP(Sheet1[[#This Row],[day_id]],calendar!A4,calendar!E4) -> 1 | H369: =_xlfn.XLOOKUP(Sheet1[[#This Row],[day_id]],calendar!A4,calendar!F4) -> 2011 | I369: =_xlfn.XLOOKUP(Sheet1[[#This Row],[day_id]],calendar!A4,calendar!J4) -> No Event | J369: =_xlfn.XLOOKUP(Sheet1[[#This Row],[day_id]],calendar!A4,calendar!K4) -> No Event Type | K369: =_xlfn.XLOOKUP(Sheet1[[#This Row],[day_id]],calendar!A4,calendar!I4) -> 0
A370: FOODS_1_085 | B370: CA_1 | C370: d_4 | D370: 5 | E370: =_xlfn.XLOOKUP(Sheet1[[#This Row],[day_id]],calendar!A5,calendar!B5) -> 40575 | F370: =_xlfn.XLOOKUP(Sheet1[[#This Row],[day_id]],calendar!A5,calendar!C5) -> Tuesday | G370: =_xlfn.XLOOKUP(Sheet1[[#This Row],[day_id]],calendar!A5,calendar!E5) -> 2 | H370: =_xlfn.XLOOKUP(Sheet1[[#This Row],[day_id]],calendar!A5,calendar!F5) -> 2011 | I370: =_xlfn.XLOOKUP(Sheet1[[#This Row],[day_id]],calendar!A5,calendar!J5) -> No Event | J370: =_xlfn.XLOOKUP(Sheet1[[#This Row],[day_id]],calendar!A5,calendar!K5) -> No Event Type | K370: =_xlfn.XLOOKUP(Sheet1[[#This Row],[day_id]],calendar!A5,calendar!I5) -> 1
A371: FOODS_1_085 | B371: CA_1 | C371: d_5 | D371: 11 | E371: =_xlfn.XLOOKUP(Sheet1[[#This Row],[day_id]],calendar!A6,calendar!B6) -> 40576 | F371: =_xlfn.XLOOKUP(Sheet1[[#This Row],[day_id]],calendar!A6,calendar!C6) -> Wednesday | G371: =_xlfn.XLOOKUP(Sheet1[[#This Row],[day_id]],calendar!A6,calendar!E6) -> 2 | H371: =_xlfn.XLOOKUP(Sheet1[[#This Row],[day_id]],calendar!A6,calendar!F6) -> 2011 | I371: =_xlfn.XLOOKUP(Sheet1[[#This Row],[day_id]],calendar!A6,calendar!J6) -> No Event | J371: =_xlfn.XLOOKUP(Sheet1[[#This Row],[day_id]],calendar!A6,calendar!K6) -> No Event Type | K371: =_xlfn.XLOOKUP(Sheet1[[#This Row],[day_id]],calendar!A6,calendar!I6) -> 1
A372: FOODS_1_085 | B372: CA_1 | C372: d_6 | D372: 5 | E372: =_xlfn.XLOOKUP(Sheet1[[#This Row],[day_id]],calendar!A7,calendar!B7) -> 40577 | F372: =_xlfn.XLOOKUP(Sheet1[[#This Row],[day_id]],calendar!A7,calendar!C7) -> Thursday | G372: =_xlfn.XLOOKUP(Sheet1[[#This Row],[day_id]],calendar!A7,calendar!E7) -> 2 | H372: =_xlfn.XLOOKUP(Sheet1[[#This Row],[day_id]],calendar!A7,calendar!F7) -> 2011 | I372: =_xlfn.XLOOKUP(Sheet1[[#This Row],[day_id]],calendar!A7,calendar!J7) -> No Event | J372: =_xlfn.XLOOKUP(Sheet1[[#This Row],[day_id]],calendar!A7,calendar!K7) -> No Event Type | K372: =_xlfn.XLOOKUP(Sheet1[[#This Row],[day_id]],calendar!A7,calendar!I7) -> 1
A373: FOODS_1_085 | B373: CA_1 | C373: d_7 | D373: 7 | E373: =_xlfn.XLOOKUP(Sheet1[[#This Row],[day_id]],calendar!A8,calendar!B8) -> 40578 | F373: =_xlfn.XLOOKUP(Sheet1[[#This Row],[day_id]],calendar!A8,calendar!C8) -> Friday | G373: =_xlfn.XLOOKUP(Sheet1[[#This Row],[day_id]],calendar!A8,calendar!E8) -> 2 | H373: =_xlfn.XLOOKUP(Sheet1[[#This Row],[day_id]],calendar!A8,calendar!F8) -> 2011 | I373: =_xlfn.XLOOKUP(Sheet1[[#This Row],[day_id]],calendar!A8,calendar!J8) -> No Event | J373: =_xlfn.XLOOKUP(Sheet1[[#This Row],[day_id]],calendar!A8,calendar!K8) -> No Event Type | K373: =_xlfn.XLOOKUP(Sheet1[[#This Row],[day_id]],calendar!A8,calendar!I8) -> 1
A374: FOODS_1_085 | B374: CA_1 | C374: d_8 | D374: 21 | E374: =_xlfn.XLOOKUP(Sheet1[[#This Row],[day_id]],calendar!A9,calendar!B9) -> 40579 | F374: =_xlfn.XLOOKUP(Sheet1[[#This Row],[day_id]],calendar!A9,calendar!C9) -> Saturday | G374: =_xlfn.XLOOKUP(Sheet1[[#This Row],[day_id]],calendar!A9,calendar!E9) -> 2 | H374: =_xlfn.XLOOKUP(Sheet1[[#This Row],[day_id]],calendar!A9,calendar!F9) -> 2011 | I374: =_xlfn.XLOOKUP(Sheet1[[#This Row],[day_id]],calendar!A9,calendar!J9) -> No Event | J374: =_xlfn.XLOOKUP(Sheet1[[#This Row],[day_id]],calendar!A9,calendar!K9) -> No Event Type | K374: =_xlfn.XLOOKUP(Sheet1[[#This Row],[day_id]],calendar!A9,calendar!I9) -> 1
A375: FOODS_1_085 | B375: CA_1 | C375: d_9 | D375: 6 | E375: =_xlfn.XLOOKUP(Sheet1[[#This Row],[day_id]],calendar!A10,calendar!B10) -> 40580 | F375: =_xlfn.XLOOKUP(Sheet1[[#This Row],[day_id]],calendar!A10,calendar!C10) -> Sunday | G375: =_xlfn.XLOOKUP(Sheet1[[#This Row],[day_id]],calendar!A10,calendar!E10) -> 2 | H375: =_xlfn.XLOOKUP(Sheet1[[#This Row],[day_id]],calendar!A10,calendar!F10) -> 2011 | I375: =_xlfn.XLOOKUP(Sheet1[[#This Row],[day_id]],calendar!A10,calendar!J10) -> SuperBowl | J375: =_xlfn.XLOOKUP(Sheet1[[#This Row],[day_id]],calendar!A10,calendar!K10) -> Sporting | K375: =_xlfn.XLOOKUP(Sheet1[[#This Row],[day_id]],calendar!A10,calendar!I10) -> 1
A376: FOODS_1_085 | B376: CA_1 | C376: d_10 | D376: 6 | E376: =_xlfn.XLOOKUP(Sheet1[[#This Row],[day_id]],calendar!A11,calendar!B11) -> 40581 | F376: =_xlfn.XLOOKUP(Sheet1[[#This Row],[day_id]],calendar!A11,calendar!C11) -> Monday | G376: =_xlfn.XLOOKUP(Sheet1[[#This Row],[day_id]],calendar!A11,calendar!E11) -> 2 | H376: =_xlfn.XLOOKUP(Sheet1[[#This Row],[day_id]],calendar!A11,calendar!F11) -> 2011 | I376: =_xlfn.XLOOKUP(Sheet1[[#This Row],[day_id]],calendar!A11,calendar!J11) -> No Event | J376: =_xlfn.XLOOKUP(Sheet1[[#This Row],[day_id]],calendar!A11,calendar!K11) -> No Event Type | K376: =_xlfn.XLOOKUP(Sheet1[[#This Row],[day_id]],calendar!A11,calendar!I11) -> 1
A377: FOODS_1_085 | B377: CA_1 | C377: d_11 | D377: 5 | E377: =_xlfn.XLOOKUP(Sheet1[[#This Row],[day_id]],calendar!A12,calendar!B12) -> 40582 | F377: =_xlfn.XLOOKUP(Sheet1[[#This Row],[day_id]],calendar!A12,calendar!C12) -> Tuesday | G377: =_xlfn.XLOOKUP(Sheet1[[#This Row],[day_id]],calendar!A12,calendar!E12) -> 2 | H377: =_xlfn.XLOOKUP(Sheet1[[#This Row],[day_id]],calendar!A12,calendar!F12) -> 2011 | I377: =_xlfn.XLOOKUP(Sheet1[[#This Row],[day_id]],calendar!A12,calendar!J12) -> No Event | J377: =_xlfn.XLOOKUP(Sheet1[[#This Row],[day_id]],calendar!A12,calendar!K12) -> No Event Type | K377: =_xlfn.XLOOKUP(Sheet1[[#This Row],[day_id]],calendar!A12,calendar!I12) -> 1
A378: FOODS_1_085 | B378: CA_1 | C378: d_12 | D378: 6 | E378: =_xlfn.XLOOKUP(Sheet1[[#This Row],[day_id]],calendar!A13,calendar!B13) -> 40583 | F378: =_xlfn.XLOOKUP(Sheet1[[#This Row],[day_id]],calendar!A13,calendar!C13) -> Wednesday | G378: =_xlfn.XLOOKUP(Sheet1[[#This Row],[day_id]],calendar!A13,calendar!E13) -> 2 | H378: =_xlfn.XLOOKUP(Sheet1[[#This Row],[day_id]],calendar!A13,calendar!F13) -> 2011 | I378: =_xlfn.XLOOKUP(Sheet1[[#This Row],[day_id]],calendar!A13,calendar!J13) -> No Event | J378: =_xlfn.XLOOKUP(Sheet1[[#This Row],[day_id]],calendar!A13,calendar!K13) -> No Event Type | K378: =_xlfn.XLOOKUP(Sheet1[[#This Row],[day_id]],calendar!A13,calendar!I13) -> 1
... A731: FOODS_1_085 | B731: CA_1 | C731: d_365 | D731: 38 | E731: =_xlfn.XLOOKUP(Sheet1[[#This Row],[day_id]],calendar!A366,calendar!B366) -> 40936 | F731: =_xlfn.XLOOKUP(Sheet1[[#This Row],[day_id]],calendar!A366,calendar!C366) -> Saturday | G731: =_xlfn.XLOOKUP(Sheet1[[#This Row],[day_id]],calendar!A366,calendar!E366) -> 1 | H731: =_xlfn.XLOOKUP(Sheet1[[#This Row],[day_id]],calendar!A366,calendar!F366) -> 2012 | I731: =_xlfn.XLOOKUP(Sheet1[[#This Row],[day_id]],calendar!A366,calendar!J366) -> No Event | J731: =_xlfn.XLOOKUP(Sheet1[[#This Row],[day_id]],calendar!A366,calendar!K366) -> No Event Type | K731: =_xlfn.XLOOKUP(Sheet1[[#This Row],[day_id]],calendar!A366,calendar!I366) -> 0
A732: FOODS_1_018 | B732: CA_1 | C732: d_1 | D732: 17 | E732: =_xlfn.XLOOKUP(Sheet1[[#This Row],[day_id]],calendar!A2,calendar!B2) -> 40572 | F732: =_xlfn.XLOOKUP(Sheet1[[#This Row],[day_id]],calendar!A2,calendar!C2) -> Saturday | G732: =_xlfn.XLOOKUP(Sheet1[[#This Row],[day_id]],calendar!A2,calendar!E2) -> 1 | H732: =_xlfn.XLOOKUP(Sheet1[[#This Row],[day_id]],calendar!A2,calendar!F2) -> 2011 | I732: =_xlfn.XLOOKUP(Sheet1[[#This Row],[day_id]],calendar!A2,calendar!J2) -> No Event | J732: =_xlfn.XLOOKUP(Sheet1[[#This Row],[day_id]],calendar!A2,calendar!K2) -> No Event Type | K732: =_xlfn.XLOOKUP(calendar!A2,calendar!A2,calendar!I2) -> 0
A733: FOODS_1_018 | B733: CA_1 | C733: d_2 | D733: 3 | E733: =_xlfn.XLOOKUP(Sheet1[[#This Row],[day_id]],calendar!A3,calendar!B3) -> 40573 | F733: =_xlfn.XLOOKUP(Sheet1[[#This Row],[day_id]],calendar!A3,calendar!C3) -> Sunday | G733: =_xlfn.XLOOKUP(Sheet1[[#This Row],[day_id]],calendar!A3,calendar!E3) -> 1 | H733: =_xlfn.XLOOKUP(Sheet1[[#This Row],[day_id]],calendar!A3,calendar!F3) -> 2011 | I733: =_xlfn.XLOOKUP(Sheet1[[#This Row],[day_id]],calendar!A3,calendar!J3) -> No Event | J733: =_xlfn.XLOOKUP(Sheet1[[#This Row],[day_id]],calendar!A3,calendar!K3) -> No Event Type | K733: =_xlfn.XLOOKUP(calendar!A3,calendar!A3,calendar!I3) -> 0
A734: FOODS_1_018 | B734: CA_1 | C734: d_3 | D734: 8 | E734: =_xlfn.XLOOKUP(Sheet1[[#This Row],[day_id]],calendar!A4,calendar!B4) -> 40574 | F734: =_xlfn.XLOOKUP(Sheet1[[#This Row],[day_id]],calendar!A4,calendar!C4) -> Monday | G734: =_xlfn.XLOOKUP(Sheet1[[#This Row],[day_id]],calendar!A4,calendar!E4) -> 1 | H734: =_xlfn.XLOOKUP(Sheet1[[#This Row],[day_id]],calendar!A4,calendar!F4) -> 2011 | I734: =_xlfn.XLOOKUP(Sheet1[[#This Row],[day_id]],calendar!A4,calendar!J4) -> No Event | J734: =_xlfn.XLOOKUP(Sheet1[[#This Row],[day_id]],calendar!A4,calendar!K4) -> No Event Type | K734: =_xlfn.XLOOKUP(calendar!A4,calendar!A4,calendar!I4) -> 0
A735: FOODS_1_018 | B735: CA_1 | C735: d_4 | D735: 2 | E735: =_xlfn.XLOOKUP(Sheet1[[#This Row],[day_id]],calendar!A5,calendar!B5) -> 40575 | F735: =_xlfn.XLOOKUP(Sheet1[[#This Row],[day_id]],calendar!A5,calendar!C5) -> Tuesday | G735: =_xlfn.XLOOKUP(Sheet1[[#This Row],[day_id]],calendar!A5,calendar!E5) -> 2 | H735: =_xlfn.XLOOKUP(Sheet1[[#This Row],[day_id]],calendar!A5,calendar!F5) -> 2011 | I735: =_xlfn.XLOOKUP(Sheet1[[#This Row],[day_id]],calendar!A5,calendar!J5) -> No Event | J735: =_xlfn.XLOOKUP(Sheet1[[#This Row],[day_id]],calendar!A5,calendar!K5) -> No Event Type | K735: =_xlfn.XLOOKUP(calendar!A5,calendar!A5,calendar!I5) -> 1
A736: FOODS_1_018 | B736: CA_1 | C736: d_5 | D736: 5 | E736: =_xlfn.XLOOKUP(Sheet1[[#This Row],[day_id]],calendar!A6,calendar!B6) -> 40576 | F736: =_xlfn.XLOOKUP(Sheet1[[#This Row],[day_id]],calendar!A6,calendar!C6) -> Wednesday | G736: =_xlfn.XLOOKUP(Sheet1[[#This Row],[day_id]],calendar!A6,calendar!E6) -> 2 | H736: =_xlfn.XLOOKUP(Sheet1[[#This Row],[day_id]],calendar!A6,calendar!F6) -> 2011 | I736: =_xlfn.XLOOKUP(Sheet1[[#This Row],[day_id]],calendar!A6,calendar!J6) -> No Event | J736: =_xlfn.XLOOKUP(Sheet1[[#This Row],[day_id]],calendar!A6,calendar!K6) -> No Event Type | K736: =_xlfn.XLOOKUP(calendar!A6,calendar!A6,calendar!I6) -> 1
A737: FOODS_1_018 | B737: CA_1 | C737: d_6 | D737: 0 | E737: =_xlfn.XLOOKUP(Sheet1[[#This Row],[day_id]],calendar!A7,calendar!B7) -> 40577 | F737: =_xlfn.XLOOKUP(Sheet1[[#This Row],[day_id]],calendar!A7,calendar!C7) -> Thursday | G737: =_xlfn.XLOOKUP(Sheet1[[#This Row],[day_id]],calendar!A7,calendar!E7) -> 2 | H737: =_xlfn.XLOOKUP(Sheet1[[#This Row],[day_id]],calendar!A7,calendar!F7) -> 2011 | I737: =_xlfn.XLOOKUP(Sheet1[[#This Row],[day_id]],calendar!A7,calendar!J7) -> No Event | J737: =_xlfn.XLOOKUP(Sheet1[[#This Row],[day_id]],calendar!A7,calendar!K7) -> No Event Type | K737: =_xlfn.XLOOKUP(calendar!A7,calendar!A7,calendar!I7) -> 1
A738: FOODS_1_018 | B738: CA_1 | C738: d_7 | D738: 1 | E738: =_xlfn.XLOOKUP(Sheet1[[#This Row],[day_id]],calendar!A8,calendar!B8) -> 40578 | F738: =_xlfn.XLOOKUP(Sheet1[[#This Row],[day_id]],calendar!A8,calendar!C8) -> Friday | G738: =_xlfn.XLOOKUP(Sheet1[[#This Row],[day_id]],calendar!A8,calendar!E8) -> 2 | H738: =_xlfn.XLOOKUP(Sheet1[[#This Row],[day_id]],calendar!A8,calendar!F8) -> 2011 | I738: =_xlfn.XLOOKUP(Sheet1[[#This Row],[day_id]],calendar!A8,calendar!J8) -> No Event | J738: =_xlfn.XLOOKUP(Sheet1[[#This Row],[day_id]],calendar!A8,calendar!K8) -> No Event Type | K738: =_xlfn.XLOOKUP(calendar!A8,calendar!A8,calendar!I8) -> 1
A739: FOODS_1_018 | B739: CA_1 | C739: d_8 | D739: 5 | E739: =_xlfn.XLOOKUP(Sheet1[[#This Row],[day_id]],calendar!A9,calendar!B9) -> 40579 | F739: =_xlfn.XLOOKUP(Sheet1[[#This Row],[day_id]],calendar!A9,calendar!C9) -> Saturday | G739: =_xlfn.XLOOKUP(Sheet1[[#This Row],[day_id]],calendar!A9,calendar!E9) -> 2 | H739: =_xlfn.XLOOKUP(Sheet1[[#This Row],[day_id]],calendar!A9,calendar!F9) -> 2011 | I739: =_xlfn.XLOOKUP(Sheet1[[#This Row],[day_id]],calendar!A9,calendar!J9) -> No Event | J739: =_xlfn.XLOOKUP(Sheet1[[#This Row],[day_id]],calendar!A9,calendar!K9) -> No Event Type | K739: =_xlfn.XLOOKUP(calendar!A9,calendar!A9,calendar!I9) -> 1
A740: FOODS_1_018 | B740: CA_1 | C740: d_9 | D740: 12 | E740: =_xlfn.XLOOKUP(Sheet1[[#This Row],[day_id]],calendar!A10,calendar!B10) -> 40580 | F740: =_xlfn.XLOOKUP(Sheet1[[#This Row],[day_id]],calendar!A10,calendar!C10) -> Sunday | G740: =_xlfn.XLOOKUP(Sheet1[[#This Row],[day_id]],calendar!A10,calendar!E10) -> 2 | H740: =_xlfn.XLOOKUP(Sheet1[[#This Row],[day_id]],calendar!A10,calendar!F10) -> 2011 | I740: =_xlfn.XLOOKUP(Sheet1[[#This Row],[day_id]],calendar!A10,calendar!J10) -> SuperBowl | J740: =_xlfn.XLOOKUP(Sheet1[[#This Row],[day_id]],calendar!A10,calendar!K10) -> Sporting | K740: =_xlfn.XLOOKUP(calendar!A10,calendar!A10,calendar!I10) -> 1
A741: FOODS_1_018 | B741: CA_1 | C741: d_10 | D741: 4 | E741: =_xlfn.XLOOKUP(Sheet1[[#This Row],[day_id]],calendar!A11,calendar!B11) -> 40581 | F741: =_xlfn.XLOOKUP(Sheet1[[#This Row],[day_id]],calendar!A11,calendar!C11) -> Monday | G741: =_xlfn.XLOOKUP(Sheet1[[#This Row],[day_id]],calendar!A11,calendar!E11) -> 2 | H741: =_xlfn.XLOOKUP(Sheet1[[#This Row],[day_id]],calendar!A11,calendar!F11) -> 2011 | I741: =_xlfn.XLOOKUP(Sheet1[[#This Row],[day_id]],calendar!A11,calendar!J11) -> No Event | J741: =_xlfn.XLOOKUP(Sheet1[[#This Row],[day_id]],calendar!A11,calendar!K11) -> No Event Type | K741: =_xlfn.XLOOKUP(calendar!A11,calendar!A11,calendar!I11) -> 1
A742: FOODS_1_018 | B742: CA_1 | C742: d_11 | D742: 7 | E742: =_xlfn.XLOOKUP(Sheet1[[#This Row],[day_id]],calendar!A12,calendar!B12) -> 40582 | F742: =_xlfn.XLOOKUP(Sheet1[[#This Row],[day_id]],calendar!A12,calendar!C12) -> Tuesday | G742: =_xlfn.XLOOKUP(Sheet1[[#This Row],[day_id]],calendar!A12,calendar!E12) -> 2 | H742: =_xlfn.XLOOKUP(Sheet1[[#This Row],[day_id]],calendar!A12,calendar!F12) -> 2011 | I742: =_xlfn.XLOOKUP(Sheet1[[#This Row],[day_id]],calendar!A12,calendar!J12) -> No Event | J742: =_xlfn.XLOOKUP(Sheet1[[#This Row],[day_id]],calendar!A12,calendar!K12) -> No Event Type | K742: =_xlfn.XLOOKUP(calendar!A12,calendar!A12,calendar!I12) -> 1
A743: FOODS_1_018 | B743: CA_1 | C743: d_12 | D743: 9 | E743: =_xlfn.XLOOKUP(Sheet1[[#This Row],[day_id]],calendar!A13,calendar!B13) -> 40583 | F743: =_xlfn.XLOOKUP(Sheet1[[#This Row],[day_id]],calendar!A13,calendar!C13) -> Wednesday | G743: =_xlfn.XLOOKUP(Sheet1[[#This Row],[day_id]],calendar!A13,calendar!E13) -> 2 | H743: =_xlfn.XLOOKUP(Sheet1[[#This Row],[day_id]],calendar!A13,calendar!F13) -> 2011 | I743: =_xlfn.XLOOKUP(Sheet1[[#This Row],[day_id]],calendar!A13,calendar!J13) -> No Event | J743: =_xlfn.XLOOKUP(Sheet1[[#This Row],[day_id]],calendar!A13,calendar!K13) -> No Event Type | K743: =_xlfn.XLOOKUP(calendar!A13,calendar!A13,calendar!I13) -> 1
... A1096: FOODS_1_018 | B1096: CA_1 | C1096: d_365 | D1096: 9 | E1096: =_xlfn.XLOOKUP(Sheet1[[#This Row],[day_id]],calendar!A366,calendar!B366) -> 40936 | F1096: =_xlfn.XLOOKUP(Sheet1[[#This Row],[day_id]],calendar!A366,calendar!C366) -> Saturday | G1096: =_xlfn.XLOOKUP(Sheet1[[#This Row],[day_id]],calendar!A366,calendar!E366) -> 1 | H1096: =_xlfn.XLOOKUP(Sheet1[[#This Row],[day_id]],calendar!A366,calendar!F366) -> 2012 | I1096: =_xlfn.XLOOKUP(Sheet1[[#This Row],[day_id]],calendar!A366,calendar!J366) -> No Event | J1096: =_xlfn.XLOOKUP(Sheet1[[#This Row],[day_id]],calendar!A366,calendar!K366) -> No Event Type | K1096: =_xlfn.XLOOKUP(calendar!A366,calendar!A366,calendar!I366) -> 0

Sheet calendar
A1: d | B1: date | C1: weekday | D1: wday | E1: month | F1: year | G1: event_name_1 | H1: event_type_1 | I1: snap_CA | J1: event_name_cleaned | K1: event_type_cleaned
A2: d_1 | B2: 40572 | C2: Saturday | D2: 1 | E2: 1 | F2: 2011 | I2: 0 | J2: =IF(G2="", "No Event",G2) -> No Event | K2: =IF(H2="", "No Event Type",H2) -> No Event Type
A3: d_2 | B3: 40573 | C3: Sunday | D3: 2 | E3: 1 | F3: 2011 | I3: 0 | J3: =IF(G3="", "No Event",G3) -> No Event | K3: =IF(H3="", "No Event Type",H3) -> No Event Type
A4: d_3 | B4: 40574 | C4: Monday | D4: 3 | E4: 1 | F4: 2011 | I4: 0 | J4: =IF(G4="", "No Event",G4) -> No Event | K4: =IF(H4="", "No Event Type",H4) -> No Event Type
A5: d_4 | B5: 40575 | C5: Tuesday | D5: 4 | E5: 2 | F5: 2011 | I5: 1 | J5: =IF(G5="", "No Event",G5) -> No Event | K5: =IF(H5="", "No Event Type",H5) -> No Event Type
A6: d_5 | B6: 40576 | C6: Wednesday | D6: 5 | E6: 2 | F6: 2011 | I6: 1 | J6: =IF(G6="", "No Event",G6) -> No Event | K6: =IF(H6="", "No Event Type",H6) -> No Event Type
A7: d_6 | B7: 40577 | C7: Thursday | D7: 6 | E7: 2 | F7: 2011 | I7: 1 | J7: =IF(G7="", "No Event",G7) -> No Event | K7: =IF(H7="", "No Event Type",H7) -> No Event Type
A8: d_7 | B8: 40578 | C8: Friday | D8: 7 | E8: 2 | F8: 2011 | I8: 1 | J8: =IF(G8="", "No Event",G8) -> No Event | K8: =IF(H8="", "No Event Type",H8) -> No Event Type
A9: d_8 | B9: 40579 | C9: Saturday | D9: 1 | E9: 2 | F9: 2011 | I9: 1 | J9: =IF(G9="", "No Event",G9) -> No Event | K9: =IF(H9="", "No Event Type",H9) -> No Event Type
A10: d_9 | B10: 40580 | C10: Sunday | D10: 2 | E10: 2 | F10: 2011 | G10: SuperBowl | H10: Sporting | I10: 1 | J10: =IF(G10="", "No Event",G10) -> SuperBowl | K10: =IF(H10="", "No Event Type",H10) -> Sporting
A11: d_10 | B11: 40581 | C11: Monday | D11: 3 | E11: 2 | F11: 2011 | I11: 1 | J11: =IF(G11="", "No Event",G11) -> No Event | K11: =IF(H11="", "No Event Type",H11) -> No Event Type
A12: d_11 | B12: 40582 | C12: Tuesday | D12: 4 | E12: 2 | F12: 2011 | I12: 1 | J12: =IF(G12="", "No Event",G12) -> No Event | K12: =IF(H12="", "No Event Type",H12) -> No Event Type
A13: d_12 | B13: 40583 | C13: Wednesday | D13: 5 | E13: 2 | F13: 2011 | I13: 1 | J13: =IF(G13="", "No Event",G13) -> No Event | K13: =IF(H13="", "No Event Type",H13) -> No Event Type
A14: d_13 | B14: 40584 | C14: Thursday | D14: 6 | E14: 2 | F14: 2011 | I14: 1 | J14: =IF(G14="", "No Event",G14) -> No Event | K14: =IF(H14="", "No Event Type",H14) -> No Event Type
A15: d_14 | B15: 40585 | C15: Friday | D15: 7 | E15: 2 | F15: 2011 | I15: 0 | J15: =IF(G15="", "No Event",G15) -> No Event | K15: =IF(H15="", "No Event Type",H15) -> No Event Type
A16: d_15 | B16: 40586 | C16: Saturday | D16: 1 | E16: 2 | F16: 2011 | I16: 0 | J16: =IF(G16="", "No Event",G16) -> No Event | K16: =IF(H16="", "No Event Type",H16) -> No Event Type
A17: d_16 | B17: 40587 | C17: Sunday | D17: 2 | E17: 2 | F17: 2011 | I17: 0 | J17: =IF(G17="", "No Event",G17) -> No Event | K17: =IF(H17="", "No Event Type",H17) -> No Event Type
A18: d_17 | B18: 40588 | C18: Monday | D18: 3 | E18: 2 | F18: 2011 | G18: ValentinesDay | H18: Cultural | I18: 0 | J18: =IF(G18="", "No Event",G18) -> ValentinesDay | K18: =IF(H18="", "No Event Type",H18) -> Cultural
A19: d_18 | B19: 40589 | C19: Tuesday | D19: 4 | E19: 2 | F19: 2011 | I19: 0 | J19: =IF(G19="", "No Event",G19) -> No Event | K19: =IF(H19="", "No Event Type",H19) -> No Event Type
A20: d_19 | B20: 40590 | C20: Wednesday | D20: 5 | E20: 2 | F20: 2011 | I20: 0 | J20: =IF(G20="", "No Event",G20) -> No Event | K20: =IF(H20="", "No Event Type",H20) -> No Event Type
A21: d_20 | B21: 40591 | C21: Thursday | D21: 6 | E21: 2 | F21: 2011 | I21: 0 | J21: =IF(G21="", "No Event",G21) -> No Event | K21: =IF(H21="", "No Event Type",H21) -> No Event Type
A22: d_21 | B22: 40592 | C22: Friday | D22: 7 | E22: 2 | F22: 2011 | I22: 0 | J22: =IF(G22="", "No Event",G22) -> No Event | K22: =IF(H22="", "No Event Type",H22) -> No Event Type
A23: d_22 | B23: 40593 | C23: Saturday | D23: 1 | E23: 2 | F23: 2011 | I23: 0 | J23: =IF(G23="", "No Event",G23) -> No Event | K23: =IF(H23="", "No Event Type",H23) -> No Event Type
A24: d_23 | B24: 40594 | C24: Sunday | D24: 2 | E24: 2 | F24: 2011 | I24: 0 | J24: =IF(G24="", "No Event",G24) -> No Event | K24: =IF(H24="", "No Event Type",H24) -> No Event Type
A25: d_24 | B25: 40595 | C25: Monday | D25: 3 | E25: 2 | F25: 2011 | G25: PresidentsDay | H25: National | I25: 0 | J25: =IF(G25="", "No Event",G25) -> PresidentsDay | K25: =IF(H25="", "No Event Type",H25) -> National
A26: d_25 | B26: 40596 | C26: Tuesday | D26: 4 | E26: 2 | F26: 2011 | I26: 0 | J26: =IF(G26="", "No Event",G26) -> No Event | K26: =IF(H26="", "No Event Type",H26) -> No Event Type
A27: d_26 | B27: 40597 | C27: Wednesday | D27: 5 | E27: 2 | F27: 2011 | I27: 0 | J27: =IF(G27="", "No Event",G27) -> No Event | K27: =IF(H27="", "No Event Type",H27) -> No Event Type
A28: d_27 | B28: 40598 | C28: Thursday | D28: 6 | E28: 2 | F28: 2011 | I28: 0 | J28: =IF(G28="", "No Event",G28) -> No Event | K28: =IF(H28="", "No Event Type",H28) -> No Event Type
A29: d_28 | B29: 40599 | C29: Friday | D29: 7 | E29: 2 | F29: 2011 | I29: 0 | J29: =IF(G29="", "No Event",G29) -> No Event | K29: =IF(H29="", "No Event Type",H29) -> No Event Type
A30: d_29 | B30: 40600 | C30: Saturday | D30: 1 | E30: 2 | F30: 2011 | I30: 0 | J30: =IF(G30="", "No Event",G30) -> No Event | K30: =IF(H30="", "No Event Type",H30) -> No Event Type
A31: d_30 | B31: 40601 | C31: Sunday | D31: 2 | E31: 2 | F31: 2011 | I31: 0 | J31: =IF(G31="", "No Event",G31) -> No Event | K31: =IF(H31="", "No Event Type",H31) -> No Event Type
A32: d_31 | B32: 40602 | C32: Monday | D32: 3 | E32: 2 | F32: 2011 | I32: 0 | J32: =IF(G32="", "No Event",G32) -> No Event | K32: =IF(H32="", "No Event Type",H32) -> No Event Type
A33: d_32 | B33: 40603 | C33: Tuesday | D33: 4 | E33: 3 | F33: 2011 | I33: 1 | J33: =IF(G33="", "No Event",G33) -> No Event | K33: =IF(H33="", "No Event Type",H33) -> No Event Type
A34: d_33 | B34: 40604 | C34: Wednesday | D34: 5 | E34: 3 | F34: 2011 | I34: 1 | J34: =IF(G34="", "No Event",G34) -> No Event | K34: =IF(H34="", "No Event Type",H34) -> No Event Type
A35: d_34 | B35: 40605 | C35: Thursday | D35: 6 | E35: 3 | F35: 2011 | I35: 1 | J35: =IF(G35="", "No Event",G35) -> No Event | K35: =IF(H35="", "No Event Type",H35) -> No Event Type
A36: d_35 | B36: 40606 | C36: Friday | D36: 7 | E36: 3 | F36: 2011 | I36: 1 | J36: =IF(G36="", "No Event",G36) -> No Event | K36: =IF(H36="", "No Event Type",H36) -> No Event Type
A37: d_36 | B37: 40607 | C37: Saturday | D37: 1 | E37: 3 | F37: 2011 | I37: 1 | J37: =IF(G37="", "No Event",G37) -> No Event | K37: =IF(H37="", "No Event Type",H37) -> No Event Type
... A40: d_39 | B40: 40610 | C40: Tuesday | D40: 4 | E40: 3 | F40: 2011 | I40: 1 | J40: =IF(G40="", "No Event",G40) -> No Event | K40: =IF(H40="", "No Event Type",H40) -> No Event Type
A41: d_40 | B41: 40611 | C41: Wednesday | D41: 5 | E41: 3 | F41: 2011 | G41: LentStart | H41: Religious | I41: 1 | J41: =IF(G41="", "No Event",G41) -> LentStart | K41: =IF(H41="", "No Event Type",H41) -> Religious
A42: d_41 | B42: 40612 | C42: Thursday | D42: 6 | E42: 3 | F42: 2011 | I42: 1 | J42: =IF(G42="", "No Event",G42) -> No Event | K42: =IF(H42="", "No Event Type",H42) -> No Event Type
...

Sheet data_quality
A2: 1. Are there any negative sales value? (sales values are never negative.)
A3: =COUNTIF(Sheet1[unit_sold],"<0") -> 0
A5: 2. How many zero-sales days exist per SKU?
A6: Sku | B6: zero sales days
A7: {=_xlfn.UNIQUE(Sheet1[item_id])} -> FOODS_1_218 | B7: =COUNTIFS(Sheet1[item_id],transformed_sales!A2,Sheet1[unit_sold],"=0") -> 88 | C7: =AVERAGEIF(Sheet1[item_id],transformed_sales!A2,Sheet1[unit_sold]) -> 8.8054795
A8: FOODS_1_085 | B8: =COUNTIFS(Sheet1[item_id],transformed_sales!A403,Sheet1[unit_sold],"=0") -> 17
A9: FOODS_1_018 | B9: =COUNTIFS(Sheet1[item_id],transformed_sales!A1071,Sheet1[unit_sold],"=0") -> 38
A10: Total | B10: =SUM(B7:B9) -> 143
A13: What is the min, max, average, and standard deviation of daily sales per SKU?
A15: SKU | B15: min | C15: max | D15: average | E15: sd
A16: {=_xlfn.UNIQUE(Sheet1[item_id])} -> FOODS_1_218 | B16: =_xlfn.MINIFS(Sheet1[unit_sold],Sheet1[item_id],transformed_sales!A2) -> 0 | C16: =_xlfn.MAXIFS(Sheet1[unit_sold],Sheet1[item_id],transformed_sales!A2) -> 68 | D16: =AVERAGEIF(Sheet1[item_id],transformed_sales!A2,Sheet1[unit_sold]) -> 8.8054795 | E16: {=_xlfn.STDEV.S(_xlfn._xlws.FILTER(Sheet1[unit_sold],Sheet1[item_id]=transformed_sales!A2))} -> 10.392726
A17: FOODS_1_085 | B17: =_xlfn.MINIFS(Sheet1[unit_sold],Sheet1[item_id],transformed_sales!A369) -> 0 | C17: =_xlfn.MAXIFS(Sheet1[unit_sold],Sheet1[item_id],transformed_sales!A417) -> 46 | E17: =calendar!A1 -> d
A18: FOODS_1_018 | B18: =_xlfn.MINIFS(Sheet1[unit_sold],Sheet1[item_id],transformed_sales!A1087) -> 0 | C18: =_xlfn.MAXIFS(Sheet1[unit_sold],Sheet1[item_id],transformed_sales!A1093) -> 33
