Workbook

Sheet RawData
A1: d | B1: date | C1: wm_yr_wk | D1: weekday | E1: wday | F1: month | G1: year | H1: event_name_1 | I1: event_type_1 | J1: event_name_2 | K1: event_type_2 | L1: snap_CA | M1: SKU1_Sales | N1: SKU2_Sales | O1: SKU3_Sales
A2: d_1 | B2: 40572 | C2: 11101 | D2: Saturday | E2: 1 | F2: 1 | G2: 2011 | L2: 0 | M2: 3 | N2: 0 | O2: 0
A3: d_2 | B3: 40573 | C3: 11101 | D3: Sunday | E3: 2 | F3: 1 | G3: 2011 | L3: 0 | M3: 0 | N3: 1 | O3: 0
A4: d_3 | B4: 40574 | C4: 11101 | D4: Monday | E4: 3 | F4: 1 | G4: 2011 | L4: 0 | M4: 0 | N4: 0 | O4: 0
A5: d_4 | B5: 40575 | C5: 11101 | D5: Tuesday | E5: 4 | F5: 2 | G5: 2011 | L5: 1 | M5: 1 | N5: 1 | O5: 0
A6: d_5 | B6: 40576 | C6: 11101 | D6: Wednesday | E6: 5 | F6: 2 | G6: 2011 | L6: 1 | M6: 4 | N6: 1 | O6: 1
A7: d_6 | B7: 40577 | C7: 11101 | D7: Thursday | E7: 6 | F7: 2 | G7: 2011 | L7: 1 | M7: 2 | N7: 1 | O7: 3
A8: d_7 | B8: 40578 | C8: 11101 | D8: Friday | E8: 7 | F8: 2 | G8: 2011 | L8: 1 | M8: 0 | N8: 0 | O8: 1
A9: d_8 | B9: 40579 | C9: 11102 | D9: Saturday | E9: 1 | F9: 2 | G9: 2011 | L9: 1 | M9: 2 | N9: 0 | O9: 1
A10: d_9 | B10: 40580 | C10: 11102 | D10: Sunday | E10: 2 | F10: 2 | G10: 2011 | H10: SuperBowl | I10: Sporting | L10: 1 | M10: 0 | N10: 0 | O10: 1
A11: d_10 | B11: 40581 | C11: 11102 | D11: Monday | E11: 3 | F11: 2 | G11: 2011 | L11: 1 | M11: 0 | N11: 0 | O11: 0
A12: d_11 | B12: 40582 | C12: 11102 | D12: Tuesday | E12: 4 | F12: 2 | G12: 2011 | L12: 1 | M12: 0 | N12: 1 | O12: 1
A13: d_12 | B13: 40583 | C13: 11102 | D13: Wednesday | E13: 5 | F13: 2 | G13: 2011 | L13: 1 | M13: 0 | N13: 1 | O13: 0
A14: d_13 | B14: 40584 | C14: 11102 | D14: Thursday | E14: 6 | F14: 2 | G14: 2011 | L14: 1 | M14: 3 | N14: 0 | O14: 0
A15: d_14 | B15: 40585 | C15: 11102 | D15: Friday | E15: 7 | F15: 2 | G15: 2011 | L15: 0 | M15: 1 | N15: 2 | O15: 2
A16: d_15 | B16: 40586 | C16: 11103 | D16: Saturday | E16: 1 | F16: 2 | G16: 2011 | L16: 0 | M16: 3 | N16: 0 | O16: 1
A17: d_16 | B17: 40587 | C17: 11103 | D17: Sunday | E17: 2 | F17: 2 | G17: 2011 | L17: 0 | M17: 0 | N17: 1 | O17: 1
A18: d_17 | B18: 40588 | C18: 11103 | D18: Monday | E18: 3 | F18: 2 | G18: 2011 | H18: ValentinesDay | I18: Cultural | L18: 0 | M18: 2 | N18: 0 | O18: 1
A19: d_18 | B19: 40589 | C19: 11103 | D19: Tuesday | E19: 4 | F19: 2 | G19: 2011 | L19: 0 | M19: 1 | N19: 0 | O19: 0
A20: d_19 | B20: 40590 | C20: 11103 | D20: Wednesday | E20: 5 | F20: 2 | G20: 2011 | L20: 0 | M20: 2 | N20: 0 | O20: 0
A21: d_20 | B21: 40591 | C21: 11103 | D21: Thursday | E21: 6 | F21: 2 | G21: 2011 | L21: 0 | M21: 0 | N21: 0 | O21: 1
A22: d_21 | B22: 40592 | C22: 11103 | D22: Friday | E22: 7 | F22: 2 | G22: 2011 | L22: 0 | M22: 2 | N22: 0 | O22: 0
A23: d_22 | B23: 40593 | C23: 11104 | D23: Saturday | E23: 1 | F23: 2 | G23: 2011 | L23: 0 | M23: 1 | N23: 0 | O23: 2
A24: d_23 | B24: 40594 | C24: 11104 | D24: Sunday | E24: 2 | F24: 2 | G24: 2011 | L24: 0 | M24: 2 | N24: 0 | O24: 4
A25: d_24 | B25: 40595 | C25: 11104 | D25: Monday | E25: 3 | F25: 2 | G25: 2011 | H25: PresidentsDay | I25: National | L25: 0 | M25: 0 | N25: 0 | O25: 1
A26: d_25 | B26: 40596 | C26: 11104 | D26: Tuesday | E26: 4 | F26: 2 | G26: 2011 | L26: 0 | M26: 2 | N26: 0 | O26: 1
A27: d_26 | B27: 40597 | C27: 11104 | D27: Wednesday | E27: 5 | F27: 2 | G27: 2011 | L27: 0 | M27: 2 | N27: 0 | O27: 2
A28: d_27 | B28: 40598 | C28: 11104 | D28: Thursday | E28: 6 | F28: 2 | G28: 2011 | L28: 0 | M28: 2 | N28: 0 | O28: 1
A29: d_28 | B29: 40599 | C29: 11104 | D29: Friday | E29: 7 | F29: 2 | G29: 2011 | L29: 0 | M29: 4 | N29: 0 | O29: 0
A30: d_29 | B30: 40600 | C30: 11105 | D30: Saturday | E30: 1 | F30: 2 | G30: 2011 | L30: 0 | M30: 2 | N30: 1 | O30: 1
A31: d_30 | B31: 40601 | C31: 11105 | D31: Sunday | E31: 2 | F31: 2 | G31: 2011 | L31: 0 | M31: 2 | N31: 0 | O31: 0
A32: d_31 | B32: 40602 | C32: 11105 | D32: Monday | E32: 3 | F32: 2 | G32: 2011 | L32: 0 | M32: 0 | N32: 0 | O32: 1
A33: d_32 | B33: 40603 | C33: 11105 | D33: Tuesday | E33: 4 | F33: 3 | G33: 2011 | L33: 1 | M33: 2 | N33: 1 | O33: 0
A34: d_33 | B34: 40604 | C34: 11105 | D34: Wednesday | E34: 5 | F34: 3 | G34: 2011 | L34: 1 | M34: 1 | N34: 1 | O34: 1
A35: d_34 | B35: 40605 | C35: 11105 | D35: Thursday | E35: 6 | F35: 3 | G35: 2011 | L35: 1 | M35: 7 | N35: 0 | O35: 1
A36: d_35 | B36: 40606 | C36: 11105 | D36: Friday | E36: 7 | F36: 3 | G36: 2011 | L36: 1 | M36: 1 | N36: 1 | O36: 2
A37: d_36 | B37: 40607 | C37: 11106 | D37: Saturday | E37: 1 | F37: 3 | G37: 2011 | L37: 1 | M37: 2 | N37: 1 | O37: 3
... A40: d_39 | B40: 40610 | C40: 11106 | D40: Tuesday | E40: 4 | F40: 3 | G40: 2011 | L40: 1 | M40: 1 | N40: 0 | O40: 0
A41: d_40 | B41: 40611 | C41: 11106 | D41: Wednesday | E41: 5 | F41: 3 | G41: 2011 | H41: LentStart | I41: Religious | L41: 1 | M41: 2 | N41: 0 | O41: 0
A42: d_41 | B42: 40612 | C42: 11106 | D42: Thursday | E42: 6 | F42: 3 | G42: 2011 | L42: 1 | M42: 3 | N42: 0 | O42: 2
...

Sheet SummaryStats
A1: Labels | B1: Food_1_001 | C1: Food_1_002 | D1: Food_1_003
A2: Total Days | B2: =COUNTA(RawData!M2:M366) -> 365 | C2: =COUNTA(RawData!N2:N366) -> 365 | D2: =COUNTA(RawData!O2:O3660) -> 365
A3: Total Units Sold | B3: =SUM(RawData!M2:M366) -> 328 | C3: =SUM(RawData!N2:N366) -> 292 | D3: =SUM(RawData!O2:O366) -> 319
A4: Average Daily Sales | B4: =AVERAGE(RawData!M2:M366) -> 0.89863014 | C4: =AVERAGE(RawData!N2:N366) -> 0.8 | D4: =AVERAGE(RawData!O2:O366) -> 0.8739726
A5: Median Daily Sales | B5: =MEDIAN(RawData!M2:M366) -> 0 | C5: =MEDIAN(RawData!N2:N366) -> 0 | D5: =MEDIAN(RawData!O2:O366) -> 0
A6: Std Dev | B6: =STDEV(RawData!M2:M366) -> 1.4056883 | C6: =STDEV(RawData!N2:N366) -> 1.0114727 | D6: =STDEV(RawData!O2:O366) -> 1.2137069
A7: CV | B7: =B6/B4 -> 1.5642568 | C7: =C6/C4 -> 1.2643408 | D7: =D6/D4 -> 1.3887242
A8: Minimum | B8: =MIN(RawData!M2:M366) -> 0 | C8: =MIN(RawData!N2:N366) -> 0 | D8: =MIN(RawData!O2:O366) -> 0
A9: Maximum | B9: =MAX(RawData!M2:M366) -> 9 | C9: =MAX(RawData!N2:N366) -> 5 | D9: =MAX(RawData!O2:O366) -> 8
A10: Zero Sales Days | B10: =COUNTIF(RawData!M2:M366,0) -> 203 | C10: =COUNTIF(RawData!N2:N366,0) -> 185 | D10: =COUNTIF(RawData!O2:O366,0) -> 187
A11: Zero Sales Rate | B11: =B10/365 -> 0.55616438 | C11: =C10/365 -> 0.50684932 | D11: =D10/365 -> 0.51232877
A12: Peak Day | B12: =INDEX(RawData!A2:A356,MATCH(MAX(RawData!M2:M356),RawData!M2:M356,0)) -> d_98 | C12: =INDEX(RawData!A2:A356,MATCH(MAX(RawData!N2:N356),RawData!N2:N356,0)) -> d_196 | D12: =INDEX(RawData!A2:A356,MATCH(MAX(RawData!O2:O356),RawData!O2:O356,0)) -> d_232
A13: Peak Date | B13: =INDEX(RawData!B2:B356,MATCH(MAX(RawData!M2:M356),RawData!M2:M356,0)) -> 40669 | C13: =INDEX(RawData!B2:B356,MATCH(MAX(RawData!N2:N356),RawData!N2:N356,0)) -> 40767 | D13: =INDEX(RawData!B2:B356,MATCH(MAX(RawData!O2:O356),RawData!O2:O356,0)) -> 40803
A14: 75th Percentile | B14: =PERCENTILE(RawData!M2:M366,0.75) -> 1 | C14: =PERCENTILE(RawData!N2:N366,0.75) -> 1 | D14: =PERCENTILE(RawData!O2:O366,0.75) -> 1
A15: 25th Percentile | B15: =PERCENTILE(RawData!M2:M366,0.25) -> 0 | C15: =PERCENTILE(RawData!N2:N366,0.25) -> 0 | D15: =PERCENTILE(RawData!O2:O366,0.25) -> 0
A16: IQR | B16: =B14-B15 -> 1 | C16: =C14-C15 -> 1 | D16: =D14-D15 -> 1

Sheet WeekdayPattern
A1: Weekday | B1: SKU1_Avg | C1: SKU2_Avg | D1: SKU3_Avg
A2: Saturday | B2: =IFERROR(AVERAGEIF(RawData!$D$2:$D$356,A2,RawData!$M$2:$M$356),"No Data") -> 1.0392157 | C2: =IFERROR(AVERAGEIF(RawData!$D$2:$D$356,A2,RawData!$N$2:$N$356),"No Data") -> 0.84313725 | D2: =IFERROR(AVERAGEIF(RawData!$D$2:$D$356,A2,RawData!$O$2:$O$356),"No Data") -> 1.5294118
A3: Sunday | B3: =IFERROR(AVERAGEIF(RawData!$D$2:$D$356,A3,RawData!$M$2:$M$356),"No Data") -> 1.1764706 | C3: =IFERROR(AVERAGEIF(RawData!$D$2:$D$356,A3,RawData!$N$2:$N$356),"No Data") -> 0.88235294 | D3: =IFERROR(AVERAGEIF(RawData!$D$2:$D$356,A3,RawData!$O$2:$O$356),"No Data") -> 0.88235294
A4: Monday | B4: =IFERROR(AVERAGEIF(RawData!$D$2:$D$356,A4,RawData!$M$2:$M$356),"No Data") -> 0.66666667 | C4: =IFERROR(AVERAGEIF(RawData!$D$2:$D$356,A4,RawData!$N$2:$N$356),"No Data") -> 0.94117647 | D4: =IFERROR(AVERAGEIF(RawData!$D$2:$D$356,A4,RawData!$O$2:$O$356),"No Data") -> 0.62745098
A5: Tuesday | B5: =IFERROR(AVERAGEIF(RawData!$D$2:$D$356,A5,RawData!$M$2:$M$356),"No Data") -> 0.64705882 | C5: =IFERROR(AVERAGEIF(RawData!$D$2:$D$356,A5,RawData!$N$2:$N$356),"No Data") -> 0.70588235 | D5: =IFERROR(AVERAGEIF(RawData!$D$2:$D$356,A5,RawData!$O$2:$O$356),"No Data") -> 0.78431373
A6: Wednesday | B6: =IFERROR(AVERAGEIF(RawData!$D$2:$D$356,A6,RawData!$M$2:$M$356),"No Data") -> 0.94117647 | C6: =IFERROR(AVERAGEIF(RawData!$D$2:$D$356,A6,RawData!$N$2:$N$356),"No Data") -> 0.78431373 | D6: =IFERROR(AVERAGEIF(RawData!$D$2:$D$356,A6,RawData!$O$2:$O$356),"No Data") -> 0.50980392
A7: Thursday | B7: =IFERROR(AVERAGEIF(RawData!$D$2:$D$356,A7,RawData!$M$2:$M$356),"No Data") -> 0.76 | C7: =IFERROR(AVERAGEIF(RawData!$D$2:$D$356,A7,RawData!$N$2:$N$356),"No Data") -> 0.56 | D7: =IFERROR(AVERAGEIF(RawData!$D$2:$D$356,A7,RawData!$O$2:$O$356),"No Data") -> 0.94
A8: Friday | B8: =IFERROR(AVERAGEIF(RawData!$D$2:$D$356,A8,RawData!$M$2:$M$356),"No Data") -> 1.08 | C8: =IFERROR(AVERAGEIF(RawData!$D$2:$D$356,A8,RawData!$N$2:$N$356),"No Data") -> 0.9 | D8: =IFERROR(AVERAGEIF(RawData!$D$2:$D$356,A8,RawData!$O$2:$O$356),"No Data") -> 0.94
A9: Overall Average | B9: =AVERAGE(Table2[SKU1_Sales]) -> 0.89863014 | C9: =AVERAGE(Table2[SKU2_Sales]) -> 0.8 | D9: =AVERAGE(Table2[SKU3_Sales]) -> 0.8739726
A11: Seasonal Index
A12: Saturday | B12: =B2/B9 -> 1.1564443 | C12: =C2/C9 -> 1.0539216 | D12: =D2/D9 -> 1.7499539
A13: Sunday | B13: =B3/B9 -> 1.3091822 | C13: =C3/C9 -> 1.1029412 | D13: =D3/D9 -> 1.0095888
A14: Monday | B14: =B4/B9 -> 0.74186992 | C14: =C4/C9 -> 1.1764706 | D14: =D4/D9 -> 0.71792981
A15: Tuesday | B15: =B5/B9 -> 0.72005022 | C15: =C5/C9 -> 0.88235294 | D15: =D5/D9 -> 0.89741226
A16: Wednesday | B16: =B6/B9 -> 1.0473458 | C16: =C6/C9 -> 0.98039216 | D16: =D6/D9 -> 0.58331797
A17: Thursday | B17: =B7/B9 -> 0.84573171 | C17: =C7/C9 -> 0.7 | D17: =D7/D9 -> 1.0755486
A18: Friday | B18: =B8/B9 -> 1.2018293 | C18: =C8/C9 -> 1.125 | D18: =D8/D9 -> 1.0755486

Sheet MonthlyPattern
A1: Month | B1: Month_Name | C1: SKU1_Avg | D1: SKU2_Avg | E1: SKU3_Avg | F1: SKU_1_seasonality_Index | G1: SKU_2_seasonality_index | H1: SKU_3_seasonality_index
A2: 1 | B2: January | C2: =AVERAGEIF(Table2[month],MonthlyPattern!A2,Table2[SKU1_Sales]) -> 0.70967742 | D2: =AVERAGEIF(Table2[month],MonthlyPattern!A2,Table2[SKU2_Sales]) -> 0.77419355 | E2: =AVERAGEIF(Table2[month],MonthlyPattern!A2,Table2[SKU3_Sales]) -> 0.4516129 | F2: =C2/AVERAGE(RawData!$M$2:$M$356) -> 0.78729839 | G2: =D2/AVERAGE(RawData!$N$2:$N$356) -> 0.96434635 | H2: =E2/AVERAGE(RawData!$O$2:$O$356) -> 0.50896057
A3: 2 | B3: February | C3: =AVERAGEIF(Table2[month],MonthlyPattern!A3,Table2[SKU1_Sales]) -> 1.4285714 | D3: =AVERAGEIF(Table2[month],MonthlyPattern!A3,Table2[SKU2_Sales]) -> 0.32142857 | E3: =AVERAGEIF(Table2[month],MonthlyPattern!A3,Table2[SKU3_Sales]) -> 0.96428571 | F3: =C3/AVERAGE(RawData!$M$2:$M$356) -> 1.5848214 | G3: =D3/AVERAGE(RawData!$N$2:$N$356) -> 0.40037594 | H3: =E3/AVERAGE(RawData!$O$2:$O$356) -> 1.0867347
A4: 3 | B4: March | C4: =AVERAGEIF(Table2[month],MonthlyPattern!A4,Table2[SKU1_Sales]) -> 1.2903226 | D4: =AVERAGEIF(Table2[month],MonthlyPattern!A4,Table2[SKU2_Sales]) -> 0.4516129 | E4: =AVERAGEIF(Table2[month],MonthlyPattern!A4,Table2[SKU3_Sales]) -> 0.93548387 | F4: =C4/AVERAGE(RawData!$M$2:$M$356) -> 1.4314516 | G4: =D4/AVERAGE(RawData!$N$2:$N$356) -> 0.56253537 | H4: =E4/AVERAGE(RawData!$O$2:$O$356) -> 1.0542755
A5: 4 | B5: April | C5: =AVERAGEIF(Table2[month],MonthlyPattern!A5,Table2[SKU1_Sales]) -> 0.76666667 | D5: =AVERAGEIF(Table2[month],MonthlyPattern!A5,Table2[SKU2_Sales]) -> 0.7 | E5: =AVERAGEIF(Table2[month],MonthlyPattern!A5,Table2[SKU3_Sales]) -> 0.96666667 | F5: =C5/AVERAGE(RawData!$M$2:$M$356) -> 0.85052083 | G5: =D5/AVERAGE(RawData!$N$2:$N$356) -> 0.87192982 | H5: =E5/AVERAGE(RawData!$O$2:$O$356) -> 1.089418
A6: 5 | B6: May | C6: =AVERAGEIF(Table2[month],MonthlyPattern!A6,Table2[SKU1_Sales]) -> 1.6129032 | D6: =AVERAGEIF(Table2[month],MonthlyPattern!A6,Table2[SKU2_Sales]) -> 0.80645161 | E6: =AVERAGEIF(Table2[month],MonthlyPattern!A6,Table2[SKU3_Sales]) -> 1.2258065 | F6: =C6/AVERAGE(RawData!$M$2:$M$356) -> 1.7893145 | G6: =D6/AVERAGE(RawData!$N$2:$N$356) -> 1.0045274 | H6: =E6/AVERAGE(RawData!$O$2:$O$356) -> 1.3814644
A7: 6 | B7: June | C7: =AVERAGEIF(Table2[month],MonthlyPattern!A7,Table2[SKU1_Sales]) -> 0.93333333 | D7: =AVERAGEIF(Table2[month],MonthlyPattern!A7,Table2[SKU2_Sales]) -> 1.3666667 | E7: =AVERAGEIF(Table2[month],MonthlyPattern!A7,Table2[SKU3_Sales]) -> 1.0666667 | F7: =C7/AVERAGE(RawData!$M$2:$M$356) -> 1.0354167 | G7: =D7/AVERAGE(RawData!$N$2:$N$356) -> 1.7023392 | H7: =E7/AVERAGE(RawData!$O$2:$O$356) -> 1.2021164
A8: 7 | B8: July | C8: =AVERAGEIF(Table2[month],MonthlyPattern!A8,Table2[SKU1_Sales]) -> 0.87096774 | D8: =AVERAGEIF(Table2[month],MonthlyPattern!A8,Table2[SKU2_Sales]) -> 0.83870968 | E8: =AVERAGEIF(Table2[month],MonthlyPattern!A8,Table2[SKU3_Sales]) -> 0.4516129 | F8: =C8/AVERAGE(RawData!$M$2:$M$356) -> 0.96622984 | G8: =D8/AVERAGE(RawData!$N$2:$N$356) -> 1.0447085 | H8: =E8/AVERAGE(RawData!$O$2:$O$356) -> 0.50896057
A9: 8 | B9: August | C9: =AVERAGEIF(Table2[month],MonthlyPattern!A9,Table2[SKU1_Sales]) -> 0.064516129 | D9: =AVERAGEIF(Table2[month],MonthlyPattern!A9,Table2[SKU2_Sales]) -> 1.0967742 | E9: =AVERAGEIF(Table2[month],MonthlyPattern!A9,Table2[SKU3_Sales]) -> 1.0967742 | F9: =C9/AVERAGE(RawData!$M$2:$M$356) -> 0.071572581 | G9: =D9/AVERAGE(RawData!$N$2:$N$356) -> 1.3661573 | H9: =E9/AVERAGE(RawData!$O$2:$O$356) -> 1.2360471
A10: 9 | B10: September | C10: =AVERAGEIF(Table2[month],MonthlyPattern!A10,Table2[SKU1_Sales]) -> 0 | D10: =AVERAGEIF(Table2[month],MonthlyPattern!A10,Table2[SKU2_Sales]) -> 0.63333333 | E10: =AVERAGEIF(Table2[month],MonthlyPattern!A10,Table2[SKU3_Sales]) -> 0.73333333 | F10: =C10/AVERAGE(RawData!$M$2:$M$356) -> 0 | G10: =D10/AVERAGE(RawData!$N$2:$N$356) -> 0.78888889 | H10: =E10/AVERAGE(RawData!$O$2:$O$356) -> 0.82645503
A11: 10 | B11: October | C11: =AVERAGEIF(Table2[month],MonthlyPattern!A11,Table2[SKU1_Sales]) -> 0 | D11: =AVERAGEIF(Table2[month],MonthlyPattern!A11,Table2[SKU2_Sales]) -> 0.77419355 | E11: =AVERAGEIF(Table2[month],MonthlyPattern!A11,Table2[SKU3_Sales]) -> 1.0645161 | F11: =C11/AVERAGE(RawData!$M$2:$M$356) -> 0 | G11: =D11/AVERAGE(RawData!$N$2:$N$356) -> 0.96434635 | H11: =E11/AVERAGE(RawData!$O$2:$O$356) -> 1.1996928
A12: 11 | B12: November | C12: =AVERAGEIF(Table2[month],MonthlyPattern!A12,Table2[SKU1_Sales]) -> 1.4 | D12: =AVERAGEIF(Table2[month],MonthlyPattern!A12,Table2[SKU2_Sales]) -> 0.86666667 | E12: =AVERAGEIF(Table2[month],MonthlyPattern!A12,Table2[SKU3_Sales]) -> 0.73333333 | F12: =C12/AVERAGE(RawData!$M$2:$M$356) -> 1.553125 | G12: =D12/AVERAGE(RawData!$N$2:$N$356) -> 1.0795322 | H12: =E12/AVERAGE(RawData!$O$2:$O$356) -> 0.82645503
A13: 12 | B13: December | C13: =AVERAGEIF(Table2[month],MonthlyPattern!A13,Table2[SKU1_Sales]) -> 1.7419355 | D13: =AVERAGEIF(Table2[month],MonthlyPattern!A13,Table2[SKU2_Sales]) -> 0.93548387 | E13: =AVERAGEIF(Table2[month],MonthlyPattern!A13,Table2[SKU3_Sales]) -> 0.80645161 | F13: =C13/AVERAGE(RawData!$M$2:$M$356) -> 1.9324597 | G13: =D13/AVERAGE(RawData!$N$2:$N$356) -> 1.1652518 | H13: =E13/AVERAGE(RawData!$O$2:$O$356) -> 0.90885817

Sheet EventAnalysis
A1: Condition | B1: Count | C1: SKU1_Avg | D1: SKU2_Avg | E1: SKU3_Avg
A2: No event | B2: =COUNTIF(Table2[event_type_1],"") -> 336 | C2: =AVERAGEIF(RawData!$I$2:$I$366,"",RawData!$M$2:$M$366) -> 0.91964286 | D2: =AVERAGEIF(RawData!$I$2:$I$366,"",RawData!$N$2:$N$366) -> 0.82440476 | E2: =AVERAGEIF(RawData!$I$2:$I$366,"",RawData!$O$2:$O$366) -> 0.88095238
A3: Sporting | B3: =COUNTIF(RawData!$I$2:$I$366,"Sporting") -> 3 | C3: =AVERAGEIF(RawData!$I$2:$I$366,"Sporting",RawData!$M$2:$M$366) -> 1.3333333 | D3: =AVERAGEIF(RawData!$I$2:$I$366,"Sporting",RawData!$N$2:$N$366) -> 0.33333333 | E3: =AVERAGEIF(RawData!$I$2:$I$366,"Sporting",RawData!$O$2:$O$366) -> 1.6666667
A4: Cultural | B4: =COUNTIF(RawData!$I$2:$I$366,"Cultural") -> 6 | C4: =AVERAGEIF(RawData!$I$2:$I$366,"Cultural",RawData!$M$2:$M$366) -> 0.66666667 | D4: =AVERAGEIF(RawData!$I$2:$I$366,"Cultural",RawData!$N$2:$N$366) -> 0.83333333 | E4: =AVERAGEIF(RawData!$I$2:$I$366,"Cultural",RawData!$O$2:$O$366) -> 1
A5: National | B5: =COUNTIF(RawData!$I$2:$I$366,"National") -> 10 | C5: =AVERAGEIF(RawData!$I$2:$I$366,"National",RawData!$M$2:$M$366) -> 0.5 | D5: =AVERAGEIF(RawData!$I$2:$I$366,"National",RawData!$N$2:$N$366) -> 0.2 | E5: =AVERAGEIF(RawData!$I$2:$I$366,"National",RawData!$O$2:$O$366) -> 0.5
A6: Religious | B6: =COUNTIF(RawData!$I$2:$I$366,"Religious") -> 10 | C6: =AVERAGEIF(RawData!$I$2:$I$356,"Religious",RawData!$M$2:$M$356) -> 0.6 | D6: =AVERAGEIF(RawData!$I$2:$I$366,"Religious",RawData!$N$2:$N$366) -> 0.7 | E6: =AVERAGEIF(RawData!$I$2:$I$366,"Religious",RawData!$O$2:$O$366) -> 0.7
A8: Event lift %
C9: SKU_1 | D9: SKU_2 | E9: SKU_3
B10: Sporting | C10: =(C3-C2)/C2 -> 0.44983819 | D10: =(D3-D2)/D2 -> -0.59566787 | E10: =(E3-E2)/E2 -> 0.89189189
B11: Cultural | C11: =(C4-C2)/C2 -> -0.27508091 | D11: =(D4-D2)/D2 -> 0.010830325 | E11: =(E4-E2)/E2 -> 0.13513514
B12: National | C12: =(C5-C2)/C2 -> -0.45631068 | D12: =(D5-D2)/D2 -> -0.75740072 | E12: =(E5-E2)/E2 -> -0.43243243
B13: Religious | C13: =(C6-C2)/C2 -> -0.34757282 | D13: =(D6-D2)/D2 -> -0.15090253 | E13: =(E6-E2)/E2 -> -0.20540541
A17: Individual Event analysis
A19: Events | B19: Date | C19: SKU1_Sales
A20: {=_xlfn.UNIQUE(_xlfn._xlws.FILTER(RawData!H2:H356,RawData!H2:H356<>""))} -> SuperBowl | B20: =_xlfn.XLOOKUP(A20,RawData!$H$2:$H$366,RawData!$A$2:$A$366) -> d_9 | C20: =_xlfn.XLOOKUP(A20,RawData!$H$2:$H$366,RawData!$M$2:$M$366) -> 0
A21: ValentinesDay | B21: =_xlfn.XLOOKUP(A21,RawData!$H$2:$H$356,RawData!$A$2:$A$356) -> d_17 | C21: =_xlfn.XLOOKUP(A21,RawData!$H$2:$H$366,RawData!$M$2:$M$366) -> 2
A22: PresidentsDay | B22: =_xlfn.XLOOKUP(A22,RawData!$H$2:$H$356,RawData!$A$2:$A$356) -> d_24 | C22: =_xlfn.XLOOKUP(A22,RawData!$H$2:$H$366,RawData!$M$2:$M$366) -> 0
A23: LentStart | B23: =_xlfn.XLOOKUP(A23,RawData!$H$2:$H$356,RawData!$A$2:$A$356) -> d_40 | C23: =_xlfn.XLOOKUP(A23,RawData!$H$2:$H$366,RawData!$M$2:$M$366) -> 2
A24: LentWeek2 | B24: =_xlfn.XLOOKUP(A24,RawData!$H$2:$H$356,RawData!$A$2:$A$356) -> d_47 | C24: =_xlfn.XLOOKUP(A24,RawData!$H$2:$H$366,RawData!$M$2:$M$366) -> 1
A25: StPatricksDay | B25: =_xlfn.XLOOKUP(A25,RawData!$H$2:$H$356,RawData!$A$2:$A$356) -> d_48 | C25: =_xlfn.XLOOKUP(A25,RawData!$H$2:$H$366,RawData!$M$2:$M$366) -> 0
A26: Purim End | B26: =_xlfn.XLOOKUP(A26,RawData!$H$2:$H$356,RawData!$A$2:$A$356) -> d_51 | C26: =_xlfn.XLOOKUP(A26,RawData!$H$2:$H$366,RawData!$M$2:$M$366) -> 1
A27: OrthodoxEaster | B27: =_xlfn.XLOOKUP(A27,RawData!$H$2:$H$356,RawData!$A$2:$A$356) -> d_86 | C27: =_xlfn.XLOOKUP(A27,RawData!$H$2:$H$366,RawData!$M$2:$M$366) -> 0
A28: Pesach End | B28: =_xlfn.XLOOKUP(A28,RawData!$H$2:$H$356,RawData!$A$2:$A$356) -> d_88 | C28: =_xlfn.XLOOKUP(A28,RawData!$H$2:$H$366,RawData!$M$2:$M$366) -> 0
A29: Cinco De Mayo | B29: =_xlfn.XLOOKUP(A29,RawData!$H$2:$H$356,RawData!$A$2:$A$356) -> d_97 | C29: =_xlfn.XLOOKUP(A29,RawData!$H$2:$H$366,RawData!$M$2:$M$366) -> 0
A30: Mother's day | B30: =_xlfn.XLOOKUP(A30,RawData!$H$2:$H$356,RawData!$A$2:$A$356) -> d_100 | C30: =_xlfn.XLOOKUP(A30,RawData!$H$2:$H$366,RawData!$M$2:$M$366) -> 0
A31: MemorialDay | B31: =_xlfn.XLOOKUP(A31,RawData!$H$2:$H$356,RawData!$A$2:$A$356) -> d_122 | C31: =_xlfn.XLOOKUP(A31,RawData!$H$2:$H$366,RawData!$M$2:$M$366) -> 0
A32: NBAFinalsStart | B32: =_xlfn.XLOOKUP(A32,RawData!$H$2:$H$356,RawData!$A$2:$A$356) -> d_123 | C32: =_xlfn.XLOOKUP(A32,RawData!$H$2:$H$366,RawData!$M$2:$M$366) -> 1
... A48: MartinLutherKingDay | B48: =_xlfn.XLOOKUP(A48,RawData!$H$2:$H$356,RawData!$A$2:$A$356) -> d_353 | C48: =_xlfn.XLOOKUP(A48,RawData!$H$2:$H$366,RawData!$M$2:$M$366) -> 1

Sheet SnapAnalysis
A1: Snap Status | B1: SKU1_Avg | C1: SKU2_Avg | D1: SKU3_Avg
A2: Snap Day (snap_CA=1) | B2: =AVERAGEIF(RawData!$L$2:$L$366,1,RawData!$M$2:$M$366) -> 0.95 | C2: =AVERAGEIF(RawData!$L$2:$L$366,1,RawData!$N$2:$N$366) -> 0.875 | D2: =AVERAGEIF(RawData!$L$2:$L$366,1,RawData!$O$2:$O$356) -> 0.825
A3: Non-Snap Day (snap_CA=0) | B3: =AVERAGEIF(RawData!$L$2:$L$366,0,RawData!$M$2:$M$366) -> 0.87346939 | C3: =AVERAGEIF(RawData!$L$2:$L$366,0,RawData!$N$2:$N$366) -> 0.76326531 | D3: =AVERAGEIF(RawData!$L$2:$L$366,0,RawData!$O$2:$O$366) -> 0.89795918
A4: Uplift% | B4: =(B2-B3)/B3 -> 0.087616822 | C4: =(C2-C3)/C3 -> 0.14639037 | D4: =(D2-D3)/D3 -> -0.08125

Sheet Rolling Trend
A1: date | B1: SKU1_Sales | C1: SKU2_Sales | D1: SKU3_Sales | E1: SKU1_28DayAvg | F1: SkU1_28DayTotal
A2: {=Table2[date]} -> 40572 | B2: {=Table2[SKU1_Sales]} -> 3 | C2: {=Table2[SKU2_Sales]} -> 0 | D2: {=Table2[SKU3_Sales]} -> 0
A3: 40573 | B3: 0 | C3: 1 | D3: 0
A4: 40574 | B4: 0 | C4: 0 | D4: 0
A5: 40575 | B5: 1 | C5: 1 | D5: 0
A6: 40576 | B6: 4 | C6: 1 | D6: 1
A7: 40577 | B7: 2 | C7: 1 | D7: 3
A8: 40578 | B8: 0 | C8: 0 | D8: 1
A9: 40579 | B9: 2 | C9: 0 | D9: 1
A10: 40580 | B10: 0 | C10: 0 | D10: 1
A11: 40581 | B11: 0 | C11: 0 | D11: 0
A12: 40582 | B12: 0 | C12: 1 | D12: 1
A13: 40583 | B13: 0 | C13: 1 | D13: 0
A14: 40584 | B14: 3 | C14: 0 | D14: 0
... A28: 40598 | B28: 2 | C28: 0 | D28: 1
A29: 40599 | B29: 4 | C29: 0 | D29: 0 | E29: =AVERAGE(B2:B29) -> 1.3928571 | F29: =SUM(B2:B29) -> 39
A30: 40600 | B30: 2 | C30: 1 | D30: 1 | E30: =AVERAGE(B3:B30) -> 1.3571429 | F30: =SUM(B3:B30) -> 38
A31: 40601 | B31: 2 | C31: 0 | D31: 0 | E31: =AVERAGE(B4:B31) -> 1.4285714 | F31: =SUM(B4:B31) -> 40
A32: 40602 | B32: 0 | C32: 0 | D32: 1 | E32: =AVERAGE(B5:B32) -> 1.4285714 | F32: =SUM(B5:B32) -> 40
A33: 40603 | B33: 2 | C33: 1 | D33: 0 | E33: =AVERAGE(B6:B33) -> 1.4642857 | F33: =SUM(B6:B33) -> 41
A34: 40604 | B34: 1 | C34: 1 | D34: 1 | E34: =AVERAGE(B7:B34) -> 1.3571429 | F34: =SUM(B7:B34) -> 38
A35: 40605 | B35: 7 | C35: 0 | D35: 1 | E35: =AVERAGE(B8:B35) -> 1.5357143 | F35: =SUM(B8:B35) -> 43
A36: 40606 | B36: 1 | C36: 1 | D36: 2 | E36: =AVERAGE(B9:B36) -> 1.5714286 | F36: =SUM(B9:B36) -> 44
A37: 40607 | B37: 2 | C37: 1 | D37: 3 | E37: =AVERAGE(B10:B37) -> 1.5714286 | F37: =SUM(B10:B37) -> 44
A38: 40608 | B38: 3 | C38: 3 | D38: 1 | E38: =AVERAGE(B11:B38) -> 1.6785714 | F38: =SUM(B11:B38) -> 47
A39: 40609 | B39: 0 | C39: 0 | D39: 0 | E39: =AVERAGE(B12:B39) -> 1.6785714 | F39: =SUM(B12:B39) -> 47
A40: 40610 | B40: 1 | C40: 0 | D40: 0 | E40: =AVERAGE(B13:B40) -> 1.7142857 | F40: =SUM(B13:B40) -> 48
... A366: 40936 | B366: 2 | C366: 0 | D366: 1 | E366: =AVERAGE(B339:B366) -> 0.67857143 | F366: =SUM(B339:B366) -> 19

Sheet CorrelationMatrix
B2: SKU1 | C2: SKU2 | D2: SKU2
A3: SKU1 | B3: 1 | C3: =CORREL(RawData!$M$2:$M$366,RawData!$N$2:$N$366) -> -0.0085017457 | D3: =CORREL(RawData!$M$2:$M$366,RawData!$O$2:$O$366) -> 0.12936336
A4: SKU2 | B4: =CORREL(RawData!$M$2:$M$366,RawData!$N$2:$N$366) -> -0.0085017457 | C4: 1 | D4: =CORREL(RawData!$N$2:$N$366,RawData!$O$2:$O$366) -> 0.082352819
A5: SKU3 | B5: =CORREL(RawData!$M$2:$M$366,RawData!$O$2:$O$366) -> 0.12936336 | C5: =CORREL(RawData!$O$2:$O$366,RawData!$N$2:$N$366) -> 0.082352819 | D5: 1
